Workbook
Name Billion: N!$F$18
Name Con_End: Inputs!$E$12
Name Con_Start: Inputs!$E$10
Name Days_Yr: N!$F$11
Name Grams_Oz: N!$F$21
Name Master_Integrity: Inputs!$E$112
Name Million: N!$F$17
Name Model_Start: Inputs!$E$7
Name Months_Qtr: N!$F$14
Name Months_Yr: N!$F$12
Name Name_Company: N!$F$6
Name Name_Model: N!$F$7
Name Name_Project: N!$F$8
Name Ops_End: Inputs!$E$17
Name Ops_Start: Inputs!$E$15
Name Qtrs_Yr: N!$F$13
Name Thousand: N!$F$16
Name Verysmallnumber: N!$F$19

Sheet   
B13: =Name_Model -> New Modelling Standards
B14: Corality Training Model
B16: Sydney, 1 April 2013
B22: Contact Details:
B23: Tim Heng
B24: Email | C24: tim.heng@corality.com
B25: Phone | C25: +61 2 9229 7457
B34: Level 7 | 33 York Street | Sydney NSW 2000 Australia | Phone +612 9222 9222 | | J34: Web www.corality.com

Sheet Corality
B50: Level 8 | 200 George Street | Sydney NSW 2000 Australia | Phone +612 9222 9222 | Web www.corality.com

Sheet Inputs
A1: Assumptions
A2: =Name_Project -> Gold Mining Project
A3: Master Integrity | D3: =Master_Integrity -> 0
C5: Timing
C6: Start
C7: Model Start Date | D7: Date | E7: 40908
C9: Construction
C10: Start | D10: Date | E10: =Model_Start+1 -> 40909
C11: Duration | D11: Qtr(s) | E11: 4
C12: End | D12: Date | E12: =EOMONTH(E10,E11*Months_Qtr-1) -> 41274
C14: Operations
C15: Start | D15: Date | E15: =E12+1 -> 41275
C16: Duration | D16: Yr(s) | E16: 10
C17: End | D17: Date | E17: =EOMONTH(E15,E16*Months_Yr-1) -> 44926
C19: Construction
C20: Categories
C21: Development Costs | E21: Contract Cost | G21: Total | H21: 1 | I21: =H21+1 -> 2 | J21: =I21+1 -> 3 | K21: =J21+1 -> 4 | L21: =K21+1 -> 5 | M21: =L21+1 -> 6 | N21: =M21+1 -> 7 | O21: =N21+1 -> 8 | P21: =O21+1 -> 9 | ... S21: =R21+1 -> 12
C22: Infrastructure | D22: AUD M | E22: 30 | G22: =SUM(H22:AK22) -> 1 | H22: 0.25 | I22: 0.25 | J22: 0.25 | K22: 0.25
C23: Overburden | D23: AUD M | E23: 15 | G23: =SUM(H23:AK23) -> 1 | I23: 0.25 | J23: 0.25 | K23: 0.5
C24: Processing Plant | D24: AUD M | E24: 75 | G24: =SUM(H24:AK24) -> 1 | J24: 0.5 | K24: 0.5
C25: Storage Dam | D25: AUD M | E25: 20 | G25: =SUM(H25:AK25) -> 1 | J25: 0.3 | K25: 0.7
C26: Civil Works | D26: AUD M | E26: 15 | G26: =SUM(H26:AK26) -> 1 | I26: 0.5 | J26: 0.25 | K26: 0.25
C27: Spare | D27: AUD M | E27: 0 | G27: =SUM(H27:AK27) -> 0
C28: Spare | D28: AUD M | E28: 0 | G28: =SUM(H28:AK28) -> 0
C29: Total | D29: AUD M | E29: =SUM(E21:E28) -> 155
C31: Contingency | D31: % | E31: 0.1
C33: Operations
C34: Production
C35: Period | F35: 1 | G35: 2 | H35: 3 | I35: 4
C36: Ore Mined | D36: t p.a. | F36: 500000 | G36: 1250000 | H36: 1250000 | I36: 1250000
C38: Strip Ratio | D38: x | F38: 2.5 | G38: 2.5 | H38: 1.5 | I38: 1.5
C40: Grade
C41: Period | F41: 1 | G41: 2 | H41: 3 | I41: 4
C42: Grams per Tonne | D42: g/t | F42: 5 | G42: 5 | H42: 4.5 | I42: 4
C44: Milling
C45: Recovery Rate | D45: % | F45: 0.85
C47: Revenue
C48: Price
C49: Period | F49: 2011 | G49: 2012 | H49: 2013 | I49: 2014
C50: Price | D50: USD / Oz | F50: 1000 | G50: 1000 | H50: 1500 | I50: 1000
...

Sheet One Line
A1: Calculations
A2: =Name_Project -> Gold Mining Project
A3: Master Integrity | D3: =Master_Integrity -> 0
A4: Period Start | J4: =I5+1 -> 40909 | K4: =J5+1 -> 41000 | L4: =K5+1 -> 41091 | M4: =L5+1 -> 41183 | N4: =M5+1 -> 41275 | O4: =N5+1 -> 41365 | P4: =O5+1 -> 41456 | Q4: =P5+1 -> 41548 | ... BI4: =BH5+1 -> 45566
A5: Period End | I5: =Model_Start -> 40908 | J5: =EOMONTH(J4,Months_Qtr-1) -> 40999 | K5: =EOMONTH(K4,Months_Qtr-1) -> 41090 | L5: =EOMONTH(L4,Months_Qtr-1) -> 41182 | M5: =EOMONTH(M4,Months_Qtr-1) -> 41274 | N5: =EOMONTH(N4,Months_Qtr-1) -> 41364 | O5: =EOMONTH(O4,Months_Qtr-1) -> 41455 | P5: =EOMONTH(P4,Months_Qtr-1) -> 41547 | Q5: =EOMONTH(Q4,Months_Qtr-1) -> 41639 | ... BI5: =EOMONTH(BI4,Months_Qtr-1) -> 45657
A6: Construction | J6: =IF(AND(J$4>=Con_Start,J$5<=Con_End),1,0) -> 1 | K6: =IF(AND(K$4>=Con_Start,K$5<=Con_End),1,0) -> 1 | L6: =IF(AND(L$4>=Con_Start,L$5<=Con_End),1,0) -> 1 | M6: =IF(AND(M$4>=Con_Start,M$5<=Con_End),1,0) -> 1 | N6: =IF(AND(N$4>=Con_Start,N$5<=Con_End),1,0) -> 0 | O6: =IF(AND(O$4>=Con_Start,O$5<=Con_End),1,0) -> 0 | P6: =IF(AND(P$4>=Con_Start,P$5<=Con_End),1,0) -> 0 | Q6: =IF(AND(Q$4>=Con_Start,Q$5<=Con_End),1,0) -> 0 | ... BI6: =IF(AND(BI$4>=Con_Start,BI$5<=Con_End),1,0) -> 0
A7: Operations | J7: =IF(AND(J$4>=Ops_Start,J$5<=Ops_End),1,0) -> 0 | K7: =IF(AND(K$4>=Ops_Start,K$5<=Ops_End),1,0) -> 0 | L7: =IF(AND(L$4>=Ops_Start,L$5<=Ops_End),1,0) -> 0 | M7: =IF(AND(M$4>=Ops_Start,M$5<=Ops_End),1,0) -> 0 | N7: =IF(AND(N$4>=Ops_Start,N$5<=Ops_End),1,0) -> 1 | O7: =IF(AND(O$4>=Ops_Start,O$5<=Ops_End),1,0) -> 1 | P7: =IF(AND(P$4>=Ops_Start,P$5<=Ops_End),1,0) -> 1 | Q7: =IF(AND(Q$4>=Ops_Start,Q$5<=Ops_End),1,0) -> 1 | ... BI7: =IF(AND(BI$4>=Ops_Start,BI$5<=Ops_End),1,0) -> 0
C9: Calculations
C10: Equity | E10: NPV
C11: Cashflow Available for Equity | D11: AUD M | E11: =XNPV(Inputs!F81,$I$11:$BI$11,$I$5:$BI$5) -> 103.39827 | I11: 0 | J11: =(((IF(ROUNDUP(SUM($J$7:J$7)*J$7/Qtrs_Yr,0)=0,0,LOOKUP(ROUNDUP(SUM($J$7:J$7)*J$7/Qtrs_Yr,0),Inputs!$F$35:$I$35,Inputs!$F$36:$I$36))/Thousand/Qtrs_Yr)*IF(ROUNDUP(SUM($J$7:J$7)*J$7/Qtrs_Yr,0)=0,0,LOOKUP(ROUNDUP(SUM($J$7:J$7)*J$7/Qtrs_Yr,0),Inputs!$F$41:$I$41,Inputs!$F$42:$I$42))/Grams_Oz*Inputs!$F$45)*LOOKUP(YEAR(J$5),Inputs!$F$49:$I$49,Inputs!$F$50:$I$50)/Thousand/LOOKUP(YEAR(J$5),Inputs!$F$89:$I$89,Inputs!$F$90:$I$90)*(J5-I5-Inputs!$F$97)/(J5-I5)+((IF(ROUNDUP(SUM($I$7:I$7)*I$7/Qtrs_Yr,0)=0,0,LOOKUP(ROUNDUP(SUM($I$7:I$7)*I$7/Qtrs_Yr,0),Inputs!$F$35:$I$35,Inputs!$F$36:$I$36))/Thousand/Qtrs_Yr)*IF(ROUNDUP(SUM($I$7:I$7)*I$7/Qtrs_Yr,0)=0,0,LOOKUP(ROUNDUP(SUM($I$7:I$7)*I$7/Qtrs_Yr,0),Inputs!$F$41:$I$41,Inputs!$F$42:$I$42))/Grams_Oz*Inputs!$F$45)*LOOKUP(YEAR(I$5),Inputs!$F$49:$I$49,Inputs!$F$50:$I$50)/Thousand/LOOKUP(YEAR(I$5),Inputs!$F$89:$I$89,Inputs!$F$90:$I$90)*Inputs!$F$97/(I5-H5))-(((Inputs!$F$64*(IF(ROUNDUP(SUM($J$7:J$7)*J$7/Qtrs_Yr,0)=0,0,LOOKUP(ROUNDUP(SUM($J$7:J$7)*J$7/Qtrs_Yr,0),Inputs!$F$35:$I$35,Inputs!$F$36:$I$36))/Thousand/Qtrs_Yr+IF(ROUNDUP(SUM($J$7:J$7)*J$7/Qtrs_Yr,0)=0,0,LOOKUP(ROUNDUP(SUM($J$7:J$7)*J$7/Qtrs_Yr,0),Inputs!$F$35:$I$35,Inputs!$F$38:$I$38)*LOOKUP(ROUNDUP(SUM($J$7:J$7)*J$7/Qtrs_Yr,0),Inputs!$F$35:$I$35,Inputs!$F$36:$I$36))/Thousand/Qtrs_Yr)+Inputs!$F$65*(IF(ROUNDUP(SUM($J$7:J$7)*J$7/Qtrs_Yr,0)=0,0,LOOKUP(ROUNDUP(SUM($J$7:J$7)*J$7/Qtrs_Yr,0),Inputs!$F$35:$I$35,Inputs!$F$36:$I$36))/Thousand/Qtrs_Yr)+Inputs!$F$66*(IF(ROUNDUP(SUM($J$7:J$7)*J$7/Qtrs_Yr,0)=0,0,LOOKUP(ROUNDUP(SUM($J$7:J$7)*J$7/Qtrs_Yr,0),Inputs!$F$35:$I$35,Inputs!$F$38:$I$38)*LOOKUP(ROUNDUP(SUM($J$7:J$7)*J$7/Qtrs_Yr,0),Inputs!$F$35:$I$35,Inputs!$F$36:$I$36))/Thousand/Qtrs_Yr))/Thousand+SUM(Inputs!$F$54:$F$61)*J$7/Qtrs_Yr)*(1+LOOKUP(YEAR(J$5),Inputs!$F$93:$I$93,Inputs!$F$94:$I$94)/Qtrs_Yr)^(COUNT($J$7:J7))*(J5-I5-Inputs!$F$98)/(J5-I5)+((Inputs!$F$64*(IF(ROUNDUP(SUM($I$7:I$7)*I$7/Qtrs_Yr,0)=0,0,LOOKUP(ROUNDUP(SUM($I$7:I$7)*I$7/Qtrs_Yr,0),Inputs!$F$35:$I$35,Inputs!$F$36:$I$36))/Thousand/Qtrs_Yr+IF(ROUNDUP(SUM($I$7:I$7)*I$7/Qtrs_Yr,0)=0,0,LOOKUP(ROUNDUP(SUM($I$7:I$7)*I$7/Qtrs_Yr,0),Inputs!$F$35:$I$35,Inputs!$F$38:$I$38)*LOOKUP(ROUNDUP(SUM($I$7:I$7)*I$7/Qtrs_Yr,0),Inputs!$F$35:$I$35,Inputs!$F$36:$I$36))/Thousand/Qtrs_Yr)+Inputs!$F$65*(IF(ROUNDUP(SUM($I$7:I$7)*I$7/Qtrs_Yr,0)=0,0,LOOKUP(ROUNDUP(SUM($I$7:I$7)*I$7/Qtrs_Yr,0),Inputs!$F$35:$I$35,Inputs!$F$36:$I$36))/Thousand/Qtrs_Yr)+Inputs!$F$66*(IF(ROUNDUP(SUM($I$7:I$7)*I$7/Qtrs_Yr,0)=0,0,LOOKUP(ROUNDUP(SUM($I$7:I$7)*I$7/Qtrs_Yr,0),Inputs!$F$35:$I$35,Inputs!$F$38:$I$38)*LOOKUP(ROUNDUP(SUM($I$7:I$7)*I$7/Qtrs_Yr,0),Inputs!$F$35:$I$35,Inputs!$F$36:$I$36))/Thousand/Qtrs_Yr))/Thousand+SUM(Inputs!$F$54:$F$61)*I$7/Qtrs_Yr)*(1+LOOKUP(YEAR(J$5),Inputs!$F$93:$I$93,Inputs!$F$94:$I$94)/Qtrs_Yr)^(COUNT($I$7:I7))*Inputs!$F$98/(I5-H5))-(((IF(ROUNDUP(SUM($J$7:J$7)*J$7/Qtrs_Yr,0)=0,0,LOOKUP(ROUNDUP(SUM($J$7:J$7)*J$7/Qtrs_Yr,0),Inputs!$F$35:$I$35,Inputs!$F$36:$I$36))/Thousand/Qtrs_Yr)*IF(ROUNDUP(SUM($J$7:J$7)*J$7/Qtrs_Yr,0)=0,0,LOOKUP(ROUNDUP(SUM($J$7:J$7)*J$7/Qtrs_Yr,0),Inputs!$F$41:$I$41,Inputs!$F$42:$I$42))/Grams_Oz*Inputs!$F$45)*LOOKUP(YEAR(J$5),Inputs!$F$49:$I$49,Inputs!$F$50:$I$50)/Thousand/LOOKUP(YEAR(J$5),Inputs!$F$89:$I$89,Inputs!$F$90:$I$90)-((Inputs!$F$64*(IF(ROUNDUP(SUM($J$7:J$7)*J$7/Qtrs_Yr,0)=0,0,LOOKUP(ROUNDUP(SUM($J$7:J$7)*J$7/Qtrs_Yr,0),Inputs!$F$35:$I$35,Inputs!$F$36:$I$36))/Thousand/Qtrs_Yr+IF(ROUNDUP(SUM($J$7:J$7)*J$7/Qtrs_Yr,0)=0,0,LOOKUP(ROUNDUP(SUM($J$7:J$7)*J$7/Qtrs_Yr,0),Inputs!$F$35:$I$35,Inputs!$F$38:$I$38)*LOOKUP(ROUNDUP(SUM($J$7:J$7)*J$7/Qtrs_Yr,0),Inputs!$F$35:$I$35,Inputs!$F$36:$I$36))/Thousand/Qtrs_Yr)+Inputs!$F$65*(IF(ROUNDUP(SUM($J$7:J$7)*J$7/Qtrs_Yr,0)=0,0,LOOKUP(ROUNDUP(SUM($J$7:J$7)*J$7/Qtrs_Yr,0),Inputs!$F$35:$I$35,Inputs!$F$36:$I$36))/Thousand/Qtrs_Yr)+Inputs!$F$66*(IF(ROUNDUP(SUM($J$7:J$7)*J$7/Qtrs_Yr,0)=0,0,LOOKUP(ROUNDUP(SUM($J$7:J$7)*J$7/Qtrs_Yr,0),Inputs!$F$35:$I$35,Inputs!$F$38:$I$38)*LOOKUP(ROUNDUP(SUM($J$7:J$7)*J$7/Qtrs_Yr,0),Inputs!$F$35:$I$35,Inputs!$F$36:$I$36))/Thousand/Qtrs_Yr))/Thousand+SUM(Inputs!$F$54:$F$61)*J$7/Qtrs_Yr)*(1+LOOKUP(YEAR(J$5),Inputs!$F$93:$I$93,Inputs!$F$94:$I$94)/Qtrs_Yr)^(COUNT($J$7:J7))-Inputs!$E$29*(1+Inputs!$E$31)*J$7/Inputs!$E$16/Qtrs_Yr-IF(OR(J$7=0,SUM($J7:J7)*J7>Inputs!$F$77*Qtrs_Yr),0,(Inputs!$F$71-SUM($J7:J7,-1)*J7*Inputs!$F$71/Inputs!$F$77/Qtrs_Yr)*(LOOKUP(YEAR(K$5),Inputs!$F$85:$I$85,Inputs!$F$86:$I$86)+LOOKUP(ROUNDUP(SUM($J7:K7)*K7/Qtrs_Yr,0),Inputs!$G$73:$J$73,Inputs!$G$74:$J$74))/Qtrs_Yr))*Inputs!$F$101-IF(OR(J$7=0,SUM($J7:J7)*J7>Inputs!$F$77*Qtrs_Yr),0,(Inputs!$F$71-SUM($J7:J7,-1)*J7*Inputs!$F$71/Inputs!$F$77/Qtrs_Yr)*(LOOKUP(YEAR(K$5),Inputs!$F$85:$I$85,Inputs!$F$86:$I$86)+LOOKUP(ROUNDUP(SUM($J7:K7)*K7/Qtrs_Yr,0),Inputs!$G$73:$J$73,Inputs!$G$74:$J$74))/Qtrs_Yr)-IF(OR(J$7=0,SUM($J7:J7)*J7>Inputs!$F$77*Qtrs_Yr),0,Inputs!$F$71/Inputs!$F$77/Qtrs_Yr) -> 0 | K11: =(((IF(ROUNDUP(SUM($J$7:K$7)*K$7/Qtrs_Yr,0)=0,0,LOOKUP(ROUNDUP(SUM($J$7:K$7)*K$7/Qtrs_Yr,0),Inputs!$F$35:$I$35,Inputs!$F$36:$I$36))/Thousand/Qtrs_Yr)*IF(ROUNDUP(SUM($J$7:K$7)*K$7/Qtrs_Yr,0)=0,0,LOOKUP(ROUNDUP(SUM($J$7:K$7)*K$7/Qtrs_Yr,0),Inputs!$F$41:$I$41,Inputs!$F$42:$I$42))/Grams_Oz*Inputs!$F$45)*LOOKUP(YEAR(K$5),Inputs!$F$49:$I$49,Inputs!$F$50:$I$50)/Thousand/LOOKUP(YEAR(K$5),Inputs!$F$89:$I$89,Inputs!$F$90:$I$90)*(K5-J5-Inputs!$F$97)/(K5-J5)+((IF(ROUNDUP(SUM($I$7:J$7)*J$7/Qtrs_Yr,0)=0,0,LOOKUP(ROUNDUP(SUM($I$7:J$7)*J$7/Qtrs_Yr,0),Inputs!$F$35:$I$35,Inputs!$F$36:$I$36))/Thousand/Qtrs_Yr)*IF(ROUNDUP(SUM($I$7:J$7)*J$7/Qtrs_Yr,0)=0,0,LOOKUP(ROUNDUP(SUM($I$7:J$7)*J$7/Qtrs_Yr,0),Inputs!$F$41:$I$41,Inputs!$F$42:$I$42))/Grams_Oz*Inputs!$F$45)*LOOKUP(YEAR(J$5),Inputs!$F$49:$I$49,Inputs!$F$50:$I$50)/Thousand/LOOKUP(YEAR(J$5),Inputs!$F$89:$I$89,Inputs!$F$90:$I$90)*Inputs!$F$97/(J5-I5))-(((Inputs!$F$64*(IF(ROUNDUP(SUM($J$7:K$7)*K$7/Qtrs_Yr,0)=0,0,LOOKUP(ROUNDUP(SUM($J$7:K$7)*K$7/Qtrs_Yr,0),Inputs!$F$35:$I$35,Inputs!$F$36:$I$36))/Thousand/Qtrs_Yr+IF(ROUNDUP(SUM($J$7:K$7)*K$7/Qtrs_Yr,0)=0,0,LOOKUP(ROUNDUP(SUM($J$7:K$7)*K$7/Qtrs_Yr,0),Inputs!$F$35:$I$35,Inputs!$F$38:$I$38)*LOOKUP(ROUNDUP(SUM($J$7:K$7)*K$7/Qtrs_Yr,0),Inputs!$F$35:$I$35,Inputs!$F$36:$I$36))/Thousand/Qtrs_Yr)+Inputs!$F$65*(IF(ROUNDUP(SUM($J$7:K$7)*K$7/Qtrs_Yr,0)=0,0,LOOKUP(ROUNDUP(SUM($J$7:K$7)*K$7/Qtrs_Yr,0),Inputs!$F$35:$I$35,Inputs!$F$36:$I$36))/Thousand/Qtrs_Yr)+Inputs!$F$66*(IF(ROUNDUP(SUM($J$7:K$7)*K$7/Qtrs_Yr,0)=0,0,LOOKUP(ROUNDUP(SUM($J$7:K$7)*K$7/Qtrs_Yr,0),Inputs!$F$35:$I$35,Inputs!$F$38:$I$38)*LOOKUP(ROUNDUP(SUM($J$7:K$7)*K$7/Qtrs_Yr,0),Inputs!$F$35:$I$35,Inputs!$F$36:$I$36))/Thousand/Qtrs_Yr))/Thousand+SUM(Inputs!$F$54:$F$61)*K$7/Qtrs_Yr)*(1+LOOKUP(YEAR(K$5),Inputs!$F$93:$I$93,Inputs!$F$94:$I$94)/Qtrs_Yr)^(COUNT($J$7:K7))*(K5-J5-Inputs!$F$98)/(K5-J5)+((Inputs!$F$64*(IF(ROUNDUP(SUM($I$7:J$7)*J$7/Qtrs_Yr,0)=0,0,LOOKUP(ROUNDUP(SUM($I$7:J$7)*J$7/Qtrs_Yr,0),Inputs!$F$35:$I$35,Inputs!$F$36:$I$36))/Thousand/Qtrs_Yr+IF(ROUNDUP(SUM($I$7:J$7)*J$7/Qtrs_Yr,0)=0,0,LOOKUP(ROUNDUP(SUM($I$7:J$7)*J$7/Qtrs_Yr,0),Inputs!$F$35:$I$35,Inputs!$F$38:$I$38)*LOOKUP(ROUNDUP(SUM($I$7:J$7)*J$7/Qtrs_Yr,0),Inputs!$F$35:$I$35,Inputs!$F$36:$I$36))/Thousand/Qtrs_Yr)+Inputs!$F$65*(IF(ROUNDUP(SUM($I$7:J$7)*J$7/Qtrs_Yr,0)=0,0,LOOKUP(ROUNDUP(SUM($I$7:J$7)*J$7/Qtrs_Yr,0),Inputs!$F$35:$I$35,Inputs!$F$36:$I$36))/Thousand/Qtrs_Yr)+Inputs!$F$66*(IF(ROUNDUP(SUM($I$7:J$7)*J$7/Qtrs_Yr,0)=0,0,LOOKUP(ROUNDUP(SUM($I$7:J$7)*J$7/Qtrs_Yr,0),Inputs!$F$35:$I$35,Inputs!$F$38:$I$38)*LOOKUP(ROUNDUP(SUM($I$7:J$7)*J$7/Qtrs_Yr,0),Inputs!$F$35:$I$35,Inputs!$F$36:$I$36))/Thousand/Qtrs_Yr))/Thousand+SUM(Inputs!$F$54:$F$61)*J$7/Qtrs_Yr)*(1+LOOKUP(YEAR(K$5),Inputs!$F$93:$I$93,Inputs!$F$94:$I$94)/Qtrs_Yr)^(COUNT($I$7:J7))*Inputs!$F$98/(J5-I5))-(((IF(ROUNDUP(SUM($J$7:K$7)*K$7/Qtrs_Yr,0)=0,0,LOOKUP(ROUNDUP(SUM($J$7:K$7)*K$7/Qtrs_Yr,0),Inputs!$F$35:$I$35,Inputs!$F$36:$I$36))/Thousand/Qtrs_Yr)*IF(ROUNDUP(SUM($J$7:K$7)*K$7/Qtrs_Yr,0)=0,0,LOOKUP(ROUNDUP(SUM($J$7:K$7)*K$7/Qtrs_Yr,0),Inputs!$F$41:$I$41,Inputs!$F$42:$I$42))/Grams_Oz*Inputs!$F$45)*LOOKUP(YEAR(K$5),Inputs!$F$49:$I$49,Inputs!$F$50:$I$50)/Thousand/LOOKUP(YEAR(K$5),Inputs!$F$89:$I$89,Inputs!$F$90:$I$90)-((Inputs!$F$64*(IF(ROUNDUP(SUM($J$7:K$7)*K$7/Qtrs_Yr,0)=0,0,LOOKUP(ROUNDUP(SUM($J$7:K$7)*K$7/Qtrs_Yr,0),Inputs!$F$35:$I$35,Inputs!$F$36:$I$36))/Thousand/Qtrs_Yr+IF(ROUNDUP(SUM($J$7:K$7)*K$7/Qtrs_Yr,0)=0,0,LOOKUP(ROUNDUP(SUM($J$7:K$7)*K$7/Qtrs_Yr,0),Inputs!$F$35:$I$35,Inputs!$F$38:$I$38)*LOOKUP(ROUNDUP(SUM($J$7:K$7)*K$7/Qtrs_Yr,0),Inputs!$F$35:$I$35,Inputs!$F$36:$I$36))/Thousand/Qtrs_Yr)+Inputs!$F$65*(IF(ROUNDUP(SUM($J$7:K$7)*K$7/Qtrs_Yr,0)=0,0,LOOKUP(ROUNDUP(SUM($J$7:K$7)*K$7/Qtrs_Yr,0),Inputs!$F$35:$I$35,Inputs!$F$36:$I$36))/Thousand/Qtrs_Yr)+Inputs!$F$66*(IF(ROUNDUP(SUM($J$7:K$7)*K$7/Qtrs_Yr,0)=0,0,LOOKUP(ROUNDUP(SUM($J$7:K$7)*K$7/Qtrs_Yr,0),Inputs!$F$35:$I$35,Inputs!$F$38:$I$38)*LOOKUP(ROUNDUP(SUM($J$7:K$7)*K$7/Qtrs_Yr,0),Inputs!$F$35:$I$35,Inputs!$F$36:$I$36))/Thousand/Qtrs_Yr))/Thousand+SUM(Inputs!$F$54:$F$61)*K$7/Qtrs_Yr)*(1+LOOKUP(YEAR(K$5),Inputs!$F$93:$I$93,Inputs!$F$94:$I$94)/Qtrs_Yr)^(COUNT($J$7:K7))-Inputs!$E$29*(1+Inputs!$E$31)*K$7/Inputs!$E$16/Qtrs_Yr-IF(OR(K$7=0,SUM($J7:K7)*K7>Inputs!$F$77*Qtrs_Yr),0,(Inputs!$F$71-SUM($J7:K7,-1)*K7*Inputs!$F$71/Inputs!$F$77/Qtrs_Yr)*(LOOKUP(YEAR(L$5),Inputs!$F$85:$I$85,Inputs!$F$86:$I$86)+LOOKUP(ROUNDUP(SUM($J7:L7)*L7/Qtrs_Yr,0),Inputs!$G$73:$J$73,Inputs!$G$74:$J$74))/Qtrs_Yr))*Inputs!$F$101-IF(OR(K$7=0,SUM($J7:K7)*K7>Inputs!$F$77*Qtrs_Yr),0,(Inputs!$F$71-SUM($J7:K7,-1)*K7*Inputs!$F$71/Inputs!$F$77/Qtrs_Yr)*(LOOKUP(YEAR(L$5),Inputs!$F$85:$I$85,Inputs!$F$86:$I$86)+LOOKUP(ROUNDUP(SUM($J7:L7)*L7/Qtrs_Yr,0),Inputs!$G$73:$J$73,Inputs!$G$74:$J$74))/Qtrs_Yr)-IF(OR(K$7=0,SUM($J7:K7)*K7>Inputs!$F$77*Qtrs_Yr),0,Inputs!$F$71/Inputs!$F$77/Qtrs_Yr) -> 0 | L11: =(((IF(ROUNDUP(SUM($J$7:L$7)*L$7/Qtrs_Yr,0)=0,0,LOOKUP(ROUNDUP(SUM($J$7:L$7)*L$7/Qtrs_Yr,0),Inputs!$F$35:$I$35,Inputs!$F$36:$I$36))/Thousand/Qtrs_Yr)*IF(ROUNDUP(SUM($J$7:L$7)*L$7/Qtrs_Yr,0)=0,0,LOOKUP(ROUNDUP(SUM($J$7:L$7)*L$7/Qtrs_Yr,0),Inputs!$F$41:$I$41,Inputs!$F$42:$I$42))/Grams_Oz*Inputs!$F$45)*LOOKUP(YEAR(L$5),Inputs!$F$49:$I$49,Inputs!$F$50:$I$50)/Thousand/LOOKUP(YEAR(L$5),Inputs!$F$89:$I$89,Inputs!$F$90:$I$90)*(L5-K5-Inputs!$F$97)/(L5-K5)+((IF(ROUNDUP(SUM($I$7:K$7)*K$7/Qtrs_Yr,0)=0,0,LOOKUP(ROUNDUP(SUM($I$7:K$7)*K$7/Qtrs_Yr,0),Inputs!$F$35:$I$35,Inputs!$F$36:$I$36))/Thousand/Qtrs_Yr)*IF(ROUNDUP(SUM($I$7:K$7)*K$7/Qtrs_Yr,0)=0,0,LOOKUP(ROUNDUP(SUM($I$7:K$7)*K$7/Qtrs_Yr,0),Inputs!$F$41:$I$41,Inputs!$F$42:$I$42))/Grams_Oz*Inputs!$F$45)*LOOKUP(YEAR(K$5),Inputs!$F$49:$I$49,Inputs!$F$50:$I$50)/Thousand/LOOKUP(YEAR(K$5),Inputs!$F$89:$I$89,Inputs!$F$90:$I$90)*Inputs!$F$97/(K5-J5))-(((Inputs!$F$64*(IF(ROUNDUP(SUM($J$7:L$7)*L$7/Qtrs_Yr,0)=0,0,LOOKUP(ROUNDUP(SUM($J$7:L$7)*L$7/Qtrs_Yr,0),Inputs!$F$35:$I$35,Inputs!$F$36:$I$36))/Thousand/Qtrs_Yr+IF(ROUNDUP(SUM($J$7:L$7)*L$7/Qtrs_Yr,0)=0,0,LOOKUP(ROUNDUP(SUM($J$7:L$7)*L$7/Qtrs_Yr,0),Inputs!$F$35:$I$35,Inputs!$F$38:$I$38)*LOOKUP(ROUNDUP(SUM($J$7:L$7)*L$7/Qtrs_Yr,0),Inputs!$F$35:$I$35,Inputs!$F$36:$I$36))/Thousand/Qtrs_Yr)+Inputs!$F$65*(IF(ROUNDUP(SUM($J$7:L$7)*L$7/Qtrs_Yr,0)=0,0,LOOKUP(ROUNDUP(SUM($J$7:L$7)*L$7/Qtrs_Yr,0),Inputs!$F$35:$I$35,Inputs!$F$36:$I$36))/Thousand/Qtrs_Yr)+Inputs!$F$66*(IF(ROUNDUP(SUM($J$7:L$7)*L$7/Qtrs_Yr,0)=0,0,LOOKUP(ROUNDUP(SUM($J$7:L$7)*L$7/Qtrs_Yr,0),Inputs!$F$35:$I$35,Inputs!$F$38:$I$38)*LOOKUP(ROUNDUP(SUM($J$7:L$7)*L$7/Qtrs_Yr,0),Inputs!$F$35:$I$35,Inputs!$F$36:$I$36))/Thousand/Qtrs_Yr))/Thousand+SUM(Inputs!$F$54:$F$61)*L$7/Qtrs_Yr)*(1+LOOKUP(YEAR(L$5),Inputs!$F$93:$I$93,Inputs!$F$94:$I$94)/Qtrs_Yr)^(COUNT($J$7:L7))*(L5-K5-Inputs!$F$98)/(L5-K5)+((Inputs!$F$64*(IF(ROUNDUP(SUM($I$7:K$7)*K$7/Qtrs_Yr,0)=0,0,LOOKUP(ROUNDUP(SUM($I$7:K$7)*K$7/Qtrs_Yr,0),Inputs!$F$35:$I$35,Inputs!$F$36:$I$36))/Thousand/Qtrs_Yr+IF(ROUNDUP(SUM($I$7:K$7)*K$7/Qtrs_Yr,0)=0,0,LOOKUP(ROUNDUP(SUM($I$7:K$7)*K$7/Qtrs_Yr,0),Inputs!$F$35:$I$35,Inputs!$F$38:$I$38)*LOOKUP(ROUNDUP(SUM($I$7:K$7)*K$7/Qtrs_Yr,0),Inputs!$F$35:$I$35,Inputs!$F$36:$I$36))/Thousand/Qtrs_Yr)+Inputs!$F$65*(IF(ROUNDUP(SUM($I$7:K$7)*K$7/Qtrs_Yr,0)=0,0,LOOKUP(ROUNDUP(SUM($I$7:K$7)*K$7/Qtrs_Yr,0),Inputs!$F$35:$I$35,Inputs!$F$36:$I$36))/Thousand/Qtrs_Yr)+Inputs!$F$66*(IF(ROUNDUP(SUM($I$7:K$7)*K$7/Qtrs_Yr,0)=0,0,LOOKUP(ROUNDUP(SUM($I$7:K$7)*K$7/Qtrs_Yr,0),Inputs!$F$35:$I$35,Inputs!$F$38:$I$38)*LOOKUP(ROUNDUP(SUM($I$7:K$7)*K$7/Qtrs_Yr,0),Inputs!$F$35:$I$35,Inputs!$F$36:$I$36))/Thousand/Qtrs_Yr))/Thousand+SUM(Inputs!$F$54:$F$61)*K$7/Qtrs_Yr)*(1+LOOKUP(YEAR(L$5),Inputs!$F$93:$I$93,Inputs!$F$94:$I$94)/Qtrs_Yr)^(COUNT($I$7:K7))*Inputs!$F$98/(K5-J5))-(((IF(ROUNDUP(SUM($J$7:L$7)*L$7/Qtrs_Yr,0)=0,0,LOOKUP(ROUNDUP(SUM($J$7:L$7)*L$7/Qtrs_Yr,0),Inputs!$F$35:$I$35,Inputs!$F$36:$I$36))/Thousand/Qtrs_Yr)*IF(ROUNDUP(SUM($J$7:L$7)*L$7/Qtrs_Yr,0)=0,0,LOOKUP(ROUNDUP(SUM($J$7:L$7)*L$7/Qtrs_Yr,0),Inputs!$F$41:$I$41,Inputs!$F$42:$I$42))/Grams_Oz*Inputs!$F$45)*LOOKUP(YEAR(L$5),Inputs!$F$49:$I$49,Inputs!$F$50:$I$50)/Thousand/LOOKUP(YEAR(L$5),Inputs!$F$89:$I$89,Inputs!$F$90:$I$90)-((Inputs!$F$64*(IF(ROUNDUP(SUM($J$7:L$7)*L$7/Qtrs_Yr,0)=0,0,LOOKUP(ROUNDUP(SUM($J$7:L$7)*L$7/Qtrs_Yr,0),Inputs!$F$35:$I$35,Inputs!$F$36:$I$36))/Thousand/Qtrs_Yr+IF(ROUNDUP(SUM($J$7:L$7)*L$7/Qtrs_Yr,0)=0,0,LOOKUP(ROUNDUP(SUM($J$7:L$7)*L$7/Qtrs_Yr,0),Inputs!$F$35:$I$35,Inputs!$F$38:$I$38)*LOOKUP(ROUNDUP(SUM($J$7:L$7)*L$7/Qtrs_Yr,0),Inputs!$F$35:$I$35,Inputs!$F$36:$I$36))/Thousand/Qtrs_Yr)+Inputs!$F$65*(IF(ROUNDUP(SUM($J$7:L$7)*L$7/Qtrs_Yr,0)=0,0,LOOKUP(ROUNDUP(SUM($J$7:L$7)*L$7/Qtrs_Yr,0),Inputs!$F$35:$I$35,Inputs!$F$36:$I$36))/Thousand/Qtrs_Yr)+Inputs!$F$66*(IF(ROUNDUP(SUM($J$7:L$7)*L$7/Qtrs_Yr,0)=0,0,LOOKUP(ROUNDUP(SUM($J$7:L$7)*L$7/Qtrs_Yr,0),Inputs!$F$35:$I$35,Inputs!$F$38:$I$38)*LOOKUP(ROUNDUP(SUM($J$7:L$7)*L$7/Qtrs_Yr,0),Inputs!$F$35:$I$35,Inputs!$F$36:$I$36))/Thousand/Qtrs_Yr))/Thousand+SUM(Inputs!$F$54:$F$61)*L$7/Qtrs_Yr)*(1+LOOKUP(YEAR(L$5),Inputs!$F$93:$I$93,Inputs!$F$94:$I$94)/Qtrs_Yr)^(COUNT($J$7:L7))-Inputs!$E$29*(1+Inputs!$E$31)*L$7/Inputs!$E$16/Qtrs_Yr-IF(OR(L$7=0,SUM($J7:L7)*L7>Inputs!$F$77*Qtrs_Yr),0,(Inputs!$F$71-SUM($J7:L7,-1)*L7*Inputs!$F$71/Inputs!$F$77/Qtrs_Yr)*(LOOKUP(YEAR(M$5),Inputs!$F$85:$I$85,Inputs!$F$86:$I$86)+LOOKUP(ROUNDUP(SUM($J7:M7)*M7/Qtrs_Yr,0),Inputs!$G$73:$J$73,Inputs!$G$74:$J$74))/Qtrs_Yr))*Inputs!$F$101-IF(OR(L$7=0,SUM($J7:L7)*L7>Inputs!$F$77*Qtrs_Yr),0,(Inputs!$F$71-SUM($J7:L7,-1)*L7*Inputs!$F$71/Inputs!$F$77/Qtrs_Yr)*(LOOKUP(YEAR(M$5),Inputs!$F$85:$I$85,Inputs!$F$86:$I$86)+LOOKUP(ROUNDUP(SUM($J7:M7)*M7/Qtrs_Yr,0),Inputs!$G$73:$J$73,Inputs!$G$74:$J$74))/Qtrs_Yr)-IF(OR(L$7=0,SUM($J7:L7)*L7>Inputs!$F$77*Qtrs_Yr),0,Inputs!$F$71/Inputs!$F$77/Qtrs_Yr) -> 0 | M11: =(((IF(ROUNDUP(SUM($J$7:M$7)*M$7/Qtrs_Yr,0)=0,0,LOOKUP(ROUNDUP(SUM($J$7:M$7)*M$7/Qtrs_Yr,0),Inputs!$F$35:$I$35,Inputs!$F$36:$I$36))/Thousand/Qtrs_Yr)*IF(ROUNDUP(SUM($J$7:M$7)*M$7/Qtrs_Yr,0)=0,0,LOOKUP(ROUNDUP(SUM($J$7:M$7)*M$7/Qtrs_Yr,0),Inputs!$F$41:$I$41,Inputs!$F$42:$I$42))/Grams_Oz*Inputs!$F$45)*LOOKUP(YEAR(M$5),Inputs!$F$49:$I$49,Inputs!$F$50:$I$50)/Thousand/LOOKUP(YEAR(M$5),Inputs!$F$89:$I$89,Inputs!$F$90:$I$90)*(M5-L5-Inputs!$F$97)/(M5-L5)+((IF(ROUNDUP(SUM($I$7:L$7)*L$7/Qtrs_Yr,0)=0,0,LOOKUP(ROUNDUP(SUM($I$7:L$7)*L$7/Qtrs_Yr,0),Inputs!$F$35:$I$35,Inputs!$F$36:$I$36))/Thousand/Qtrs_Yr)*IF(ROUNDUP(SUM($I$7:L$7)*L$7/Qtrs_Yr,0)=0,0,LOOKUP(ROUNDUP(SUM($I$7:L$7)*L$7/Qtrs_Yr,0),Inputs!$F$41:$I$41,Inputs!$F$42:$I$42))/Grams_Oz*Inputs!$F$45)*LOOKUP(YEAR(L$5),Inputs!$F$49:$I$49,Inputs!$F$50:$I$50)/Thousand/LOOKUP(YEAR(L$5),Inputs!$F$89:$I$89,Inputs!$F$90:$I$90)*Inputs!$F$97/(L5-K5))-(((Inputs!$F$64*(IF(ROUNDUP(SUM($J$7:M$7)*M$7/Qtrs_Yr,0)=0,0,LOOKUP(ROUNDUP(SUM($J$7:M$7)*M$7/Qtrs_Yr,0),Inputs!$F$35:$I$35,Inputs!$F$36:$I$36))/Thousand/Qtrs_Yr+IF(ROUNDUP(SUM($J$7:M$7)*M$7/Qtrs_Yr,0)=0,0,LOOKUP(ROUNDUP(SUM($J$7:M$7)*M$7/Qtrs_Yr,0),Inputs!$F$35:$I$35,Inputs!$F$38:$I$38)*LOOKUP(ROUNDUP(SUM($J$7:M$7)*M$7/Qtrs_Yr,0),Inputs!$F$35:$I$35,Inputs!$F$36:$I$36))/Thousand/Qtrs_Yr)+Inputs!$F$65*(IF(ROUNDUP(SUM($J$7:M$7)*M$7/Qtrs_Yr,0)=0,0,LOOKUP(ROUNDUP(SUM($J$7:M$7)*M$7/Qtrs_Yr,0),Inputs!$F$35:$I$35,Inputs!$F$36:$I$36))/Thousand/Qtrs_Yr)+Inputs!$F$66*(IF(ROUNDUP(SUM($J$7:M$7)*M$7/Qtrs_Yr,0)=0,0,LOOKUP(ROUNDUP(SUM($J$7:M$7)*M$7/Qtrs_Yr,0),Inputs!$F$35:$I$35,Inputs!$F$38:$I$38)*LOOKUP(ROUNDUP(SUM($J$7:M$7)*M$7/Qtrs_Yr,0),Inputs!$F$35:$I$35,Inputs!$F$36:$I$36))/Thousand/Qtrs_Yr))/Thousand+SUM(Inputs!$F$54:$F$61)*M$7/Qtrs_Yr)*(1+LOOKUP(YEAR(M$5),Inputs!$F$93:$I$93,Inputs!$F$94:$I$94)/Qtrs_Yr)^(COUNT($J$7:M7))*(M5-L5-Inputs!$F$98)/(M5-L5)+((Inputs!$F$64*(IF(ROUNDUP(SUM($I$7:L$7)*L$7/Qtrs_Yr,0)=0,0,LOOKUP(ROUNDUP(SUM($I$7:L$7)*L$7/Qtrs_Yr,0),Inputs!$F$35:$I$35,Inputs!$F$36:$I$36))/Thousand/Qtrs_Yr+IF(ROUNDUP(SUM($I$7:L$7)*L$7/Qtrs_Yr,0)=0,0,LOOKUP(ROUNDUP(SUM($I$7:L$7)*L$7/Qtrs_Yr,0),Inputs!$F$35:$I$35,Inputs!$F$38:$I$38)*LOOKUP(ROUNDUP(SUM($I$7:L$7)*L$7/Qtrs_Yr,0),Inputs!$F$35:$I$35,Inputs!$F$36:$I$36))/Thousand/Qtrs_Yr)+Inputs!$F$65*(IF(ROUNDUP(SUM($I$7:L$7)*L$7/Qtrs_Yr,0)=0,0,LOOKUP(ROUNDUP(SUM($I$7:L$7)*L$7/Qtrs_Yr,0),Inputs!$F$35:$I$35,Inputs!$F$36:$I$36))/Thousand/Qtrs_Yr)+Inputs!$F$66*(IF(ROUNDUP(SUM($I$7:L$7)*L$7/Qtrs_Yr,0)=0,0,LOOKUP(ROUNDUP(SUM($I$7:L$7)*L$7/Qtrs_Yr,0),Inputs!$F$35:$I$35,Inputs!$F$38:$I$38)*LOOKUP(ROUNDUP(SUM($I$7:L$7)*L$7/Qtrs_Yr,0),Inputs!$F$35:$I$35,Inputs!$F$36:$I$36))/Thousand/Qtrs_Yr))/Thousand+SUM(Inputs!$F$54:$F$61)*L$7/Qtrs_Yr)*(1+LOOKUP(YEAR(M$5),Inputs!$F$93:$I$93,Inputs!$F$94:$I$94)/Qtrs_Yr)^(COUNT($I$7:L7))*Inputs!$F$98/(L5-K5))-(((IF(ROUNDUP(SUM($J$7:M$7)*M$7/Qtrs_Yr,0)=0,0,LOOKUP(ROUNDUP(SUM($J$7:M$7)*M$7/Qtrs_Yr,0),Inputs!$F$35:$I$35,Inputs!$F$36:$I$36))/Thousand/Qtrs_Yr)*IF(ROUNDUP(SUM($J$7:M$7)*M$7/Qtrs_Yr,0)=0,0,LOOKUP(ROUNDUP(SUM($J$7:M$7)*M$7/Qtrs_Yr,0),Inputs!$F$41:$I$41,Inputs!$F$42:$I$42))/Grams_Oz*Inputs!$F$45)*LOOKUP(YEAR(M$5),Inputs!$F$49:$I$49,Inputs!$F$50:$I$50)/Thousand/LOOKUP(YEAR(M$5),Inputs!$F$89:$I$89,Inputs!$F$90:$I$90)-((Inputs!$F$64*(IF(ROUNDUP(SUM($J$7:M$7)*M$7/Qtrs_Yr,0)=0,0,LOOKUP(ROUNDUP(SUM($J$7:M$7)*M$7/Qtrs_Yr,0),Inputs!$F$35:$I$35,Inputs!$F$36:$I$36))/Thousand/Qtrs_Yr+IF(ROUNDUP(SUM($J$7:M$7)*M$7/Qtrs_Yr,0)=0,0,LOOKUP(ROUNDUP(SUM($J$7:M$7)*M$7/Qtrs_Yr,0),Inputs!$F$35:$I$35,Inputs!$F$38:$I$38)*LOOKUP(ROUNDUP(SUM($J$7:M$7)*M$7/Qtrs_Yr,0),Inputs!$F$35:$I$35,Inputs!$F$36:$I$36))/Thousand/Qtrs_Yr)+Inputs!$F$65*(IF(ROUNDUP(SUM($J$7:M$7)*M$7/Qtrs_Yr,0)=0,0,LOOKUP(ROUNDUP(SUM($J$7:M$7)*M$7/Qtrs_Yr,0),Inputs!$F$35:$I$35,Inputs!$F$36:$I$36))/Thousand/Qtrs_Yr)+Inputs!$F$66*(IF(ROUNDUP(SUM($J$7:M$7)*M$7/Qtrs_Yr,0)=0,0,LOOKUP(ROUNDUP(SUM($J$7:M$7)*M$7/Qtrs_Yr,0),Inputs!$F$35:$I$35,Inputs!$F$38:$I$38)*LOOKUP(ROUNDUP(SUM($J$7:M$7)*M$7/Qtrs_Yr,0),Inputs!$F$35:$I$35,Inputs!$F$36:$I$36))/Thousand/Qtrs_Yr))/Thousand+SUM(Inputs!$F$54:$F$61)*M$7/Qtrs_Yr)*(1+LOOKUP(YEAR(M$5),Inputs!$F$93:$I$93,Inputs!$F$94:$I$94)/Qtrs_Yr)^(COUNT($J$7:M7))-Inputs!$E$29*(1+Inputs!$E$31)*M$7/Inputs!$E$16/Qtrs_Yr-IF(OR(M$7=0,SUM($J7:M7)*M7>Inputs!$F$77*Qtrs_Yr),0,(Inputs!$F$71-SUM($J7:M7,-1)*M7*Inputs!$F$71/Inputs!$F$77/Qtrs_Yr)*(LOOKUP(YEAR(N$5),Inputs!$F$85:$I$85,Inputs!$F$86:$I$86)+LOOKUP(ROUNDUP(SUM($J7:N7)*N7/Qtrs_Yr,0),Inputs!$G$73:$J$73,Inputs!$G$74:$J$74))/Qtrs_Yr))*Inputs!$F$101-IF(OR(M$7=0,SUM($J7:M7)*M7>Inputs!$F$77*Qtrs_Yr),0,(Inputs!$F$71-SUM($J7:M7,-1)*M7*Inputs!$F$71/Inputs!$F$77/Qtrs_Yr)*(LOOKUP(YEAR(N$5),Inputs!$F$85:$I$85,Inputs!$F$86:$I$86)+LOOKUP(ROUNDUP(SUM($J7:N7)*N7/Qtrs_Yr,0),Inputs!$G$73:$J$73,Inputs!$G$74:$J$74))/Qtrs_Yr)-IF(OR(M$7=0,SUM($J7:M7)*M7>Inputs!$F$77*Qtrs_Yr),0,Inputs!$F$71/Inputs!$F$77/Qtrs_Yr) -> 0 | N11: =(((IF(ROUNDUP(SUM($J$7:N$7)*N$7/Qtrs_Yr,0)=0,0,LOOKUP(ROUNDUP(SUM($J$7:N$7)*N$7/Qtrs_Yr,0),Inputs!$F$35:$I$35,Inputs!$F$36:$I$36))/Thousand/Qtrs_Yr)*IF(ROUNDUP(SUM($J$7:N$7)*N$7/Qtrs_Yr,0)=0,0,LOOKUP(ROUNDUP(SUM($J$7:N$7)*N$7/Qtrs_Yr,0),Inputs!$F$41:$I$41,Inputs!$F$42:$I$42))/Grams_Oz*Inputs!$F$45)*LOOKUP(YEAR(N$5),Inputs!$F$49:$I$49,Inputs!$F$50:$I$50)/Thousand/LOOKUP(YEAR(N$5),Inputs!$F$89:$I$89,Inputs!$F$90:$I$90)*(N5-M5-Inputs!$F$97)/(N5-M5)+((IF(ROUNDUP(SUM($I$7:M$7)*M$7/Qtrs_Yr,0)=0,0,LOOKUP(ROUNDUP(SUM($I$7:M$7)*M$7/Qtrs_Yr,0),Inputs!$F$35:$I$35,Inputs!$F$36:$I$36))/Thousand/Qtrs_Yr)*IF(ROUNDUP(SUM($I$7:M$7)*M$7/Qtrs_Yr,0)=0,0,LOOKUP(ROUNDUP(SUM($I$7:M$7)*M$7/Qtrs_Yr,0),Inputs!$F$41:$I$41,Inputs!$F$42:$I$42))/Grams_Oz*Inputs!$F$45)*LOOKUP(YEAR(M$5),Inputs!$F$49:$I$49,Inputs!$F$50:$I$50)/Thousand/LOOKUP(YEAR(M$5),Inputs!$F$89:$I$89,Inputs!$F$90:$I$90)*Inputs!$F$97/(M5-L5))-(((Inputs!$F$64*(IF(ROUNDUP(SUM($J$7:N$7)*N$7/Qtrs_Yr,0)=0,0,LOOKUP(ROUNDUP(SUM($J$7:N$7)*N$7/Qtrs_Yr,0),Inputs!$F$35:$I$35,Inputs!$F$36:$I$36))/Thousand/Qtrs_Yr+IF(ROUNDUP(SUM($J$7:N$7)*N$7/Qtrs_Yr,0)=0,0,LOOKUP(ROUNDUP(SUM($J$7:N$7)*N$7/Qtrs_Yr,0),Inputs!$F$35:$I$35,Inputs!$F$38:$I$38)*LOOKUP(ROUNDUP(SUM($J$7:N$7)*N$7/Qtrs_Yr,0),Inputs!$F$35:$I$35,Inputs!$F$36:$I$36))/Thousand/Qtrs_Yr)+Inputs!$F$65*(IF(ROUNDUP(SUM($J$7:N$7)*N$7/Qtrs_Yr,0)=0,0,LOOKUP(ROUNDUP(SUM($J$7:N$7)*N$7/Qtrs_Yr,0),Inputs!$F$35:$I$35,Inputs!$F$36:$I$36))/Thousand/Qtrs_Yr)+Inputs!$F$66*(IF(ROUNDUP(SUM($J$7:N$7)*N$7/Qtrs_Yr,0)=0,0,LOOKUP(ROUNDUP(SUM($J$7:N$7)*N$7/Qtrs_Yr,0),Inputs!$F$35:$I$35,Inputs!$F$38:$I$38)*LOOKUP(ROUNDUP(SUM($J$7:N$7)*N$7/Qtrs_Yr,0),Inputs!$F$35:$I$35,Inputs!$F$36:$I$36))/Thousand/Qtrs_Yr))/Thousand+SUM(Inputs!$F$54:$F$61)*N$7/Qtrs_Yr)*(1+LOOKUP(YEAR(N$5),Inputs!$F$93:$I$93,Inputs!$F$94:$I$94)/Qtrs_Yr)^(COUNT($J$7:N7))*(N5-M5-Inputs!$F$98)/(N5-M5)+((Inputs!$F$64*(IF(ROUNDUP(SUM($I$7:M$7)*M$7/Qtrs_Yr,0)=0,0,LOOKUP(ROUNDUP(SUM($I$7:M$7)*M$7/Qtrs_Yr,0),Inputs!$F$35:$I$35,Inputs!$F$36:$I$36))/Thousand/Qtrs_Yr+IF(ROUNDUP(SUM($I$7:M$7)*M$7/Qtrs_Yr,0)=0,0,LOOKUP(ROUNDUP(SUM($I$7:M$7)*M$7/Qtrs_Yr,0),Inputs!$F$35:$I$35,Inputs!$F$38:$I$38)*LOOKUP(ROUNDUP(SUM($I$7:M$7)*M$7/Qtrs_Yr,0),Inputs!$F$35:$I$35,Inputs!$F$36:$I$36))/Thousand/Qtrs_Yr)+Inputs!$F$65*(IF(ROUNDUP(SUM($I$7:M$7)*M$7/Qtrs_Yr,0)=0,0,LOOKUP(ROUNDUP(SUM($I$7:M$7)*M$7/Qtrs_Yr,0),Inputs!$F$35:$I$35,Inputs!$F$36:$I$36))/Thousand/Qtrs_Yr)+Inputs!$F$66*(IF(ROUNDUP(SUM($I$7:M$7)*M$7/Qtrs_Yr,0)=0,0,LOOKUP(ROUNDUP(SUM($I$7:M$7)*M$7/Qtrs_Yr,0),Inputs!$F$35:$I$35,Inputs!$F$38:$I$38)*LOOKUP(ROUNDUP(SUM($I$7:M$7)*M$7/Qtrs_Yr,0),Inputs!$F$35:$I$35,Inputs!$F$36:$I$36))/Thousand/Qtrs_Yr))/Thousand+SUM(Inputs!$F$54:$F$61)*M$7/Qtrs_Yr)*(1+LOOKUP(YEAR(N$5),Inputs!$F$93:$I$93,Inputs!$F$94:$I$94)/Qtrs_Yr)^(COUNT($I$7:M7))*Inputs!$F$98/(M5-L5))-(((IF(ROUNDUP(SUM($J$7:N$7)*N$7/Qtrs_Yr,0)=0,0,LOOKUP(ROUNDUP(SUM($J$7:N$7)*N$7/Qtrs_Yr,0),Inputs!$F$35:$I$35,Inputs!$F$36:$I$36))/Thousand/Qtrs_Yr)*IF(ROUNDUP(SUM($J$7:N$7)*N$7/Qtrs_Yr,0)=0,0,LOOKUP(ROUNDUP(SUM($J$7:N$7)*N$7/Qtrs_Yr,0),Inputs!$F$41:$I$41,Inputs!$F$42:$I$42))/Grams_Oz*Inputs!$F$45)*LOOKUP(YEAR(N$5),Inputs!$F$49:$I$49,Inputs!$F$50:$I$50)/Thousand/LOOKUP(YEAR(N$5),Inputs!$F$89:$I$89,Inputs!$F$90:$I$90)-((Inputs!$F$64*(IF(ROUNDUP(SUM($J$7:N$7)*N$7/Qtrs_Yr,0)=0,0,LOOKUP(ROUNDUP(SUM($J$7:N$7)*N$7/Qtrs_Yr,0),Inputs!$F$35:$I$35,Inputs!$F$36:$I$36))/Thousand/Qtrs_Yr+IF(ROUNDUP(SUM($J$7:N$7)*N$7/Qtrs_Yr,0)=0,0,LOOKUP(ROUNDUP(SUM($J$7:N$7)*N$7/Qtrs_Yr,0),Inputs!$F$35:$I$35,Inputs!$F$38:$I$38)*LOOKUP(ROUNDUP(SUM($J$7:N$7)*N$7/Qtrs_Yr,0),Inputs!$F$35:$I$35,Inputs!$F$36:$I$36))/Thousand/Qtrs_Yr)+Inputs!$F$65*(IF(ROUNDUP(SUM($J$7:N$7)*N$7/Qtrs_Yr,0)=0,0,LOOKUP(ROUNDUP(SUM($J$7:N$7)*N$7/Qtrs_Yr,0),Inputs!$F$35:$I$35,Inputs!$F$36:$I$36))/Thousand/Qtrs_Yr)+Inputs!$F$66*(IF(ROUNDUP(SUM($J$7:N$7)*N$7/Qtrs_Yr,0)=0,0,LOOKUP(ROUNDUP(SUM($J$7:N$7)*N$7/Qtrs_Yr,0),Inputs!$F$35:$I$35,Inputs!$F$38:$I$38)*LOOKUP(ROUNDUP(SUM($J$7:N$7)*N$7/Qtrs_Yr,0),Inputs!$F$35:$I$35,Inputs!$F$36:$I$36))/Thousand/Qtrs_Yr))/Thousand+SUM(Inputs!$F$54:$F$61)*N$7/Qtrs_Yr)*(1+LOOKUP(YEAR(N$5),Inputs!$F$93:$I$93,Inputs!$F$94:$I$94)/Qtrs_Yr)^(COUNT($J$7:N7))-Inputs!$E$29*(1+Inputs!$E$31)*N$7/Inputs!$E$16/Qtrs_Yr-IF(OR(N$7=0,SUM($J7:N7)*N7>Inputs!$F$77*Qtrs_Yr),0,(Inputs!$F$71-SUM($J7:N7,-1)*N7*Inputs!$F$71/Inputs!$F$77/Qtrs_Yr)*(LOOKUP(YEAR(O$5),Inputs!$F$85:$I$85,Inputs!$F$86:$I$86)+LOOKUP(ROUNDUP(SUM($J7:O7)*O7/Qtrs_Yr,0),Inputs!$G$73:$J$73,Inputs!$G$74:$J$74))/Qtrs_Yr))*Inputs!$F$101-IF(OR(N$7=0,SUM($J7:N7)*N7>Inputs!$F$77*Qtrs_Yr),0,(Inputs!$F$71-SUM($J7:N7,-1)*N7*Inputs!$F$71/Inputs!$F$77/Qtrs_Yr)*(LOOKUP(YEAR(O$5),Inputs!$F$85:$I$85,Inputs!$F$86:$I$86)+LOOKUP(ROUNDUP(SUM($J7:O7)*O7/Qtrs_Yr,0),Inputs!$G$73:$J$73,Inputs!$G$74:$J$74))/Qtrs_Yr)-IF(OR(N$7=0,SUM($J7:N7)*N7>Inputs!$F$77*Qtrs_Yr),0,Inputs!$F$71/Inputs!$F$77/Qtrs_Yr) -> 1.2273457 | O11: =(((IF(ROUNDUP(SUM($J$7:O$7)*O$7/Qtrs_Yr,0)=0,0,LOOKUP(ROUNDUP(SUM($J$7:O$7)*O$7/Qtrs_Yr,0),Inputs!$F$35:$I$35,Inputs!$F$36:$I$36))/Thousand/Qtrs_Yr)*IF(ROUNDUP(SUM($J$7:O$7)*O$7/Qtrs_Yr,0)=0,0,LOOKUP(ROUNDUP(SUM($J$7:O$7)*O$7/Qtrs_Yr,0),Inputs!$F$41:$I$41,Inputs!$F$42:$I$42))/Grams_Oz*Inputs!$F$45)*LOOKUP(YEAR(O$5),Inputs!$F$49:$I$49,Inputs!$F$50:$I$50)/Thousand/LOOKUP(YEAR(O$5),Inputs!$F$89:$I$89,Inputs!$F$90:$I$90)*(O5-N5-Inputs!$F$97)/(O5-N5)+((IF(ROUNDUP(SUM($I$7:N$7)*N$7/Qtrs_Yr,0)=0,0,LOOKUP(ROUNDUP(SUM($I$7:N$7)*N$7/Qtrs_Yr,0),Inputs!$F$35:$I$35,Inputs!$F$36:$I$36))/Thousand/Qtrs_Yr)*IF(ROUNDUP(SUM($I$7:N$7)*N$7/Qtrs_Yr,0)=0,0,LOOKUP(ROUNDUP(SUM($I$7:N$7)*N$7/Qtrs_Yr,0),Inputs!$F$41:$I$41,Inputs!$F$42:$I$42))/Grams_Oz*Inputs!$F$45)*LOOKUP(YEAR(N$5),Inputs!$F$49:$I$49,Inputs!$F$50:$I$50)/Thousand/LOOKUP(YEAR(N$5),Inputs!$F$89:$I$89,Inputs!$F$90:$I$90)*Inputs!$F$97/(N5-M5))-(((Inputs!$F$64*(IF(ROUNDUP(SUM($J$7:O$7)*O$7/Qtrs_Yr,0)=0,0,LOOKUP(ROUNDUP(SUM($J$7:O$7)*O$7/Qtrs_Yr,0),Inputs!$F$35:$I$35,Inputs!$F$36:$I$36))/Thousand/Qtrs_Yr+IF(ROUNDUP(SUM($J$7:O$7)*O$7/Qtrs_Yr,0)=0,0,LOOKUP(ROUNDUP(SUM($J$7:O$7)*O$7/Qtrs_Yr,0),Inputs!$F$35:$I$35,Inputs!$F$38:$I$38)*LOOKUP(ROUNDUP(SUM($J$7:O$7)*O$7/Qtrs_Yr,0),Inputs!$F$35:$I$35,Inputs!$F$36:$I$36))/Thousand/Qtrs_Yr)+Inputs!$F$65*(IF(ROUNDUP(SUM($J$7:O$7)*O$7/Qtrs_Yr,0)=0,0,LOOKUP(ROUNDUP(SUM($J$7:O$7)*O$7/Qtrs_Yr,0),Inputs!$F$35:$I$35,Inputs!$F$36:$I$36))/Thousand/Qtrs_Yr)+Inputs!$F$66*(IF(ROUNDUP(SUM($J$7:O$7)*O$7/Qtrs_Yr,0)=0,0,LOOKUP(ROUNDUP(SUM($J$7:O$7)*O$7/Qtrs_Yr,0),Inputs!$F$35:$I$35,Inputs!$F$38:$I$38)*LOOKUP(ROUNDUP(SUM($J$7:O$7)*O$7/Qtrs_Yr,0),Inputs!$F$35:$I$35,Inputs!$F$36:$I$36))/Thousand/Qtrs_Yr))/Thousand+SUM(Inputs!$F$54:$F$61)*O$7/Qtrs_Yr)*(1+LOOKUP(YEAR(O$5),Inputs!$F$93:$I$93,Inputs!$F$94:$I$94)/Qtrs_Yr)^(COUNT($J$7:O7))*(O5-N5-Inputs!$F$98)/(O5-N5)+((Inputs!$F$64*(IF(ROUNDUP(SUM($I$7:N$7)*N$7/Qtrs_Yr,0)=0,0,LOOKUP(ROUNDUP(SUM($I$7:N$7)*N$7/Qtrs_Yr,0),Inputs!$F$35:$I$35,Inputs!$F$36:$I$36))/Thousand/Qtrs_Yr+IF(ROUNDUP(SUM($I$7:N$7)*N$7/Qtrs_Yr,0)=0,0,LOOKUP(ROUNDUP(SUM($I$7:N$7)*N$7/Qtrs_Yr,0),Inputs!$F$35:$I$35,Inputs!$F$38:$I$38)*LOOKUP(ROUNDUP(SUM($I$7:N$7)*N$7/Qtrs_Yr,0),Inputs!$F$35:$I$35,Inputs!$F$36:$I$36))/Thousand/Qtrs_Yr)+Inputs!$F$65*(IF(ROUNDUP(SUM($I$7:N$7)*N$7/Qtrs_Yr,0)=0,0,LOOKUP(ROUNDUP(SUM($I$7:N$7)*N$7/Qtrs_Yr,0),Inputs!$F$35:$I$35,Inputs!$F$36:$I$36))/Thousand/Qtrs_Yr)+Inputs!$F$66*(IF(ROUNDUP(SUM($I$7:N$7)*N$7/Qtrs_Yr,0)=0,0,LOOKUP(ROUNDUP(SUM($I$7:N$7)*N$7/Qtrs_Yr,0),Inputs!$F$35:$I$35,Inputs!$F$38:$I$38)*LOOKUP(ROUNDUP(SUM($I$7:N$7)*N$7/Qtrs_Yr,0),Inputs!$F$35:$I$35,Inputs!$F$36:$I$36))/Thousand/Qtrs_Yr))/Thousand+SUM(Inputs!$F$54:$F$61)*N$7/Qtrs_Yr)*(1+LOOKUP(YEAR(O$5),Inputs!$F$93:$I$93,Inputs!$F$94:$I$94)/Qtrs_Yr)^(COUNT($I$7:N7))*Inputs!$F$98/(N5-M5))-(((IF(ROUNDUP(SUM($J$7:O$7)*O$7/Qtrs_Yr,0)=0,0,LOOKUP(ROUNDUP(SUM($J$7:O$7)*O$7/Qtrs_Yr,0),Inputs!$F$35:$I$35,Inputs!$F$36:$I$36))/Thousand/Qtrs_Yr)*IF(ROUNDUP(SUM($J$7:O$7)*O$7/Qtrs_Yr,0)=0,0,LOOKUP(ROUNDUP(SUM($J$7:O$7)*O$7/Qtrs_Yr,0),Inputs!$F$41:$I$41,Inputs!$F$42:$I$42))/Grams_Oz*Inputs!$F$45)*LOOKUP(YEAR(O$5),Inputs!$F$49:$I$49,Inputs!$F$50:$I$50)/Thousand/LOOKUP(YEAR(O$5),Inputs!$F$89:$I$89,Inputs!$F$90:$I$90)-((Inputs!$F$64*(IF(ROUNDUP(SUM($J$7:O$7)*O$7/Qtrs_Yr,0)=0,0,LOOKUP(ROUNDUP(SUM($J$7:O$7)*O$7/Qtrs_Yr,0),Inputs!$F$35:$I$35,Inputs!$F$36:$I$36))/Thousand/Qtrs_Yr+IF(ROUNDUP(SUM($J$7:O$7)*O$7/Qtrs_Yr,0)=0,0,LOOKUP(ROUNDUP(SUM($J$7:O$7)*O$7/Qtrs_Yr,0),Inputs!$F$35:$I$35,Inputs!$F$38:$I$38)*LOOKUP(ROUNDUP(SUM($J$7:O$7)*O$7/Qtrs_Yr,0),Inputs!$F$35:$I$35,Inputs!$F$36:$I$36))/Thousand/Qtrs_Yr)+Inputs!$F$65*(IF(ROUNDUP(SUM($J$7:O$7)*O$7/Qtrs_Yr,0)=0,0,LOOKUP(ROUNDUP(SUM($J$7:O$7)*O$7/Qtrs_Yr,0),Inputs!$F$35:$I$35,Inputs!$F$36:$I$36))/Thousand/Qtrs_Yr)+Inputs!$F$66*(IF(ROUNDUP(SUM($J$7:O$7)*O$7/Qtrs_Yr,0)=0,0,LOOKUP(ROUNDUP(SUM($J$7:O$7)*O$7/Qtrs_Yr,0),Inputs!$F$35:$I$35,Inputs!$F$38:$I$38)*LOOKUP(ROUNDUP(SUM($J$7:O$7)*O$7/Qtrs_Yr,0),Inputs!$F$35:$I$35,Inputs!$F$36:$I$36))/Thousand/Qtrs_Yr))/Thousand+SUM(Inputs!$F$54:$F$61)*O$7/Qtrs_Yr)*(1+LOOKUP(YEAR(O$5),Inputs!$F$93:$I$93,Inputs!$F$94:$I$94)/Qtrs_Yr)^(COUNT($J$7:O7))-Inputs!$E$29*(1+Inputs!$E$31)*O$7/Inputs!$E$16/Qtrs_Yr-IF(OR(O$7=0,SUM($J7:O7)*O7>Inputs!$F$77*Qtrs_Yr),0,(Inputs!$F$71-SUM($J7:O7,-1)*O7*Inputs!$F$71/Inputs!$F$77/Qtrs_Yr)*(LOOKUP(YEAR(P$5),Inputs!$F$85:$I$85,Inputs!$F$86:$I$86)+LOOKUP(ROUNDUP(SUM($J7:P7)*P7/Qtrs_Yr,0),Inputs!$G$73:$J$73,Inputs!$G$74:$J$74))/Qtrs_Yr))*Inputs!$F$101-IF(OR(O$7=0,SUM($J7:O7)*O7>Inputs!$F$77*Qtrs_Yr),0,(Inputs!$F$71-SUM($J7:O7,-1)*O7*Inputs!$F$71/Inputs!$F$77/Qtrs_Yr)*(LOOKUP(YEAR(P$5),Inputs!$F$85:$I$85,Inputs!$F$86:$I$86)+LOOKUP(ROUNDUP(SUM($J7:P7)*P7/Qtrs_Yr,0),Inputs!$G$73:$J$73,Inputs!$G$74:$J$74))/Qtrs_Yr)-IF(OR(O$7=0,SUM($J7:O7)*O7>Inputs!$F$77*Qtrs_Yr),0,Inputs!$F$71/Inputs!$F$77/Qtrs_Yr) -> 4.1659453 | P11: =(((IF(ROUNDUP(SUM($J$7:P$7)*P$7/Qtrs_Yr,0)=0,0,LOOKUP(ROUNDUP(SUM($J$7:P$7)*P$7/Qtrs_Yr,0),Inputs!$F$35:$I$35,Inputs!$F$36:$I$36))/Thousand/Qtrs_Yr)*IF(ROUNDUP(SUM($J$7:P$7)*P$7/Qtrs_Yr,0)=0,0,LOOKUP(ROUNDUP(SUM($J$7:P$7)*P$7/Qtrs_Yr,0),Inputs!$F$41:$I$41,Inputs!$F$42:$I$42))/Grams_Oz*Inputs!$F$45)*LOOKUP(YEAR(P$5),Inputs!$F$49:$I$49,Inputs!$F$50:$I$50)/Thousand/LOOKUP(YEAR(P$5),Inputs!$F$89:$I$89,Inputs!$F$90:$I$90)*(P5-O5-Inputs!$F$97)/(P5-O5)+((IF(ROUNDUP(SUM($I$7:O$7)*O$7/Qtrs_Yr,0)=0,0,LOOKUP(ROUNDUP(SUM($I$7:O$7)*O$7/Qtrs_Yr,0),Inputs!$F$35:$I$35,Inputs!$F$36:$I$36))/Thousand/Qtrs_Yr)*IF(ROUNDUP(SUM($I$7:O$7)*O$7/Qtrs_Yr,0)=0,0,LOOKUP(ROUNDUP(SUM($I$7:O$7)*O$7/Qtrs_Yr,0),Inputs!$F$41:$I$41,Inputs!$F$42:$I$42))/Grams_Oz*Inputs!$F$45)*LOOKUP(YEAR(O$5),Inputs!$F$49:$I$49,Inputs!$F$50:$I$50)/Thousand/LOOKUP(YEAR(O$5),Inputs!$F$89:$I$89,Inputs!$F$90:$I$90)*Inputs!$F$97/(O5-N5))-(((Inputs!$F$64*(IF(ROUNDUP(SUM($J$7:P$7)*P$7/Qtrs_Yr,0)=0,0,LOOKUP(ROUNDUP(SUM($J$7:P$7)*P$7/Qtrs_Yr,0),Inputs!$F$35:$I$35,Inputs!$F$36:$I$36))/Thousand/Qtrs_Yr+IF(ROUNDUP(SUM($J$7:P$7)*P$7/Qtrs_Yr,0)=0,0,LOOKUP(ROUNDUP(SUM($J$7:P$7)*P$7/Qtrs_Yr,0),Inputs!$F$35:$I$35,Inputs!$F$38:$I$38)*LOOKUP(ROUNDUP(SUM($J$7:P$7)*P$7/Qtrs_Yr,0),Inputs!$F$35:$I$35,Inputs!$F$36:$I$36))/Thousand/Qtrs_Yr)+Inputs!$F$65*(IF(ROUNDUP(SUM($J$7:P$7)*P$7/Qtrs_Yr,0)=0,0,LOOKUP(ROUNDUP(SUM($J$7:P$7)*P$7/Qtrs_Yr,0),Inputs!$F$35:$I$35,Inputs!$F$36:$I$36))/Thousand/Qtrs_Yr)+Inputs!$F$66*(IF(ROUNDUP(SUM($J$7:P$7)*P$7/Qtrs_Yr,0)=0,0,LOOKUP(ROUNDUP(SUM($J$7:P$7)*P$7/Qtrs_Yr,0),Inputs!$F$35:$I$35,Inputs!$F$38:$I$38)*LOOKUP(ROUNDUP(SUM($J$7:P$7)*P$7/Qtrs_Yr,0),Inputs!$F$35:$I$35,Inputs!$F$36:$I$36))/Thousand/Qtrs_Yr))/Thousand+SUM(Inputs!$F$54:$F$61)*P$7/Qtrs_Yr)*(1+LOOKUP(YEAR(P$5),Inputs!$F$93:$I$93,Inputs!$F$94:$I$94)/Qtrs_Yr)^(COUNT($J$7:P7))*(P5-O5-Inputs!$F$98)/(P5-O5)+((Inputs!$F$64*(IF(ROUNDUP(SUM($I$7:O$7)*O$7/Qtrs_Yr,0)=0,0,LOOKUP(ROUNDUP(SUM($I$7:O$7)*O$7/Qtrs_Yr,0),Inputs!$F$35:$I$35,Inputs!$F$36:$I$36))/Thousand/Qtrs_Yr+IF(ROUNDUP(SUM($I$7:O$7)*O$7/Qtrs_Yr,0)=0,0,LOOKUP(ROUNDUP(SUM($I$7:O$7)*O$7/Qtrs_Yr,0),Inputs!$F$35:$I$35,Inputs!$F$38:$I$38)*LOOKUP(ROUNDUP(SUM($I$7:O$7)*O$7/Qtrs_Yr,0),Inputs!$F$35:$I$35,Inputs!$F$36:$I$36))/Thousand/Qtrs_Yr)+Inputs!$F$65*(IF(ROUNDUP(SUM($I$7:O$7)*O$7/Qtrs_Yr,0)=0,0,LOOKUP(ROUNDUP(SUM($I$7:O$7)*O$7/Qtrs_Yr,0),Inputs!$F$35:$I$35,Inputs!$F$36:$I$36))/Thousand/Qtrs_Yr)+Inputs!$F$66*(IF(ROUNDUP(SUM($I$7:O$7)*O$7/Qtrs_Yr,0)=0,0,LOOKUP(ROUNDUP(SUM($I$7:O$7)*O$7/Qtrs_Yr,0),Inputs!$F$35:$I$35,Inputs!$F$38:$I$38)*LOOKUP(ROUNDUP(SUM($I$7:O$7)*O$7/Qtrs_Yr,0),Inputs!$F$35:$I$35,Inputs!$F$36:$I$36))/Thousand/Qtrs_Yr))/Thousand+SUM(Inputs!$F$54:$F$61)*O$7/Qtrs_Yr)*(1+LOOKUP(YEAR(P$5),Inputs!$F$93:$I$93,Inputs!$F$94:$I$94)/Qtrs_Yr)^(COUNT($I$7:O7))*Inputs!$F$98/(O5-N5))-(((IF(ROUNDUP(SUM($J$7:P$7)*P$7/Qtrs_Yr,0)=0,0,LOOKUP(ROUNDUP(SUM($J$7:P$7)*P$7/Qtrs_Yr,0),Inputs!$F$35:$I$35,Inputs!$F$36:$I$36))/Thousand/Qtrs_Yr)*IF(ROUNDUP(SUM($J$7:P$7)*P$7/Qtrs_Yr,0)=0,0,LOOKUP(ROUNDUP(SUM($J$7:P$7)*P$7/Qtrs_Yr,0),Inputs!$F$41:$I$41,Inputs!$F$42:$I$42))/Grams_Oz*Inputs!$F$45)*LOOKUP(YEAR(P$5),Inputs!$F$49:$I$49,Inputs!$F$50:$I$50)/Thousand/LOOKUP(YEAR(P$5),Inputs!$F$89:$I$89,Inputs!$F$90:$I$90)-((Inputs!$F$64*(IF(ROUNDUP(SUM($J$7:P$7)*P$7/Qtrs_Yr,0)=0,0,LOOKUP(ROUNDUP(SUM($J$7:P$7)*P$7/Qtrs_Yr,0),Inputs!$F$35:$I$35,Inputs!$F$36:$I$36))/Thousand/Qtrs_Yr+IF(ROUNDUP(SUM($J$7:P$7)*P$7/Qtrs_Yr,0)=0,0,LOOKUP(ROUNDUP(SUM($J$7:P$7)*P$7/Qtrs_Yr,0),Inputs!$F$35:$I$35,Inputs!$F$38:$I$38)*LOOKUP(ROUNDUP(SUM($J$7:P$7)*P$7/Qtrs_Yr,0),Inputs!$F$35:$I$35,Inputs!$F$36:$I$36))/Thousand/Qtrs_Yr)+Inputs!$F$65*(IF(ROUNDUP(SUM($J$7:P$7)*P$7/Qtrs_Yr,0)=0,0,LOOKUP(ROUNDUP(SUM($J$7:P$7)*P$7/Qtrs_Yr,0),Inputs!$F$35:$I$35,Inputs!$F$36:$I$36))/Thousand/Qtrs_Yr)+Inputs!$F$66*(IF(ROUNDUP(SUM($J$7:P$7)*P$7/Qtrs_Yr,0)=0,0,LOOKUP(ROUNDUP(SUM($J$7:P$7)*P$7/Qtrs_Yr,0),Inputs!$F$35:$I$35,Inputs!$F$38:$I$38)*LOOKUP(ROUNDUP(SUM($J$7:P$7)*P$7/Qtrs_Yr,0),Inputs!$F$35:$I$35,Inputs!$F$36:$I$36))/Thousand/Qtrs_Yr))/Thousand+SUM(Inputs!$F$54:$F$61)*P$7/Qtrs_Yr)*(1+LOOKUP(YEAR(P$5),Inputs!$F$93:$I$93,Inputs!$F$94:$I$94)/Qtrs_Yr)^(COUNT($J$7:P7))-Inputs!$E$29*(1+Inputs!$E$31)*P$7/Inputs!$E$16/Qtrs_Yr-IF(OR(P$7=0,SUM($J7:P7)*P7>Inputs!$F$77*Qtrs_Yr),0,(Inputs!$F$71-SUM($J7:P7,-1)*P7*Inputs!$F$71/Inputs!$F$77/Qtrs_Yr)*(LOOKUP(YEAR(Q$5),Inputs!$F$85:$I$85,Inputs!$F$86:$I$86)+LOOKUP(ROUNDUP(SUM($J7:Q7)*Q7/Qtrs_Yr,0),Inputs!$G$73:$J$73,Inputs!$G$74:$J$74))/Qtrs_Yr))*Inputs!$F$101-IF(OR(P$7=0,SUM($J7:P7)*P7>Inputs!$F$77*Qtrs_Yr),0,(Inputs!$F$71-SUM($J7:P7,-1)*P7*Inputs!$F$71/Inputs!$F$77/Qtrs_Yr)*(LOOKUP(YEAR(Q$5),Inputs!$F$85:$I$85,Inputs!$F$86:$I$86)+LOOKUP(ROUNDUP(SUM($J7:Q7)*Q7/Qtrs_Yr,0),Inputs!$G$73:$J$73,Inputs!$G$74:$J$74))/Qtrs_Yr)-IF(OR(P$7=0,SUM($J7:P7)*P7>Inputs!$F$77*Qtrs_Yr),0,Inputs!$F$71/Inputs!$F$77/Qtrs_Yr) -> 4.1682946 | Q11: =(((IF(ROUNDUP(SUM($J$7:Q$7)*Q$7/Qtrs_Yr,0)=0,0,LOOKUP(ROUNDUP(SUM($J$7:Q$7)*Q$7/Qtrs_Yr,0),Inputs!$F$35:$I$35,Inputs!$F$36:$I$36))/Thousand/Qtrs_Yr)*IF(ROUNDUP(SUM($J$7:Q$7)*Q$7/Qtrs_Yr,0)=0,0,LOOKUP(ROUNDUP(SUM($J$7:Q$7)*Q$7/Qtrs_Yr,0),Inputs!$F$41:$I$41,Inputs!$F$42:$I$42))/Grams_Oz*Inputs!$F$45)*LOOKUP(YEAR(Q$5),Inputs!$F$49:$I$49,Inputs!$F$50:$I$50)/Thousand/LOOKUP(YEAR(Q$5),Inputs!$F$89:$I$89,Inputs!$F$90:$I$90)*(Q5-P5-Inputs!$F$97)/(Q5-P5)+((IF(ROUNDUP(SUM($I$7:P$7)*P$7/Qtrs_Yr,0)=0,0,LOOKUP(ROUNDUP(SUM($I$7:P$7)*P$7/Qtrs_Yr,0),Inputs!$F$35:$I$35,Inputs!$F$36:$I$36))/Thousand/Qtrs_Yr)*IF(ROUNDUP(SUM($I$7:P$7)*P$7/Qtrs_Yr,0)=0,0,LOOKUP(ROUNDUP(SUM($I$7:P$7)*P$7/Qtrs_Yr,0),Inputs!$F$41:$I$41,Inputs!$F$42:$I$42))/Grams_Oz*Inputs!$F$45)*LOOKUP(YEAR(P$5),Inputs!$F$49:$I$49,Inputs!$F$50:$I$50)/Thousand/LOOKUP(YEAR(P$5),Inputs!$F$89:$I$89,Inputs!$F$90:$I$90)*Inputs!$F$97/(P5-O5))-(((Inputs!$F$64*(IF(ROUNDUP(SUM($J$7:Q$7)*Q$7/Qtrs_Yr,0)=0,0,LOOKUP(ROUNDUP(SUM($J$7:Q$7)*Q$7/Qtrs_Yr,0),Inputs!$F$35:$I$35,Inputs!$F$36:$I$36))/Thousand/Qtrs_Yr+IF(ROUNDUP(SUM($J$7:Q$7)*Q$7/Qtrs_Yr,0)=0,0,LOOKUP(ROUNDUP(SUM($J$7:Q$7)*Q$7/Qtrs_Yr,0),Inputs!$F$35:$I$35,Inputs!$F$38:$I$38)*LOOKUP(ROUNDUP(SUM($J$7:Q$7)*Q$7/Qtrs_Yr,0),Inputs!$F$35:$I$35,Inputs!$F$36:$I$36))/Thousand/Qtrs_Yr)+Inputs!$F$65*(IF(ROUNDUP(SUM($J$7:Q$7)*Q$7/Qtrs_Yr,0)=0,0,LOOKUP(ROUNDUP(SUM($J$7:Q$7)*Q$7/Qtrs_Yr,0),Inputs!$F$35:$I$35,Inputs!$F$36:$I$36))/Thousand/Qtrs_Yr)+Inputs!$F$66*(IF(ROUNDUP(SUM($J$7:Q$7)*Q$7/Qtrs_Yr,0)=0,0,LOOKUP(ROUNDUP(SUM($J$7:Q$7)*Q$7/Qtrs_Yr,0),Inputs!$F$35:$I$35,Inputs!$F$38:$I$38)*LOOKUP(ROUNDUP(SUM($J$7:Q$7)*Q$7/Qtrs_Yr,0),Inputs!$F$35:$I$35,Inputs!$F$36:$I$36))/Thousand/Qtrs_Yr))/Thousand+SUM(Inputs!$F$54:$F$61)*Q$7/Qtrs_Yr)*(1+LOOKUP(YEAR(Q$5),Inputs!$F$93:$I$93,Inputs!$F$94:$I$94)/Qtrs_Yr)^(COUNT($J$7:Q7))*(Q5-P5-Inputs!$F$98)/(Q5-P5)+((Inputs!$F$64*(IF(ROUNDUP(SUM($I$7:P$7)*P$7/Qtrs_Yr,0)=0,0,LOOKUP(ROUNDUP(SUM($I$7:P$7)*P$7/Qtrs_Yr,0),Inputs!$F$35:$I$35,Inputs!$F$36:$I$36))/Thousand/Qtrs_Yr+IF(ROUNDUP(SUM($I$7:P$7)*P$7/Qtrs_Yr,0)=0,0,LOOKUP(ROUNDUP(SUM($I$7:P$7)*P$7/Qtrs_Yr,0),Inputs!$F$35:$I$35,Inputs!$F$38:$I$38)*LOOKUP(ROUNDUP(SUM($I$7:P$7)*P$7/Qtrs_Yr,0),Inputs!$F$35:$I$35,Inputs!$F$36:$I$36))/Thousand/Qtrs_Yr)+Inputs!$F$65*(IF(ROUNDUP(SUM($I$7:P$7)*P$7/Qtrs_Yr,0)=0,0,LOOKUP(ROUNDUP(SUM($I$7:P$7)*P$7/Qtrs_Yr,0),Inputs!$F$35:$I$35,Inputs!$F$36:$I$36))/Thousand/Qtrs_Yr)+Inputs!$F$66*(IF(ROUNDUP(SUM($I$7:P$7)*P$7/Qtrs_Yr,0)=0,0,LOOKUP(ROUNDUP(SUM($I$7:P$7)*P$7/Qtrs_Yr,0),Inputs!$F$35:$I$35,Inputs!$F$38:$I$38)*LOOKUP(ROUNDUP(SUM($I$7:P$7)*P$7/Qtrs_Yr,0),Inputs!$F$35:$I$35,Inputs!$F$36:$I$36))/Thousand/Qtrs_Yr))/Thousand+SUM(Inputs!$F$54:$F$61)*P$7/Qtrs_Yr)*(1+LOOKUP(YEAR(Q$5),Inputs!$F$93:$I$93,Inputs!$F$94:$I$94)/Qtrs_Yr)^(COUNT($I$7:P7))*Inputs!$F$98/(P5-O5))-(((IF(ROUNDUP(SUM($J$7:Q$7)*Q$7/Qtrs_Yr,0)=0,0,LOOKUP(ROUNDUP(SUM($J$7:Q$7)*Q$7/Qtrs_Yr,0),Inputs!$F$35:$I$35,Inputs!$F$36:$I$36))/Thousand/Qtrs_Yr)*IF(ROUNDUP(SUM($J$7:Q$7)*Q$7/Qtrs_Yr,0)=0,0,LOOKUP(ROUNDUP(SUM($J$7:Q$7)*Q$7/Qtrs_Yr,0),Inputs!$F$41:$I$41,Inputs!$F$42:$I$42))/Grams_Oz*Inputs!$F$45)*LOOKUP(YEAR(Q$5),Inputs!$F$49:$I$49,Inputs!$F$50:$I$50)/Thousand/LOOKUP(YEAR(Q$5),Inputs!$F$89:$I$89,Inputs!$F$90:$I$90)-((Inputs!$F$64*(IF(ROUNDUP(SUM($J$7:Q$7)*Q$7/Qtrs_Yr,0)=0,0,LOOKUP(ROUNDUP(SUM($J$7:Q$7)*Q$7/Qtrs_Yr,0),Inputs!$F$35:$I$35,Inputs!$F$36:$I$36))/Thousand/Qtrs_Yr+IF(ROUNDUP(SUM($J$7:Q$7)*Q$7/Qtrs_Yr,0)=0,0,LOOKUP(ROUNDUP(SUM($J$7:Q$7)*Q$7/Qtrs_Yr,0),Inputs!$F$35:$I$35,Inputs!$F$38:$I$38)*LOOKUP(ROUNDUP(SUM($J$7:Q$7)*Q$7/Qtrs_Yr,0),Inputs!$F$35:$I$35,Inputs!$F$36:$I$36))/Thousand/Qtrs_Yr)+Inputs!$F$65*(IF(ROUNDUP(SUM($J$7:Q$7)*Q$7/Qtrs_Yr,0)=0,0,LOOKUP(ROUNDUP(SUM($J$7:Q$7)*Q$7/Qtrs_Yr,0),Inputs!$F$35:$I$35,Inputs!$F$36:$I$36))/Thousand/Qtrs_Yr)+Inputs!$F$66*(IF(ROUNDUP(SUM($J$7:Q$7)*Q$7/Qtrs_Yr,0)=0,0,LOOKUP(ROUNDUP(SUM($J$7:Q$7)*Q$7/Qtrs_Yr,0),Inputs!$F$35:$I$35,Inputs!$F$38:$I$38)*LOOKUP(ROUNDUP(SUM($J$7:Q$7)*Q$7/Qtrs_Yr,0),Inputs!$F$35:$I$35,Inputs!$F$36:$I$36))/Thousand/Qtrs_Yr))/Thousand+SUM(Inputs!$F$54:$F$61)*Q$7/Qtrs_Yr)*(1+LOOKUP(YEAR(Q$5),Inputs!$F$93:$I$93,Inputs!$F$94:$I$94)/Qtrs_Yr)^(COUNT($J$7:Q7))-Inputs!$E$29*(1+Inputs!$E$31)*Q$7/Inputs!$E$16/Qtrs_Yr-IF(OR(Q$7=0,SUM($J7:Q7)*Q7>Inputs!$F$77*Qtrs_Yr),0,(Inputs!$F$71-SUM($J7:Q7,-1)*Q7*Inputs!$F$71/Inputs!$F$77/Qtrs_Yr)*(LOOKUP(YEAR(R$5),Inputs!$F$85:$I$85,Inputs!$F$86:$I$86)+LOOKUP(ROUNDUP(SUM($J7:R7)*R7/Qtrs_Yr,0),Inputs!$G$73:$J$73,Inputs!$G$74:$J$74))/Qtrs_Yr))*Inputs!$F$101-IF(OR(Q$7=0,SUM($J7:Q7)*Q7>Inputs!$F$77*Qtrs_Yr),0,(Inputs!$F$71-SUM($J7:Q7,-1)*Q7*Inputs!$F$71/Inputs!$F$77/Qtrs_Yr)*(LOOKUP(YEAR(R$5),Inputs!$F$85:$I$85,Inputs!$F$86:$I$86)+LOOKUP(ROUNDUP(SUM($J7:R7)*R7/Qtrs_Yr,0),Inputs!$G$73:$J$73,Inputs!$G$74:$J$74))/Qtrs_Yr)-IF(OR(Q$7=0,SUM($J7:Q7)*Q7>Inputs!$F$77*Qtrs_Yr),0,Inputs!$F$71/Inputs!$F$77/Qtrs_Yr) -> 4.1228065 | ... BI11: =(((IF(ROUNDUP(SUM($J$7:BI$7)*BI$7/Qtrs_Yr,0)=0,0,LOOKUP(ROUNDUP(SUM($J$7:BI$7)*BI$7/Qtrs_Yr,0),Inputs!$F$35:$I$35,Inputs!$F$36:$I$36))/Thousand/Qtrs_Yr)*IF(ROUNDUP(SUM($J$7:BI$7)*BI$7/Qtrs_Yr,0)=0,0,LOOKUP(ROUNDUP(SUM($J$7:BI$7)*BI$7/Qtrs_Yr,0),Inputs!$F$41:$I$41,Inputs!$F$42:$I$42))/Grams_Oz*Inputs!$F$45)*LOOKUP(YEAR(BI$5),Inputs!$F$49:$I$49,Inputs!$F$50:$I$50)/Thousand/LOOKUP(YEAR(BI$5),Inputs!$F$89:$I$89,Inputs!$F$90:$I$90)*(BI5-BH5-Inputs!$F$97)/(BI5-BH5)+((IF(ROUNDUP(SUM($I$7:BH$7)*BH$7/Qtrs_Yr,0)=0,0,LOOKUP(ROUNDUP(SUM($I$7:BH$7)*BH$7/Qtrs_Yr,0),Inputs!$F$35:$I$35,Inputs!$F$36:$I$36))/Thousand/Qtrs_Yr)*IF(ROUNDUP(SUM($I$7:BH$7)*BH$7/Qtrs_Yr,0)=0,0,LOOKUP(ROUNDUP(SUM($I$7:BH$7)*BH$7/Qtrs_Yr,0),Inputs!$F$41:$I$41,Inputs!$F$42:$I$42))/Grams_Oz*Inputs!$F$45)*LOOKUP(YEAR(BH$5),Inputs!$F$49:$I$49,Inputs!$F$50:$I$50)/Thousand/LOOKUP(YEAR(BH$5),Inputs!$F$89:$I$89,Inputs!$F$90:$I$90)*Inputs!$F$97/(BH5-BG5))-(((Inputs!$F$64*(IF(ROUNDUP(SUM($J$7:BI$7)*BI$7/Qtrs_Yr,0)=0,0,LOOKUP(ROUNDUP(SUM($J$7:BI$7)*BI$7/Qtrs_Yr,0),Inputs!$F$35:$I$35,Inputs!$F$36:$I$36))/Thousand/Qtrs_Yr+IF(ROUNDUP(SUM($J$7:BI$7)*BI$7/Qtrs_Yr,0)=0,0,LOOKUP(ROUNDUP(SUM($J$7:BI$7)*BI$7/Qtrs_Yr,0),Inputs!$F$35:$I$35,Inputs!$F$38:$I$38)*LOOKUP(ROUNDUP(SUM($J$7:BI$7)*BI$7/Qtrs_Yr,0),Inputs!$F$35:$I$35,Inputs!$F$36:$I$36))/Thousand/Qtrs_Yr)+Inputs!$F$65*(IF(ROUNDUP(SUM($J$7:BI$7)*BI$7/Qtrs_Yr,0)=0,0,LOOKUP(ROUNDUP(SUM($J$7:BI$7)*BI$7/Qtrs_Yr,0),Inputs!$F$35:$I$35,Inputs!$F$36:$I$36))/Thousand/Qtrs_Yr)+Inputs!$F$66*(IF(ROUNDUP(SUM($J$7:BI$7)*BI$7/Qtrs_Yr,0)=0,0,LOOKUP(ROUNDUP(SUM($J$7:BI$7)*BI$7/Qtrs_Yr,0),Inputs!$F$35:$I$35,Inputs!$F$38:$I$38)*LOOKUP(ROUNDUP(SUM($J$7:BI$7)*BI$7/Qtrs_Yr,0),Inputs!$F$35:$I$35,Inputs!$F$36:$I$36))/Thousand/Qtrs_Yr))/Thousand+SUM(Inputs!$F$54:$F$61)*BI$7/Qtrs_Yr)*(1+LOOKUP(YEAR(BI$5),Inputs!$F$93:$I$93,Inputs!$F$94:$I$94)/Qtrs_Yr)^(COUNT($J$7:BI7))*(BI5-BH5-Inputs!$F$98)/(BI5-BH5)+((Inputs!$F$64*(IF(ROUNDUP(SUM($I$7:BH$7)*BH$7/Qtrs_Yr,0)=0,0,LOOKUP(ROUNDUP(SUM($I$7:BH$7)*BH$7/Qtrs_Yr,0),Inputs!$F$35:$I$35,Inputs!$F$36:$I$36))/Thousand/Qtrs_Yr+IF(ROUNDUP(SUM($I$7:BH$7)*BH$7/Qtrs_Yr,0)=0,0,LOOKUP(ROUNDUP(SUM($I$7:BH$7)*BH$7/Qtrs_Yr,0),Inputs!$F$35:$I$35,Inputs!$F$38:$I$38)*LOOKUP(ROUNDUP(SUM($I$7:BH$7)*BH$7/Qtrs_Yr,0),Inputs!$F$35:$I$35,Inputs!$F$36:$I$36))/Thousand/Qtrs_Yr)+Inputs!$F$65*(IF(ROUNDUP(SUM($I$7:BH$7)*BH$7/Qtrs_Yr,0)=0,0,LOOKUP(ROUNDUP(SUM($I$7:BH$7)*BH$7/Qtrs_Yr,0),Inputs!$F$35:$I$35,Inputs!$F$36:$I$36))/Thousand/Qtrs_Yr)+Inputs!$F$66*(IF(ROUNDUP(SUM($I$7:BH$7)*BH$7/Qtrs_Yr,0)=0,0,LOOKUP(ROUNDUP(SUM($I$7:BH$7)*BH$7/Qtrs_Yr,0),Inputs!$F$35:$I$35,Inputs!$F$38:$I$38)*LOOKUP(ROUNDUP(SUM($I$7:BH$7)*BH$7/Qtrs_Yr,0),Inputs!$F$35:$I$35,Inputs!$F$36:$I$36))/Thousand/Qtrs_Yr))/Thousand+SUM(Inputs!$F$54:$F$61)*BH$7/Qtrs_Yr)*(1+LOOKUP(YEAR(BI$5),Inputs!$F$93:$I$93,Inputs!$F$94:$I$94)/Qtrs_Yr)^(COUNT($I$7:BH7))*Inputs!$F$98/(BH5-BG5))-(((IF(ROUNDUP(SUM($J$7:BI$7)*BI$7/Qtrs_Yr,0)=0,0,LOOKUP(ROUNDUP(SUM($J$7:BI$7)*BI$7/Qtrs_Yr,0),Inputs!$F$35:$I$35,Inputs!$F$36:$I$36))/Thousand/Qtrs_Yr)*IF(ROUNDUP(SUM($J$7:BI$7)*BI$7/Qtrs_Yr,0)=0,0,LOOKUP(ROUNDUP(SUM($J$7:BI$7)*BI$7/Qtrs_Yr,0),Inputs!$F$41:$I$41,Inputs!$F$42:$I$42))/Grams_Oz*Inputs!$F$45)*LOOKUP(YEAR(BI$5),Inputs!$F$49:$I$49,Inputs!$F$50:$I$50)/Thousand/LOOKUP(YEAR(BI$5),Inputs!$F$89:$I$89,Inputs!$F$90:$I$90)-((Inputs!$F$64*(IF(ROUNDUP(SUM($J$7:BI$7)*BI$7/Qtrs_Yr,0)=0,0,LOOKUP(ROUNDUP(SUM($J$7:BI$7)*BI$7/Qtrs_Yr,0),Inputs!$F$35:$I$35,Inputs!$F$36:$I$36))/Thousand/Qtrs_Yr+IF(ROUNDUP(SUM($J$7:BI$7)*BI$7/Qtrs_Yr,0)=0,0,LOOKUP(ROUNDUP(SUM($J$7:BI$7)*BI$7/Qtrs_Yr,0),Inputs!$F$35:$I$35,Inputs!$F$38:$I$38)*LOOKUP(ROUNDUP(SUM($J$7:BI$7)*BI$7/Qtrs_Yr,0),Inputs!$F$35:$I$35,Inputs!$F$36:$I$36))/Thousand/Qtrs_Yr)+Inputs!$F$65*(IF(ROUNDUP(SUM($J$7:BI$7)*BI$7/Qtrs_Yr,0)=0,0,LOOKUP(ROUNDUP(SUM($J$7:BI$7)*BI$7/Qtrs_Yr,0),Inputs!$F$35:$I$35,Inputs!$F$36:$I$36))/Thousand/Qtrs_Yr)+Inputs!$F$66*(IF(ROUNDUP(SUM($J$7:BI$7)*BI$7/Qtrs_Yr,0)=0,0,LOOKUP(ROUNDUP(SUM($J$7:BI$7)*BI$7/Qtrs_Yr,0),Inputs!$F$35:$I$35,Inputs!$F$38:$I$38)*LOOKUP(ROUNDUP(SUM($J$7:BI$7)*BI$7/Qtrs_Yr,0),Inputs!$F$35:$I$35,Inputs!$F$36:$I$36))/Thousand/Qtrs_Yr))/Thousand+SUM(Inputs!$F$54:$F$61)*BI$7/Qtrs_Yr)*(1+LOOKUP(YEAR(BI$5),Inputs!$F$93:$I$93,Inputs!$F$94:$I$94)/Qtrs_Yr)^(COUNT($J$7:BI7))-Inputs!$E$29*(1+Inputs!$E$31)*BI$7/Inputs!$E$16/Qtrs_Yr-IF(OR(BI$7=0,SUM($J7:BI7)*BI7>Inputs!$F$77*Qtrs_Yr),0,(Inputs!$F$71-SUM($J7:BI7,-1)*BI7*Inputs!$F$71/Inputs!$F$77/Qtrs_Yr)*(LOOKUP(YEAR(BJ$5),Inputs!$F$85:$I$85,Inputs!$F$86:$I$86)+LOOKUP(ROUNDUP(SUM($J7:BJ7)*BJ7/Qtrs_Yr,0),Inputs!$G$73:$J$73,Inputs!$G$74:$J$74))/Qtrs_Yr))*Inputs!$F$101-IF(OR(BI$7=0,SUM($J7:BI7)*BI7>Inputs!$F$77*Qtrs_Yr),0,(Inputs!$F$71-SUM($J7:BI7,-1)*BI7*Inputs!$F$71/Inputs!$F$77/Qtrs_Yr)*(LOOKUP(YEAR(BJ$5),Inputs!$F$85:$I$85,Inputs!$F$86:$I$86)+LOOKUP(ROUNDUP(SUM($J7:BJ7)*BJ7/Qtrs_Yr,0),Inputs!$G$73:$J$73,Inputs!$G$74:$J$74))/Qtrs_Yr)-IF(OR(BI$7=0,SUM($J7:BI7)*BI7>Inputs!$F$77*Qtrs_Yr),0,Inputs!$F$71/Inputs!$F$77/Qtrs_Yr) -> 0
C13: Debt | E13: Min DSCR
