Workbook

Sheet Cover
B3: BREWERY FINANCIAL MODEL
B5: SkyBrew & AllDark Brewing Company
B7: 10-Year Monthly Projection Model
B9: Model Version: | C9: 1.0
B10: Last Updated: | C10: 2025-12-16
B12: Contents:
B13: 1. Control - Scenario selection and global settings
B14: 2. Timeline - 120-month date spine
B15: 3. SKU_Matrix - Product portfolio (24 SKUs)
B16: 4. Assumptions - Volume, Pricing, Costs, Capex, WC, Finance
B17: 5. Calculations - Volume, Revenue, COGS, Capacity, etc.
B18: 6. Financial Statements - IS, CF, BS
B19: 7. KPIs - Key performance indicators
B20: 8. Checks - Model integrity checks

Sheet Control
B2: SCENARIO & GLOBAL CONTROL
B4: SCENARIO SELECTION
B5: Active Scenario (1=Base, 2=Upside, 3=Downside) | D5: 1
B7: GLOBAL SETTINGS
B8: Model Start Date | D8: 45658
B9: Projection Years | D9: 10
B10: Periods per Year | D10: 12
B11: Total Periods | D11: =D9*D10 -> 120
B13: CURRENCY & TAX
B14: Reporting Currency | D14: AUD
B15: AUD/NZD Exchange Rate | D15: 1.1
B16: Corporate Tax Rate | D16: 0.3
B18: INFLATION ASSUMPTIONS
B19: General Inflation (Annual) | D19: 0.025
B20: Wage Inflation (Annual) | D20: 0.03

Sheet Timeline
A1: TIMELINE
A3: Period | B3: Date | C3: Month | D3: Year | E3: Quarter | F3: FY | G3: Period Label
A4: 1 | B4: 45658 | C4: 1 | D4: 2025 | E4: Q1 | F4: FY2025 | G4: Jan-25
A5: 2 | B5: 45689 | C5: 2 | D5: 2025 | E5: Q1 | F5: FY2025 | G5: Feb-25
A6: 3 | B6: 45717 | C6: 3 | D6: 2025 | E6: Q1 | F6: FY2025 | G6: Mar-25
A7: 4 | B7: 45748 | C7: 4 | D7: 2025 | E7: Q2 | F7: FY2025 | G7: Apr-25
A8: 5 | B8: 45778 | C8: 5 | D8: 2025 | E8: Q2 | F8: FY2025 | G8: May-25
A9: 6 | B9: 45809 | C9: 6 | D9: 2025 | E9: Q2 | F9: FY2025 | G9: Jun-25
A10: 7 | B10: 45839 | C10: 7 | D10: 2025 | E10: Q3 | F10: FY2026 | G10: Jul-25
A11: 8 | B11: 45870 | C11: 8 | D11: 2025 | E11: Q3 | F11: FY2026 | G11: Aug-25
A12: 9 | B12: 45901 | C12: 9 | D12: 2025 | E12: Q3 | F12: FY2026 | G12: Sep-25
A13: 10 | B13: 45931 | C13: 10 | D13: 2025 | E13: Q4 | F13: FY2026 | G13: Oct-25
A14: 11 | B14: 45962 | C14: 11 | D14: 2025 | E14: Q4 | F14: FY2026 | G14: Nov-25
A15: 12 | B15: 45992 | C15: 12 | D15: 2025 | E15: Q4 | F15: FY2026 | G15: Dec-25
... A123: 120 | B123: 49279 | C123: 12 | D123: 2034 | E123: Q4 | F123: FY2035 | G123: Dec-34

Sheet SKU_Matrix
A1: SKU MATRIX
A3: SKU_ID | B3: Brand | C3: Format | D3: Pack_Size | E3: Units_Per_Pack | F3: ML_Per_Unit | G3: HL_Per_Pack | H3: ABV | I3: On_Trade | J3: Off_Trade | K3: Active
A4: SKU01 | B4: SkyBrew | C4: Bottle | D4: 330ml Single | E4: 1 | F4: 330 | G4: =E4*F4/100000 -> 0.0033 | H4: 0.05 | I4: 1 | J4: 1 | K4: 1
A5: SKU02 | B5: SkyBrew | C5: Bottle | D5: 330ml 6-pack | E5: 6 | F5: 330 | G5: =E5*F5/100000 -> 0.0198 | H5: 0.05 | I5: 1 | J5: 1 | K5: 1
A6: SKU03 | B6: SkyBrew | C6: Bottle | D6: 330ml 24-pack | E6: 24 | F6: 330 | G6: =E6*F6/100000 -> 0.0792 | H6: 0.05 | I6: 0 | J6: 1 | K6: 1
A7: SKU04 | B7: SkyBrew | C7: Bottle | D7: 500ml Single | E7: 1 | F7: 500 | G7: =E7*F7/100000 -> 0.005 | H7: 0.05 | I7: 1 | J7: 1 | K7: 1
A8: SKU05 | B8: SkyBrew | C8: Bottle | D8: 750ml Single | E8: 1 | F8: 750 | G8: =E8*F8/100000 -> 0.0075 | H8: 0.05 | I8: 1 | J8: 1 | K8: 1
A9: SKU06 | B9: SkyBrew | C9: Can | D9: 330ml Single | E9: 1 | F9: 330 | G9: =E9*F9/100000 -> 0.0033 | H9: 0.05 | I9: 1 | J9: 1 | K9: 1
A10: SKU07 | B10: SkyBrew | C10: Can | D10: 330ml 4-pack | E10: 4 | F10: 330 | G10: =E10*F10/100000 -> 0.0132 | H10: 0.05 | I10: 0 | J10: 1 | K10: 1
A11: SKU08 | B11: SkyBrew | C11: Can | D11: 330ml 6-pack | E11: 6 | F11: 330 | G11: =E11*F11/100000 -> 0.0198 | H11: 0.05 | I11: 1 | J11: 1 | K11: 1
A12: SKU09 | B12: SkyBrew | C12: Can | D12: 330ml 24-pack | E12: 24 | F12: 330 | G12: =E12*F12/100000 -> 0.0792 | H12: 0.05 | I12: 0 | J12: 1 | K12: 1
A13: SKU10 | B13: SkyBrew | C13: Can | D13: 500ml Single | E13: 1 | F13: 500 | G13: =E13*F13/100000 -> 0.005 | H13: 0.05 | I13: 1 | J13: 1 | K13: 1
A14: SKU11 | B14: SkyBrew | C14: Keg | D14: 20L | E14: 1 | F14: 20000 | G14: =E14*F14/100000 -> 0.2 | H14: 0.05 | I14: 1 | J14: 0 | K14: 1
A15: SKU12 | B15: SkyBrew | C15: Keg | D15: 50L | E15: 1 | F15: 50000 | G15: =E15*F15/100000 -> 0.5 | H15: 0.05 | I15: 1 | J15: 0 | K15: 1
... A27: SKU24 | B27: AllDark | C27: Keg | D27: 50L | E27: 1 | F27: 50000 | G27: =E27*F27/100000 -> 0.5 | H27: 0.06 | I27: 1 | J27: 0 | K27: 1

Sheet Assum_Volume
A1: VOLUME ASSUMPTIONS
A3: BASE ANNUAL VOLUMES (HL) - YEAR 1
A5: Total Base Volume (HL) | C5: 800000
A7: BRAND MIX
A8: SkyBrew % | C8: 0.7
A9: AllDark % | C9: =1-C8 -> 0.3
A11: MARKET MIX
A12: Australia % | C12: 0.7
A13: New Zealand % | C13: =1-C12 -> 0.3
A15: CHANNEL MIX
A16: On-Trade % | C16: 0.35
A17: Off-Trade % | C17: =1-C16 -> 0.65
A19: FORMAT MIX (within channel)
A20: On-Trade:
A21: Kegs % | C21: 0.7
A22: Bottles % | C22: 0.2
A23: Cans % | C23: =1-C21-C22 -> 0.1
A25: Off-Trade:
A26: Bottles % | C26: 0.45
A27: Cans % | C27: 0.55
A30: ANNUAL VOLUME GROWTH RATES
B31: Base | C31: Upside | D31: Downside
A32: Year 1 | B32: 0 | C32: 0 | D32: 0
A33: Year 2 | B33: 0.08 | C33: 0.1 | D33: 0.05
A34: Year 3 | B34: 0.08 | C34: 0.1 | D34: 0.05
A35: Year 4 | B35: 0.06 | C35: 0.08 | D35: 0.03
A36: Year 5 | B36: 0.06 | C36: 0.08 | D36: 0.03
A37: Year 6 | B37: 0.04 | C37: 0.06 | D37: 0.02
A38: Year 7 | B38: 0.04 | C38: 0.06 | D38: 0.02
A39: Year 8 | B39: 0.04 | C39: 0.06 | D39: 0.02
A40: Year 9 | B40: 0.04 | C40: 0.06 | D40: 0.02
A41: Year 10 | B41: 0.04 | C41: 0.06 | D41: 0.02
A44: MONTHLY SEASONALITY INDEX
A45: (Sum = 12.00)
A46: Jan | B46: 1.15
A47: Feb | B47: 1.1
A48: Mar | B48: 1
A49: Apr | B49: 0.9
A50: May | B50: 0.85
A51: Jun | B51: 0.8
...

Sheet Assum_Pricing
A1: PRICING ASSUMPTIONS
A3: GROSS PRICE PER HL (AUD)
A5: Brand | B5: Format | C5: On-Trade | D5: Off-Trade
A6: SkyBrew | B6: Bottle | C6: 850 | D6: 550
A7: SkyBrew | B7: Can | C7: 800 | D7: 520
A8: SkyBrew | B8: Keg | C8: 650 | D8: 0
A9: AllDark | B9: Bottle | C9: 950 | D9: 620
A10: AllDark | B10: Can | C10: 900 | D10: 580
A11: AllDark | B11: Keg | C11: 720 | D11: 0
A14: DISCOUNTS & REBATES
A15: On-Trade Discount % | C15: 0.08
A16: Off-Trade Retail Discount % | C16: 0.12
A17: Off-Trade Wholesale Discount % | C17: 0.18
A18: Blended Off-Trade Discount | C18: =(C16+C17)/2 -> 0.15
A21: EXCISE DUTY
A22: Australia - Rate per Litre of Alcohol (LAL) | C22: 55
A23: Australia - Keg Rebate % | C23: 0.3
A24: New Zealand - Rate per LAL (AUD equivalent) | C24: 32
A26: CALCULATED EXCISE PER HL:
A27: AU SkyBrew (5% ABV) - Standard | C27: =$C$22*0.05*100 -> 275
A28: AU SkyBrew (5% ABV) - Keg | C28: =$C$22*0.05*100*(1-$C$23) -> 192.5
A29: AU AllDark (6% ABV) - Standard | C29: =$C$22*0.06*100 -> 330
A30: AU AllDark (6% ABV) - Keg | C30: =$C$22*0.06*100*(1-$C$23) -> 231
A31: NZ SkyBrew (5% ABV) | C31: =$C$24*0.05*100 -> 160
A32: NZ AllDark (6% ABV) | C32: =$C$24*0.06*100 -> 192
A35: ANNUAL PRICE INCREASE
A36: Base Scenario | C36: 0.025
A37: Upside Scenario | C37: 0.035
A38: Downside Scenario | C38: 0.015

Sheet Assum_Costs
A1: COST ASSUMPTIONS
A3: COGS PER HL (AUD)
A5: RAW MATERIALS (per HL)
A6: Malt & Adjuncts | C6: 12
A7: Hops | C7: 5
A8: Yeast | C8: 1.5
A9: Water & Treatment | C9: 1.5
A10: Total Raw Materials | C10: =SUM(C6:C9) -> 20
A12: PACKAGING MATERIALS (per HL)
A13: Bottles (glass, labels, caps, cartons) | C13: 35
A14: Cans (aluminum, labels, cartons) | C14: 30
A15: Kegs (depreciation, cleaning, fittings) | C15: 8
A17: DIRECT MANUFACTURING (per HL)
A18: Direct Labour | C18: 12
A19: Utilities (power, gas, water) | C19: 6
A20: Manufacturing Overhead | C20: 8
A21: Quality Control | C21: 2
A22: Total Direct Manufacturing | C22: =SUM(C18:C21) -> 28
A24: TOTAL COGS SUMMARY (per HL)
A25: Bottle Product | C25: =C10+C13+C22 -> 83
A26: Can Product | C26: =C10+C14+C22 -> 78
A27: Keg Product | C27: =C10+C15+C22 -> 56
A30: LOGISTICS & DISTRIBUTION (per HL)
A31: Domestic Freight - Australia | C31: 22
A32: Domestic Freight - New Zealand | C32: 18
A33: Export Freight (AU to NZ) | C33: 35
A34: Warehousing | C34: 8
A35: Cold Chain Premium (Kegs) | C35: 10
A38: SG&A (% of Revenue)
A39: Sales Team | C39: 0.04
A40: Marketing | C40: 0.06
A41: Trade Marketing | C41: 0.03
A42: General & Admin | C42: 0.04
A43: Total SG&A % | C43: =SUM(C39:C42) -> 0.17
A46: ANNUAL COST INFLATION
A47: Base Scenario | C47: 0.025
A48: Upside Scenario | C48: 0.02
A49: Downside Scenario | C49: 0.035

Sheet Assum_Capex
A1: CAPEX & CAPACITY ASSUMPTIONS
A3: OPENING BALANCE SHEET (Year 0)
A5: Asset Class | B5: Gross Value | C5: Accum Depr | D5: Net Value | E5: Useful Life | F5: Annual Depr
A6: Land | B6: 5000000 | C6: 0 | D6: =B6-C6 -> 5000000 | E6: N/A | F6: 0
A7: Buildings | B7: 15000000 | C7: 3000000 | D7: =B7-C7 -> 12000000 | E7: 40 | F7: =B7/E7 -> 375000
A8: Brewing Equipment | B8: 20000000 | C8: 8000000 | D8: =B8-C8 -> 12000000 | E8: 15 | F8: =B8/E8 -> 1333333.3
A9: Packaging Lines | B9: 12000000 | C9: 4800000 | D9: =B9-C9 -> 7200000 | E9: 10 | F9: =B9/E9 -> 1200000
A10: Kegs & Returnable Packaging | B10: 5000000 | C10: 2500000 | D10: =B10-C10 -> 2500000 | E10: 10 | F10: =B10/E10 -> 500000
A11: Vehicles & Logistics | B11: 3000000 | C11: 1500000 | D11: =B11-C11 -> 1500000 | E11: 5 | F11: =B11/E11 -> 600000
A12: IT & Systems | B12: 2000000 | C12: 1200000 | D12: =B12-C12 -> 800000 | E12: 4 | F12: =B12/E12 -> 500000
A13: TOTAL | B13: =SUM(B6:B12) -> 62000000 | C13: =SUM(C6:C12) -> 21000000 | D13: =SUM(D6:D12) -> 41000000 | F13: =SUM(F6:F12) -> 4508333.3
A16: PRODUCTION CAPACITY
A17: Fermentation Capacity (HL/year) | C17: 1000000
A18: Bottle Line Capacity (HL/year) | C18: 500000
A19: Can Line Capacity (HL/year) | C19: 400000
A20: Keg Line Capacity (HL/year) | C20: 200000
A23: EXPANSION CAPEX (per 20% capacity addition)
A24: Fermentation Expansion | C24: 15000000
A25: Bottle Line Expansion | C25: 8000000
A26: Can Line Expansion | C26: 6000000
A27: Keg Line Expansion | C27: 3000000
A30: MAINTENANCE CAPEX
A31: Annual Maintenance Capex (% of Gross PP&E) | C31: 0.02
A34: EXPANSION TRIGGER
A35: Utilization Trigger for Expansion | C35: 0.85

Sheet Assum_WC
A1: WORKING CAPITAL ASSUMPTIONS
A3: INVENTORY DAYS
A4: Raw Materials (days of COGS) | C4: 30
A5: Work in Progress (days of COGS) | C5: 14
A6: Finished Goods (days of COGS) | C6: 21
A7: Total Inventory Days | C7: =SUM(C4:C6) -> 65
A10: RECEIVABLE DAYS
A11: On-Trade (days of revenue) | C11: 55
A12: Off-Trade (days of revenue) | C12: 38
A13: Blended Average | C13: =C11*Assum_Volume!C16+C12*Assum_Volume!C17 -> 43.95
A16: PAYABLE DAYS
A17: Trade Payables (days of COGS + Opex) | C17: 35
A20: OTHER WORKING CAPITAL
A21: Prepayments (days of Opex) | C21: 15
A22: Accruals (days of Opex) | C22: 20
A23: Returnable Packaging Deposits (AUD) | C23: 2500000
A26: OPENING WORKING CAPITAL
A27: Opening Inventory ($000s) | C27: 12000
A28: Opening Receivables ($000s) | C28: 33000
A29: Opening Payables ($000s) | C29: 19000
A30: Opening Prepayments ($000s) | C30: 5500
A31: Opening Accruals ($000s) | C31: 7400
A32: Opening Net Working Capital | C32: =C27+C28+C30-C29-C31 -> 24100

Sheet Assum_Finance
A1: FINANCING ASSUMPTIONS
A3: EXISTING DEBT
A4: Term Loan - Principal Outstanding | C4: 25000000
A5: Term Loan - Interest Rate | C5: 0.065
A6: Term Loan - Remaining Term (years) | C6: 7
A7: Term Loan - Annual Principal Payment | C7: =C4/C6 -> 3571428.6
A10: REVOLVING FACILITY
A11: Facility Limit | C11: 10000000
A12: Current Drawn Amount | C12: 0
A13: Interest Rate | C13: 0.075
A14: Commitment Fee (on undrawn) | C14: 0.005
A17: EQUITY
A18: Opening Share Capital | C18: 30000000
A19: Opening Retained Earnings | C19: 18100000
A22: DIVIDEND POLICY
A23: Target Payout Ratio (% of Net Income) | C23: 0.4
A24: Minimum Cash Balance Before Dividends | C24: 5000000
A27: CASH
A28: Opening Cash Balance | C28: 8000000
A29: Minimum Operating Cash | C29: 3000000

Sheet Calc_Volume
A1: VOLUME CALCULATIONS
A3: Period | B3: 1 | C3: 2 | D3: 3 | E3: 4 | F3: 5 | G3: 6 | H3: 7 | I3: 8 | J3: 9 | K3: 10 | L3: 11 | M3: 12 | N3: 13 | O3: 14 | P3: 15 | Q3: 16 | R3: 17 | S3: 18 | T3: 19 | U3: 20 | V3: 21 | W3: 22 | X3: 23 | Y3: 24 | Z3: 25 | AA3: 26 | AB3: 27 | AC3: 28 | AD3: 29 | AE3: 30 | AF3: 31 | AG3: 32 | AH3: 33 | AI3: 34 | AJ3: 35 | AK3: 36 | AL3: 37 | AM3: 38 | AN3: 39 | AO3: 40 | AP3: 41 | AQ3: 42 | AR3: 43 | AS3: 44 | AT3: 45 | AU3: 46 | AV3: 47 | AW3: 48 | AX3: 49 | AY3: 50 | AZ3: 51 | BA3: 52 | BB3: 53 | BC3: 54 | BD3: 55 | BE3: 56 | BF3: 57 | BG3: 58 | BH3: 59 | BI3: 60 | BJ3: 61 | BK3: 62 | BL3: 63 | BM3: 64 | BN3: 65 | BO3: 66 | BP3: 67 | BQ3: 68 | BR3: 69 | BS3: 70 | BT3: 71 | BU3: 72 | BV3: 73 | BW3: 74 | BX3: 75 | BY3: 76 | BZ3: 77 | CA3: 78 | CB3: 79 | CC3: 80 | CD3: 81 | CE3: 82 | CF3: 83 | CG3: 84 | CH3: 85 | CI3: 86 | CJ3: 87 | CK3: 88 | CL3: 89 | CM3: 90 | CN3: 91 | CO3: 92 | CP3: 93 | CQ3: 94 | CR3: 95 | CS3: 96 | CT3: 97 | CU3: 98 | CV3: 99 | CW3: 100 | CX3: 101 | CY3: 102 | CZ3: 103 | DA3: 104 | DB3: 105 | DC3: 106 | DD3: 107 | DE3: 108 | DF3: 109 | DG3: 110 | DH3: 111 | DI3: 112 | DJ3: 113 | DK3: 114 | DL3: 115 | DM3: 116 | DN3: 117 | DO3: 118 | DP3: 119 | DQ3: 120
A4: Date | B4: 45658 | C4: 45689 | D4: 45717 | E4: 45748 | F4: 45778 | G4: 45809 | H4: 45839 | I4: 45870 | J4: 45901 | K4: 45931 | L4: 45962 | M4: 45992 | N4: 46023 | O4: 46054 | P4: 46082 | Q4: 46113 | R4: 46143 | S4: 46174 | T4: 46204 | U4: 46235 | V4: 46266 | W4: 46296 | X4: 46327 | Y4: 46357 | Z4: 46388 | AA4: 46419 | AB4: 46447 | AC4: 46478 | AD4: 46508 | AE4: 46539 | AF4: 46569 | AG4: 46600 | AH4: 46631 | AI4: 46661 | AJ4: 46692 | AK4: 46722 | AL4: 46753 | AM4: 46784 | AN4: 46813 | AO4: 46844 | AP4: 46874 | AQ4: 46905 | AR4: 46935 | AS4: 46966 | AT4: 46997 | AU4: 47027 | AV4: 47058 | AW4: 47088 | AX4: 47119 | AY4: 47150 | AZ4: 47178 | BA4: 47209 | BB4: 47239 | BC4: 47270 | BD4: 47300 | BE4: 47331 | BF4: 47362 | BG4: 47392 | BH4: 47423 | BI4: 47453 | BJ4: 47484 | BK4: 47515 | BL4: 47543 | BM4: 47574 | BN4: 47604 | BO4: 47635 | BP4: 47665 | BQ4: 47696 | BR4: 47727 | BS4: 47757 | BT4: 47788 | BU4: 47818 | BV4: 47849 | BW4: 47880 | BX4: 47908 | BY4: 47939 | BZ4: 47969 | CA4: 48000 | CB4: 48030 | CC4: 48061 | CD4: 48092 | CE4: 48122 | CF4: 48153 | CG4: 48183 | CH4: 48214 | CI4: 48245 | CJ4: 48274 | CK4: 48305 | CL4: 48335 | CM4: 48366 | CN4: 48396 | CO4: 48427 | CP4: 48458 | CQ4: 48488 | CR4: 48519 | CS4: 48549 | CT4: 48580 | CU4: 48611 | CV4: 48639 | CW4: 48670 | CX4: 48700 | CY4: 48731 | CZ4: 48761 | DA4: 48792 | DB4: 48823 | DC4: 48853 | DD4: 48884 | DE4: 48914 | DF4: 48945 | DG4: 48976 | DH4: 49004 | DI4: 49035 | DJ4: 49065 | DK4: 49096 | DL4: 49126 | DM4: 49157 | DN4: 49188 | DO4: 49218 | DP4: 49249 | DQ4: 49279
A5: Year | B5: 1 | C5: 1 | D5: 1 | E5: 1 | F5: 1 | G5: 1 | H5: 1 | I5: 1 | J5: 1 | K5: 1 | L5: 1 | M5: 1 | N5: 2 | O5: 2 | P5: 2 | Q5: 2 | R5: 2 | S5: 2 | T5: 2 | U5: 2 | V5: 2 | W5: 2 | X5: 2 | Y5: 2 | Z5: 3 | AA5: 3 | AB5: 3 | AC5: 3 | AD5: 3 | AE5: 3 | AF5: 3 | AG5: 3 | AH5: 3 | AI5: 3 | AJ5: 3 | AK5: 3 | AL5: 4 | AM5: 4 | AN5: 4 | AO5: 4 | AP5: 4 | AQ5: 4 | AR5: 4 | AS5: 4 | AT5: 4 | AU5: 4 | AV5: 4 | AW5: 4 | AX5: 5 | AY5: 5 | AZ5: 5 | BA5: 5 | BB5: 5 | BC5: 5 | BD5: 5 | BE5: 5 | BF5: 5 | BG5: 5 | BH5: 5 | BI5: 5 | BJ5: 6 | BK5: 6 | BL5: 6 | BM5: 6 | BN5: 6 | BO5: 6 | BP5: 6 | BQ5: 6 | BR5: 6 | BS5: 6 | BT5: 6 | BU5: 6 | BV5: 7 | BW5: 7 | BX5: 7 | BY5: 7 | BZ5: 7 | CA5: 7 | CB5: 7 | CC5: 7 | CD5: 7 | CE5: 7 | CF5: 7 | CG5: 7 | CH5: 8 | CI5: 8 | CJ5: 8 | CK5: 8 | CL5: 8 | CM5: 8 | CN5: 8 | CO5: 8 | CP5: 8 | CQ5: 8 | CR5: 8 | CS5: 8 | CT5: 9 | CU5: 9 | CV5: 9 | CW5: 9 | CX5: 9 | CY5: 9 | CZ5: 9 | DA5: 9 | DB5: 9 | DC5: 9 | DD5: 9 | DE5: 9 | DF5: 10 | DG5: 10 | DH5: 10 | DI5: 10 | DJ5: 10 | DK5: 10 | DL5: 10 | DM5: 10 | DN5: 10 | DO5: 10 | DP5: 10 | DQ5: 10
A6: Month | B6: 1 | C6: 2 | D6: 3 | E6: 4 | F6: 5 | G6: 6 | H6: 7 | I6: 8 | J6: 9 | K6: 10 | L6: 11 | M6: 12 | N6: 1 | O6: 2 | P6: 3 | Q6: 4 | R6: 5 | S6: 6 | T6: 7 | U6: 8 | V6: 9 | W6: 10 | X6: 11 | Y6: 12 | Z6: 1 | AA6: 2 | AB6: 3 | AC6: 4 | AD6: 5 | AE6: 6 | AF6: 7 | AG6: 8 | AH6: 9 | AI6: 10 | AJ6: 11 | AK6: 12 | AL6: 1 | AM6: 2 | AN6: 3 | AO6: 4 | AP6: 5 | AQ6: 6 | AR6: 7 | AS6: 8 | AT6: 9 | AU6: 10 | AV6: 11 | AW6: 12 | AX6: 1 | AY6: 2 | AZ6: 3 | BA6: 4 | BB6: 5 | BC6: 6 | BD6: 7 | BE6: 8 | BF6: 9 | BG6: 10 | BH6: 11 | BI6: 12 | BJ6: 1 | BK6: 2 | BL6: 3 | BM6: 4 | BN6: 5 | BO6: 6 | BP6: 7 | BQ6: 8 | BR6: 9 | BS6: 10 | BT6: 11 | BU6: 12 | BV6: 1 | BW6: 2 | BX6: 3 | BY6: 4 | BZ6: 5 | CA6: 6 | CB6: 7 | CC6: 8 | CD6: 9 | CE6: 10 | CF6: 11 | CG6: 12 | CH6: 1 | CI6: 2 | CJ6: 3 | CK6: 4 | CL6: 5 | CM6: 6 | CN6: 7 | CO6: 8 | CP6: 9 | CQ6: 10 | CR6: 11 | CS6: 12 | CT6: 1 | CU6: 2 | CV6: 3 | CW6: 4 | CX6: 5 | CY6: 6 | CZ6: 7 | DA6: 8 | DB6: 9 | DC6: 10 | DD6: 11 | DE6: 12 | DF6: 1 | DG6: 2 | DH6: 3 | DI6: 4 | DJ6: 5 | DK6: 6 | DL6: 7 | DM6: 8 | DN6: 9 | DO6: 10 | DP6: 11 | DQ6: 12
A7: Seasonality Index | B7: =Assum_Volume!$B$46 -> 1.15 | C7: =Assum_Volume!$B$47 -> 1.1 | D7: =Assum_Volume!$B$48 -> 1 | E7: =Assum_Volume!$B$49 -> 0.9 | F7: =Assum_Volume!$B$50 -> 0.85 | G7: =Assum_Volume!$B$51 -> 0.8 | H7: =Assum_Volume!$B$52 -> 0.8 | I7: =Assum_Volume!$B$53 -> 0.85 | J7: =Assum_Volume!$B$54 -> 0.95 | K7: =Assum_Volume!$B$55 -> 1.05 | L7: =Assum_Volume!$B$56 -> 1.15 | M7: =Assum_Volume!$B$57 -> 1.4 | N7: =Assum_Volume!$B$46 -> 1.15 | O7: =Assum_Volume!$B$47 -> 1.1 | P7: =Assum_Volume!$B$48 -> 1 | Q7: =Assum_Volume!$B$49 -> 0.9 | R7: =Assum_Volume!$B$50 -> 0.85 | S7: =Assum_Volume!$B$51 -> 0.8 | T7: =Assum_Volume!$B$52 -> 0.8 | U7: =Assum_Volume!$B$53 -> 0.85 | V7: =Assum_Volume!$B$54 -> 0.95 | W7: =Assum_Volume!$B$55 -> 1.05 | X7: =Assum_Volume!$B$56 -> 1.15 | Y7: =Assum_Volume!$B$57 -> 1.4 | Z7: =Assum_Volume!$B$46 -> 1.15 | AA7: =Assum_Volume!$B$47 -> 1.1 | AB7: =Assum_Volume!$B$48 -> 1 | AC7: =Assum_Volume!$B$49 -> 0.9 | AD7: =Assum_Volume!$B$50 -> 0.85 | AE7: =Assum_Volume!$B$51 -> 0.8 | AF7: =Assum_Volume!$B$52 -> 0.8 | AG7: =Assum_Volume!$B$53 -> 0.85 | AH7: =Assum_Volume!$B$54 -> 0.95 | AI7: =Assum_Volume!$B$55 -> 1.05 | AJ7: =Assum_Volume!$B$56 -> 1.15 | AK7: =Assum_Volume!$B$57 -> 1.4 | AL7: =Assum_Volume!$B$46 -> 1.15 | AM7: =Assum_Volume!$B$47 -> 1.1 | AN7: =Assum_Volume!$B$48 -> 1 | AO7: =Assum_Volume!$B$49 -> 0.9 | AP7: =Assum_Volume!$B$50 -> 0.85 | AQ7: =Assum_Volume!$B$51 -> 0.8 | AR7: =Assum_Volume!$B$52 -> 0.8 | AS7: =Assum_Volume!$B$53 -> 0.85 | AT7: =Assum_Volume!$B$54 -> 0.95 | AU7: =Assum_Volume!$B$55 -> 1.05 | AV7: =Assum_Volume!$B$56 -> 1.15 | AW7: =Assum_Volume!$B$57 -> 1.4 | AX7: =Assum_Volume!$B$46 -> 1.15 | AY7: =Assum_Volume!$B$47 -> 1.1 | AZ7: =Assum_Volume!$B$48 -> 1 | BA7: =Assum_Volume!$B$49 -> 0.9 | BB7: =Assum_Volume!$B$50 -> 0.85 | BC7: =Assum_Volume!$B$51 -> 0.8 | BD7: =Assum_Volume!$B$52 -> 0.8 | BE7: =Assum_Volume!$B$53 -> 0.85 | BF7: =Assum_Volume!$B$54 -> 0.95 | BG7: =Assum_Volume!$B$55 -> 1.05 | BH7: =Assum_Volume!$B$56 -> 1.15 | BI7: =Assum_Volume!$B$57 -> 1.4 | BJ7: =Assum_Volume!$B$46 -> 1.15 | BK7: =Assum_Volume!$B$47 -> 1.1 | BL7: =Assum_Volume!$B$48 -> 1 | BM7: =Assum_Volume!$B$49 -> 0.9 | BN7: =Assum_Volume!$B$50 -> 0.85 | BO7: =Assum_Volume!$B$51 -> 0.8 | BP7: =Assum_Volume!$B$52 -> 0.8 | BQ7: =Assum_Volume!$B$53 -> 0.85 | BR7: =Assum_Volume!$B$54 -> 0.95 | BS7: =Assum_Volume!$B$55 -> 1.05 | BT7: =Assum_Volume!$B$56 -> 1.15 | BU7: =Assum_Volume!$B$57 -> 1.4 | BV7: =Assum_Volume!$B$46 -> 1.15 | BW7: =Assum_Volume!$B$47 -> 1.1 | BX7: =Assum_Volume!$B$48 -> 1 | BY7: =Assum_Volume!$B$49 -> 0.9 | BZ7: =Assum_Volume!$B$50 -> 0.85 | CA7: =Assum_Volume!$B$51 -> 0.8 | CB7: =Assum_Volume!$B$52 -> 0.8 | CC7: =Assum_Volume!$B$53 -> 0.85 | CD7: =Assum_Volume!$B$54 -> 0.95 | CE7: =Assum_Volume!$B$55 -> 1.05 | CF7: =Assum_Volume!$B$56 -> 1.15 | CG7: =Assum_Volume!$B$57 -> 1.4 | CH7: =Assum_Volume!$B$46 -> 1.15 | CI7: =Assum_Volume!$B$47 -> 1.1 | CJ7: =Assum_Volume!$B$48 -> 1 | CK7: =Assum_Volume!$B$49 -> 0.9 | CL7: =Assum_Volume!$B$50 -> 0.85 | CM7: =Assum_Volume!$B$51 -> 0.8 | CN7: =Assum_Volume!$B$52 -> 0.8 | CO7: =Assum_Volume!$B$53 -> 0.85 | CP7: =Assum_Volume!$B$54 -> 0.95 | CQ7: =Assum_Volume!$B$55 -> 1.05 | CR7: =Assum_Volume!$B$56 -> 1.15 | CS7: =Assum_Volume!$B$57 -> 1.4 | CT7: =Assum_Volume!$B$46 -> 1.15 | CU7: =Assum_Volume!$B$47 -> 1.1 | CV7: =Assum_Volume!$B$48 -> 1 | CW7: =Assum_Volume!$B$49 -> 0.9 | CX7: =Assum_Volume!$B$50 -> 0.85 | CY7: =Assum_Volume!$B$51 -> 0.8 | CZ7: =Assum_Volume!$B$52 -> 0.8 | DA7: =Assum_Volume!$B$53 -> 0.85 | DB7: =Assum_Volume!$B$54 -> 0.95 | DC7: =Assum_Volume!$B$55 -> 1.05 | DD7: =Assum_Volume!$B$56 -> 1.15 | DE7: =Assum_Volume!$B$57 -> 1.4 | DF7: =Assum_Volume!$B$46 -> 1.15 | DG7: =Assum_Volume!$B$47 -> 1.1 | DH7: =Assum_Volume!$B$48 -> 1 | DI7: =Assum_Volume!$B$49 -> 0.9 | DJ7: =Assum_Volume!$B$50 -> 0.85 | DK7: =Assum_Volume!$B$51 -> 0.8 | DL7: =Assum_Volume!$B$52 -> 0.8 | DM7: =Assum_Volume!$B$53 -> 0.85 | DN7: =Assum_Volume!$B$54 -> 0.95 | DO7: =Assum_Volume!$B$55 -> 1.05 | DP7: =Assum_Volume!$B$56 -> 1.15 | DQ7: =Assum_Volume!$B$57 -> 1.4
A9: CUMULATIVE GROWTH INDEX | B9: 1 | C9: =B9 -> 1 | D9: =C9 -> 1 | E9: =D9 -> 1 | F9: =E9 -> 1 | G9: =F9 -> 1 | H9: =G9 -> 1 | I9: =H9 -> 1 | J9: =I9 -> 1 | ... M9: =L9 -> 1 | N9: =M9*(1+INDEX(Assum_Volume!$B$32:$D$41,2,Control!$D$5)) -> 1.08 | O9: =N9 -> 1.08 | P9: =O9 -> 1.08 | Q9: =P9 -> 1.08 | R9: =Q9 -> 1.08 | S9: =R9 -> 1.08 | T9: =S9 -> 1.08 | U9: =T9 -> 1.08 | V9: =U9 -> 1.08 | ... Y9: =X9 -> 1.08 | Z9: =Y9*(1+INDEX(Assum_Volume!$B$32:$D$41,3,Control!$D$5)) -> 1.1664 | AA9: =Z9 -> 1.1664 | AB9: =AA9 -> 1.1664 | AC9: =AB9 -> 1.1664 | AD9: =AC9 -> 1.1664 | AE9: =AD9 -> 1.1664 | AF9: =AE9 -> 1.1664 | AG9: =AF9 -> 1.1664 | AH9: =AG9 -> 1.1664 | ... AK9: =AJ9 -> 1.1664 | AL9: =AK9*(1+INDEX(Assum_Volume!$B$32:$D$41,4,Control!$D$5)) -> 1.236384 | AM9: =AL9 -> 1.236384 | AN9: =AM9 -> 1.236384 | AO9: =AN9 -> 1.236384 | AP9: =AO9 -> 1.236384 | AQ9: =AP9 -> 1.236384 | AR9: =AQ9 -> 1.236384 | AS9: =AR9 -> 1.236384 | AT9: =AS9 -> 1.236384 | ... AW9: =AV9 -> 1.236384 | AX9: =AW9*(1+INDEX(Assum_Volume!$B$32:$D$41,5,Control!$D$5)) -> 1.310567 | AY9: =AX9 -> 1.310567 | AZ9: =AY9 -> 1.310567 | BA9: =AZ9 -> 1.310567 | BB9: =BA9 -> 1.310567 | BC9: =BB9 -> 1.310567 | BD9: =BC9 -> 1.310567 | BE9: =BD9 -> 1.310567 | BF9: =BE9 -> 1.310567 | ... BI9: =BH9 -> 1.310567 | BJ9: =BI9*(1+INDEX(Assum_Volume!$B$32:$D$41,6,Control!$D$5)) -> 1.3629897 | BK9: =BJ9 -> 1.3629897 | BL9: =BK9 -> 1.3629897 | BM9: =BL9 -> 1.3629897 | BN9: =BM9 -> 1.3629897 | BO9: =BN9 -> 1.3629897 | BP9: =BO9 -> 1.3629897 | BQ9: =BP9 -> 1.3629897 | BR9: =BQ9 -> 1.3629897 | ... BU9: =BT9 -> 1.3629897 | BV9: =BU9*(1+INDEX(Assum_Volume!$B$32:$D$41,7,Control!$D$5)) -> 1.4175093 | BW9: =BV9 -> 1.4175093 | BX9: =BW9 -> 1.4175093 | BY9: =BX9 -> 1.4175093 | BZ9: =BY9 -> 1.4175093 | CA9: =BZ9 -> 1.4175093 | CB9: =CA9 -> 1.4175093 | CC9: =CB9 -> 1.4175093 | CD9: =CC9 -> 1.4175093 | ... CG9: =CF9 -> 1.4175093 | CH9: =CG9*(1+INDEX(Assum_Volume!$B$32:$D$41,8,Control!$D$5)) -> 1.4742097 | CI9: =CH9 -> 1.4742097 | CJ9: =CI9 -> 1.4742097 | CK9: =CJ9 -> 1.4742097 | CL9: =CK9 -> 1.4742097 | CM9: =CL9 -> 1.4742097 | CN9: =CM9 -> 1.4742097 | CO9: =CN9 -> 1.4742097 | CP9: =CO9 -> 1.4742097 | ... CS9: =CR9 -> 1.4742097 | CT9: =CS9*(1+INDEX(Assum_Volume!$B$32:$D$41,9,Control!$D$5)) -> 1.5331781 | CU9: =CT9 -> 1.5331781 | CV9: =CU9 -> 1.5331781 | CW9: =CV9 -> 1.5331781 | CX9: =CW9 -> 1.5331781 | CY9: =CX9 -> 1.5331781 | CZ9: =CY9 -> 1.5331781 | DA9: =CZ9 -> 1.5331781 | DB9: =DA9 -> 1.5331781 | ... DE9: =DD9 -> 1.5331781 | DF9: =DE9*(1+INDEX(Assum_Volume!$B$32:$D$41,10,Control!$D$5)) -> 1.5945052 | DG9: =DF9 -> 1.5945052 | DH9: =DG9 -> 1.5945052 | DI9: =DH9 -> 1.5945052 | DJ9: =DI9 -> 1.5945052 | DK9: =DJ9 -> 1.5945052 | DL9: =DK9 -> 1.5945052 | DM9: =DL9 -> 1.5945052 | DN9: =DM9 -> 1.5945052 | ... DQ9: =DP9 -> 1.5945052
A11: TOTAL VOLUME (HL)
A12: SkyBrew | B12: =Assum_Volume!$C$5*Assum_Volume!$C$8/12*B7*B9 -> 53666.667 | C12: =Assum_Volume!$C$5*Assum_Volume!$C$8/12*C7*C9 -> 51333.333 | D12: =Assum_Volume!$C$5*Assum_Volume!$C$8/12*D7*D9 -> 46666.667 | E12: =Assum_Volume!$C$5*Assum_Volume!$C$8/12*E7*E9 -> 42000 | F12: =Assum_Volume!$C$5*Assum_Volume!$C$8/12*F7*F9 -> 39666.667 | G12: =Assum_Volume!$C$5*Assum_Volume!$C$8/12*G7*G9 -> 37333.333 | H12: =Assum_Volume!$C$5*Assum_Volume!$C$8/12*H7*H9 -> 37333.333 | I12: =Assum_Volume!$C$5*Assum_Volume!$C$8/12*I7*I9 -> 39666.667 | ... DQ12: =Assum_Volume!$C$5*Assum_Volume!$C$8/12*DQ7*DQ9 -> 104174.34
A13: AllDark | B13: =Assum_Volume!$C$5*Assum_Volume!$C$9/12*B7*B9 -> 23000 | C13: =Assum_Volume!$C$5*Assum_Volume!$C$9/12*C7*C9 -> 22000 | D13: =Assum_Volume!$C$5*Assum_Volume!$C$9/12*D7*D9 -> 20000 | E13: =Assum_Volume!$C$5*Assum_Volume!$C$9/12*E7*E9 -> 18000 | F13: =Assum_Volume!$C$5*Assum_Volume!$C$9/12*F7*F9 -> 17000 | G13: =Assum_Volume!$C$5*Assum_Volume!$C$9/12*G7*G9 -> 16000 | H13: =Assum_Volume!$C$5*Assum_Volume!$C$9/12*H7*H9 -> 16000 | I13: =Assum_Volume!$C$5*Assum_Volume!$C$9/12*I7*I9 -> 17000 | ... DQ13: =Assum_Volume!$C$5*Assum_Volume!$C$9/12*DQ7*DQ9 -> 44646.145
A14: Total | B14: =B12+B13 -> 76666.667 | C14: =C12+C13 -> 73333.333 | D14: =D12+D13 -> 66666.667 | E14: =E12+E13 -> 60000 | F14: =F12+F13 -> 56666.667 | G14: =G12+G13 -> 53333.333 | H14: =H12+H13 -> 53333.333 | I14: =I12+I13 -> 56666.667 | ... DQ14: =DQ12+DQ13 -> 148820.48
A16: BY MARKET (HL)
A17: Australia | B17: =B14*Assum_Volume!$C$12 -> 53666.667 | C17: =C14*Assum_Volume!$C$12 -> 51333.333 | D17: =D14*Assum_Volume!$C$12 -> 46666.667 | E17: =E14*Assum_Volume!$C$12 -> 42000 | F17: =F14*Assum_Volume!$C$12 -> 39666.667 | G17: =G14*Assum_Volume!$C$12 -> 37333.333 | H17: =H14*Assum_Volume!$C$12 -> 37333.333 | I17: =I14*Assum_Volume!$C$12 -> 39666.667 | ... DQ17: =DQ14*Assum_Volume!$C$12 -> 104174.34
A18: New Zealand | B18: =B14*Assum_Volume!$C$13 -> 23000 | C18: =C14*Assum_Volume!$C$13 -> 22000 | D18: =D14*Assum_Volume!$C$13 -> 20000 | E18: =E14*Assum_Volume!$C$13 -> 18000 | F18: =F14*Assum_Volume!$C$13 -> 17000 | G18: =G14*Assum_Volume!$C$13 -> 16000 | H18: =H14*Assum_Volume!$C$13 -> 16000 | I18: =I14*Assum_Volume!$C$13 -> 17000 | ... DQ18: =DQ14*Assum_Volume!$C$13 -> 44646.145
A20: BY CHANNEL (HL)
A21: On-Trade | B21: =B14*Assum_Volume!$C$16 -> 26833.333 | C21: =C14*Assum_Volume!$C$16 -> 25666.667 | D21: =D14*Assum_Volume!$C$16 -> 23333.333 | E21: =E14*Assum_Volume!$C$16 -> 21000 | F21: =F14*Assum_Volume!$C$16 -> 19833.333 | G21: =G14*Assum_Volume!$C$16 -> 18666.667 | H21: =H14*Assum_Volume!$C$16 -> 18666.667 | I21: =I14*Assum_Volume!$C$16 -> 19833.333 | ... DQ21: =DQ14*Assum_Volume!$C$16 -> 52087.17
A22: Off-Trade | B22: =B14*Assum_Volume!$C$17 -> 49833.333 | C22: =C14*Assum_Volume!$C$17 -> 47666.667 | D22: =D14*Assum_Volume!$C$17 -> 43333.333 | E22: =E14*Assum_Volume!$C$17 -> 39000 | F22: =F14*Assum_Volume!$C$17 -> 36833.333 | G22: =G14*Assum_Volume!$C$17 -> 34666.667 | H22: =H14*Assum_Volume!$C$17 -> 34666.667 | I22: =I14*Assum_Volume!$C$17 -> 36833.333 | ... DQ22: =DQ14*Assum_Volume!$C$17 -> 96733.315
A24: BY FORMAT (HL)
A25: Bottles | B25: =B21*Assum_Volume!$C$22+B22*Assum_Volume!$C$26 -> 27791.667 | C25: =C21*Assum_Volume!$C$22+C22*Assum_Volume!$C$26 -> 26583.333 | D25: =D21*Assum_Volume!$C$22+D22*Assum_Volume!$C$26 -> 24166.667 | E25: =E21*Assum_Volume!$C$22+E22*Assum_Volume!$C$26 -> 21750 | F25: =F21*Assum_Volume!$C$22+F22*Assum_Volume!$C$26 -> 20541.667 | G25: =G21*Assum_Volume!$C$22+G22*Assum_Volume!$C$26 -> 19333.333 | H25: =H21*Assum_Volume!$C$22+H22*Assum_Volume!$C$26 -> 19333.333 | I25: =I21*Assum_Volume!$C$22+I22*Assum_Volume!$C$26 -> 20541.667 | ... DQ25: =DQ21*Assum_Volume!$C$22+DQ22*Assum_Volume!$C$26 -> 53947.426
A26: Cans | B26: =B21*Assum_Volume!$C$23+B22*Assum_Volume!$C$27 -> 30091.667 | C26: =C21*Assum_Volume!$C$23+C22*Assum_Volume!$C$27 -> 28783.333 | D26: =D21*Assum_Volume!$C$23+D22*Assum_Volume!$C$27 -> 26166.667 | E26: =E21*Assum_Volume!$C$23+E22*Assum_Volume!$C$27 -> 23550 | F26: =F21*Assum_Volume!$C$23+F22*Assum_Volume!$C$27 -> 22241.667 | G26: =G21*Assum_Volume!$C$23+G22*Assum_Volume!$C$27 -> 20933.333 | H26: =H21*Assum_Volume!$C$23+H22*Assum_Volume!$C$27 -> 20933.333 | I26: =I21*Assum_Volume!$C$23+I22*Assum_Volume!$C$27 -> 22241.667 | ... DQ26: =DQ21*Assum_Volume!$C$23+DQ22*Assum_Volume!$C$27 -> 58412.04
A27: Kegs | B27: =B21*Assum_Volume!$C$21 -> 18783.333 | C27: =C21*Assum_Volume!$C$21 -> 17966.667 | D27: =D21*Assum_Volume!$C$21 -> 16333.333 | E27: =E21*Assum_Volume!$C$21 -> 14700 | F27: =F21*Assum_Volume!$C$21 -> 13883.333 | G27: =G21*Assum_Volume!$C$21 -> 13066.667 | H27: =H21*Assum_Volume!$C$21 -> 13066.667 | I27: =I21*Assum_Volume!$C$21 -> 13883.333 | ... DQ27: =DQ21*Assum_Volume!$C$21 -> 36461.019

Sheet Calc_Revenue
A1: REVENUE CALCULATIONS
A3: Period | B3: =Calc_Volume!B3 -> 1 | C3: =Calc_Volume!C3 -> 2 | D3: =Calc_Volume!D3 -> 3 | E3: =Calc_Volume!E3 -> 4 | F3: =Calc_Volume!F3 -> 5 | G3: =Calc_Volume!G3 -> 6 | H3: =Calc_Volume!H3 -> 7 | I3: =Calc_Volume!I3 -> 8 | ... DQ3: =Calc_Volume!DQ3 -> 120
A4: Date | B4: =Calc_Volume!B4 -> 45658 | C4: =Calc_Volume!C4 -> 45689 | D4: =Calc_Volume!D4 -> 45717 | E4: =Calc_Volume!E4 -> 45748 | F4: =Calc_Volume!F4 -> 45778 | G4: =Calc_Volume!G4 -> 45809 | H4: =Calc_Volume!H4 -> 45839 | I4: =Calc_Volume!I4 -> 45870 | ... DQ4: =Calc_Volume!DQ4 -> 49279
A5: Price Index (cumulative) | B5: 1 | C5: =B5 -> 1 | D5: =C5 -> 1 | E5: =D5 -> 1 | F5: =E5 -> 1 | G5: =F5 -> 1 | H5: =G5 -> 1 | I5: =H5 -> 1 | J5: =I5 -> 1 | ... M5: =L5 -> 1 | N5: =M5*(1+INDEX(Assum_Pricing!$C$36:$C$38,Control!$D$5,1)) -> 1.025 | O5: =N5 -> 1.025 | P5: =O5 -> 1.025 | Q5: =P5 -> 1.025 | R5: =Q5 -> 1.025 | S5: =R5 -> 1.025 | T5: =S5 -> 1.025 | U5: =T5 -> 1.025 | V5: =U5 -> 1.025 | ... Y5: =X5 -> 1.025 | Z5: =Y5*(1+INDEX(Assum_Pricing!$C$36:$C$38,Control!$D$5,1)) -> 1.050625 | AA5: =Z5 -> 1.050625 | AB5: =AA5 -> 1.050625 | AC5: =AB5 -> 1.050625 | AD5: =AC5 -> 1.050625 | AE5: =AD5 -> 1.050625 | AF5: =AE5 -> 1.050625 | AG5: =AF5 -> 1.050625 | AH5: =AG5 -> 1.050625 | ... AK5: =AJ5 -> 1.050625 | AL5: =AK5*(1+INDEX(Assum_Pricing!$C$36:$C$38,Control!$D$5,1)) -> 1.0768906 | AM5: =AL5 -> 1.0768906 | AN5: =AM5 -> 1.0768906 | AO5: =AN5 -> 1.0768906 | AP5: =AO5 -> 1.0768906 | AQ5: =AP5 -> 1.0768906 | AR5: =AQ5 -> 1.0768906 | AS5: =AR5 -> 1.0768906 | AT5: =AS5 -> 1.0768906 | ... AW5: =AV5 -> 1.0768906 | AX5: =AW5*(1+INDEX(Assum_Pricing!$C$36:$C$38,Control!$D$5,1)) -> 1.1038129 | AY5: =AX5 -> 1.1038129 | AZ5: =AY5 -> 1.1038129 | BA5: =AZ5 -> 1.1038129 | BB5: =BA5 -> 1.1038129 | BC5: =BB5 -> 1.1038129 | BD5: =BC5 -> 1.1038129 | BE5: =BD5 -> 1.1038129 | BF5: =BE5 -> 1.1038129 | ... BI5: =BH5 -> 1.1038129 | BJ5: =BI5*(1+INDEX(Assum_Pricing!$C$36:$C$38,Control!$D$5,1)) -> 1.1314082 | BK5: =BJ5 -> 1.1314082 | BL5: =BK5 -> 1.1314082 | BM5: =BL5 -> 1.1314082 | BN5: =BM5 -> 1.1314082 | BO5: =BN5 -> 1.1314082 | BP5: =BO5 -> 1.1314082 | BQ5: =BP5 -> 1.1314082 | BR5: =BQ5 -> 1.1314082 | ... BU5: =BT5 -> 1.1314082 | BV5: =BU5*(1+INDEX(Assum_Pricing!$C$36:$C$38,Control!$D$5,1)) -> 1.1596934 | BW5: =BV5 -> 1.1596934 | BX5: =BW5 -> 1.1596934 | BY5: =BX5 -> 1.1596934 | BZ5: =BY5 -> 1.1596934 | CA5: =BZ5 -> 1.1596934 | CB5: =CA5 -> 1.1596934 | CC5: =CB5 -> 1.1596934 | CD5: =CC5 -> 1.1596934 | ... CG5: =CF5 -> 1.1596934 | CH5: =CG5*(1+INDEX(Assum_Pricing!$C$36:$C$38,Control!$D$5,1)) -> 1.1886858 | CI5: =CH5 -> 1.1886858 | CJ5: =CI5 -> 1.1886858 | CK5: =CJ5 -> 1.1886858 | CL5: =CK5 -> 1.1886858 | CM5: =CL5 -> 1.1886858 | CN5: =CM5 -> 1.1886858 | CO5: =CN5 -> 1.1886858 | CP5: =CO5 -> 1.1886858 | ... CS5: =CR5 -> 1.1886858 | CT5: =CS5*(1+INDEX(Assum_Pricing!$C$36:$C$38,Control!$D$5,1)) -> 1.2184029 | CU5: =CT5 -> 1.2184029 | CV5: =CU5 -> 1.2184029 | CW5: =CV5 -> 1.2184029 | CX5: =CW5 -> 1.2184029 | CY5: =CX5 -> 1.2184029 | CZ5: =CY5 -> 1.2184029 | DA5: =CZ5 -> 1.2184029 | DB5: =DA5 -> 1.2184029 | ... DE5: =DD5 -> 1.2184029 | DF5: =DE5*(1+INDEX(Assum_Pricing!$C$36:$C$38,Control!$D$5,1)) -> 1.248863 | DG5: =DF5 -> 1.248863 | DH5: =DG5 -> 1.248863 | DI5: =DH5 -> 1.248863 | DJ5: =DI5 -> 1.248863 | DK5: =DJ5 -> 1.248863 | DL5: =DK5 -> 1.248863 | DM5: =DL5 -> 1.248863 | DN5: =DM5 -> 1.248863 | ... DQ5: =DP5 -> 1.248863
A7: GROSS REVENUE ($000s)
A8: SkyBrew On-Trade | B8: =(Calc_Volume!B12*Assum_Volume!$C$16)*(Assum_Pricing!$C$6*Assum_Volume!$C$22+Assum_Pricing!$C$7*Assum_Volume!$C$23+Assum_Pricing!$C$8*Assum_Volume!$C$21)*B5/1000 -> 13242.25 | C8: =(Calc_Volume!C12*Assum_Volume!$C$16)*(Assum_Pricing!$C$6*Assum_Volume!$C$22+Assum_Pricing!$C$7*Assum_Volume!$C$23+Assum_Pricing!$C$8*Assum_Volume!$C$21)*C5/1000 -> 12666.5 | D8: =(Calc_Volume!D12*Assum_Volume!$C$16)*(Assum_Pricing!$C$6*Assum_Volume!$C$22+Assum_Pricing!$C$7*Assum_Volume!$C$23+Assum_Pricing!$C$8*Assum_Volume!$C$21)*D5/1000 -> 11515 | E8: =(Calc_Volume!E12*Assum_Volume!$C$16)*(Assum_Pricing!$C$6*Assum_Volume!$C$22+Assum_Pricing!$C$7*Assum_Volume!$C$23+Assum_Pricing!$C$8*Assum_Volume!$C$21)*E5/1000 -> 10363.5 | F8: =(Calc_Volume!F12*Assum_Volume!$C$16)*(Assum_Pricing!$C$6*Assum_Volume!$C$22+Assum_Pricing!$C$7*Assum_Volume!$C$23+Assum_Pricing!$C$8*Assum_Volume!$C$21)*F5/1000 -> 9787.75 | G8: =(Calc_Volume!G12*Assum_Volume!$C$16)*(Assum_Pricing!$C$6*Assum_Volume!$C$22+Assum_Pricing!$C$7*Assum_Volume!$C$23+Assum_Pricing!$C$8*Assum_Volume!$C$21)*G5/1000 -> 9212 | H8: =(Calc_Volume!H12*Assum_Volume!$C$16)*(Assum_Pricing!$C$6*Assum_Volume!$C$22+Assum_Pricing!$C$7*Assum_Volume!$C$23+Assum_Pricing!$C$8*Assum_Volume!$C$21)*H5/1000 -> 9212 | I8: =(Calc_Volume!I12*Assum_Volume!$C$16)*(Assum_Pricing!$C$6*Assum_Volume!$C$22+Assum_Pricing!$C$7*Assum_Volume!$C$23+Assum_Pricing!$C$8*Assum_Volume!$C$21)*I5/1000 -> 9787.75 | ... DQ8: =(Calc_Volume!DQ12*Assum_Volume!$C$16)*(Assum_Pricing!$C$6*Assum_Volume!$C$22+Assum_Pricing!$C$7*Assum_Volume!$C$23+Assum_Pricing!$C$8*Assum_Volume!$C$21)*DQ5/1000 -> 32102.045
A9: SkyBrew Off-Trade | B9: =(Calc_Volume!B12*Assum_Volume!$C$17)*(Assum_Pricing!$D$6*Assum_Volume!$C$26+Assum_Pricing!$D$7*Assum_Volume!$C$27)*B5/1000 -> 18610.258 | C9: =(Calc_Volume!C12*Assum_Volume!$C$17)*(Assum_Pricing!$D$6*Assum_Volume!$C$26+Assum_Pricing!$D$7*Assum_Volume!$C$27)*C5/1000 -> 17801.117 | D9: =(Calc_Volume!D12*Assum_Volume!$C$17)*(Assum_Pricing!$D$6*Assum_Volume!$C$26+Assum_Pricing!$D$7*Assum_Volume!$C$27)*D5/1000 -> 16182.833 | E9: =(Calc_Volume!E12*Assum_Volume!$C$17)*(Assum_Pricing!$D$6*Assum_Volume!$C$26+Assum_Pricing!$D$7*Assum_Volume!$C$27)*E5/1000 -> 14564.55 | F9: =(Calc_Volume!F12*Assum_Volume!$C$17)*(Assum_Pricing!$D$6*Assum_Volume!$C$26+Assum_Pricing!$D$7*Assum_Volume!$C$27)*F5/1000 -> 13755.408 | G9: =(Calc_Volume!G12*Assum_Volume!$C$17)*(Assum_Pricing!$D$6*Assum_Volume!$C$26+Assum_Pricing!$D$7*Assum_Volume!$C$27)*G5/1000 -> 12946.267 | H9: =(Calc_Volume!H12*Assum_Volume!$C$17)*(Assum_Pricing!$D$6*Assum_Volume!$C$26+Assum_Pricing!$D$7*Assum_Volume!$C$27)*H5/1000 -> 12946.267 | I9: =(Calc_Volume!I12*Assum_Volume!$C$17)*(Assum_Pricing!$D$6*Assum_Volume!$C$26+Assum_Pricing!$D$7*Assum_Volume!$C$27)*I5/1000 -> 13755.408 | ... DQ9: =(Calc_Volume!DQ12*Assum_Volume!$C$17)*(Assum_Pricing!$D$6*Assum_Volume!$C$26+Assum_Pricing!$D$7*Assum_Volume!$C$27)*DQ5/1000 -> 45115.245
A10: AllDark On-Trade | B10: =(Calc_Volume!B13*Assum_Volume!$C$16)*(Assum_Pricing!$C$9*Assum_Volume!$C$22+Assum_Pricing!$C$10*Assum_Volume!$C$23+Assum_Pricing!$C$11*Assum_Volume!$C$21)*B5/1000 -> 6311.2 | C10: =(Calc_Volume!C13*Assum_Volume!$C$16)*(Assum_Pricing!$C$9*Assum_Volume!$C$22+Assum_Pricing!$C$10*Assum_Volume!$C$23+Assum_Pricing!$C$11*Assum_Volume!$C$21)*C5/1000 -> 6036.8 | D10: =(Calc_Volume!D13*Assum_Volume!$C$16)*(Assum_Pricing!$C$9*Assum_Volume!$C$22+Assum_Pricing!$C$10*Assum_Volume!$C$23+Assum_Pricing!$C$11*Assum_Volume!$C$21)*D5/1000 -> 5488 | E10: =(Calc_Volume!E13*Assum_Volume!$C$16)*(Assum_Pricing!$C$9*Assum_Volume!$C$22+Assum_Pricing!$C$10*Assum_Volume!$C$23+Assum_Pricing!$C$11*Assum_Volume!$C$21)*E5/1000 -> 4939.2 | F10: =(Calc_Volume!F13*Assum_Volume!$C$16)*(Assum_Pricing!$C$9*Assum_Volume!$C$22+Assum_Pricing!$C$10*Assum_Volume!$C$23+Assum_Pricing!$C$11*Assum_Volume!$C$21)*F5/1000 -> 4664.8 | G10: =(Calc_Volume!G13*Assum_Volume!$C$16)*(Assum_Pricing!$C$9*Assum_Volume!$C$22+Assum_Pricing!$C$10*Assum_Volume!$C$23+Assum_Pricing!$C$11*Assum_Volume!$C$21)*G5/1000 -> 4390.4 | H10: =(Calc_Volume!H13*Assum_Volume!$C$16)*(Assum_Pricing!$C$9*Assum_Volume!$C$22+Assum_Pricing!$C$10*Assum_Volume!$C$23+Assum_Pricing!$C$11*Assum_Volume!$C$21)*H5/1000 -> 4390.4 | I10: =(Calc_Volume!I13*Assum_Volume!$C$16)*(Assum_Pricing!$C$9*Assum_Volume!$C$22+Assum_Pricing!$C$10*Assum_Volume!$C$23+Assum_Pricing!$C$11*Assum_Volume!$C$21)*I5/1000 -> 4664.8 | ... DQ10: =(Calc_Volume!DQ13*Assum_Volume!$C$16)*(Assum_Pricing!$C$9*Assum_Volume!$C$22+Assum_Pricing!$C$10*Assum_Volume!$C$23+Assum_Pricing!$C$11*Assum_Volume!$C$21)*DQ5/1000 -> 15299.698
A11: AllDark Off-Trade | B11: =(Calc_Volume!B13*Assum_Volume!$C$17)*(Assum_Pricing!$D$9*Assum_Volume!$C$26+Assum_Pricing!$D$10*Assum_Volume!$C$27)*B5/1000 -> 8940.1 | C11: =(Calc_Volume!C13*Assum_Volume!$C$17)*(Assum_Pricing!$D$9*Assum_Volume!$C$26+Assum_Pricing!$D$10*Assum_Volume!$C$27)*C5/1000 -> 8551.4 | D11: =(Calc_Volume!D13*Assum_Volume!$C$17)*(Assum_Pricing!$D$9*Assum_Volume!$C$26+Assum_Pricing!$D$10*Assum_Volume!$C$27)*D5/1000 -> 7774 | E11: =(Calc_Volume!E13*Assum_Volume!$C$17)*(Assum_Pricing!$D$9*Assum_Volume!$C$26+Assum_Pricing!$D$10*Assum_Volume!$C$27)*E5/1000 -> 6996.6 | F11: =(Calc_Volume!F13*Assum_Volume!$C$17)*(Assum_Pricing!$D$9*Assum_Volume!$C$26+Assum_Pricing!$D$10*Assum_Volume!$C$27)*F5/1000 -> 6607.9 | G11: =(Calc_Volume!G13*Assum_Volume!$C$17)*(Assum_Pricing!$D$9*Assum_Volume!$C$26+Assum_Pricing!$D$10*Assum_Volume!$C$27)*G5/1000 -> 6219.2 | H11: =(Calc_Volume!H13*Assum_Volume!$C$17)*(Assum_Pricing!$D$9*Assum_Volume!$C$26+Assum_Pricing!$D$10*Assum_Volume!$C$27)*H5/1000 -> 6219.2 | I11: =(Calc_Volume!I13*Assum_Volume!$C$17)*(Assum_Pricing!$D$9*Assum_Volume!$C$26+Assum_Pricing!$D$10*Assum_Volume!$C$27)*I5/1000 -> 6607.9 | ... DQ11: =(Calc_Volume!DQ13*Assum_Volume!$C$17)*(Assum_Pricing!$D$9*Assum_Volume!$C$26+Assum_Pricing!$D$10*Assum_Volume!$C$27)*DQ5/1000 -> 21672.714
A12: Total Gross Revenue | B12: =SUM(B8:B11) -> 47103.808 | C12: =SUM(C8:C11) -> 45055.817 | D12: =SUM(D8:D11) -> 40959.833 | E12: =SUM(E8:E11) -> 36863.85 | F12: =SUM(F8:F11) -> 34815.858 | G12: =SUM(G8:G11) -> 32767.867 | H12: =SUM(H8:H11) -> 32767.867 | I12: =SUM(I8:I11) -> 34815.858 | ... DQ12: =SUM(DQ8:DQ11) -> 114189.7
A14: DISCOUNTS ($000s)
A15: On-Trade Discounts | B15: =(B8+B10)*Assum_Pricing!$C$15 -> 1564.276 | C15: =(C8+C10)*Assum_Pricing!$C$15 -> 1496.264 | D15: =(D8+D10)*Assum_Pricing!$C$15 -> 1360.24 | E15: =(E8+E10)*Assum_Pricing!$C$15 -> 1224.216 | F15: =(F8+F10)*Assum_Pricing!$C$15 -> 1156.204 | G15: =(G8+G10)*Assum_Pricing!$C$15 -> 1088.192 | H15: =(H8+H10)*Assum_Pricing!$C$15 -> 1088.192 | I15: =(I8+I10)*Assum_Pricing!$C$15 -> 1156.204 | ... DQ15: =(DQ8+DQ10)*Assum_Pricing!$C$15 -> 3792.1395
A16: Off-Trade Discounts | B16: =(B9+B11)*Assum_Pricing!$C$18 -> 4132.5538 | C16: =(C9+C11)*Assum_Pricing!$C$18 -> 3952.8775 | D16: =(D9+D11)*Assum_Pricing!$C$18 -> 3593.525 | E16: =(E9+E11)*Assum_Pricing!$C$18 -> 3234.1725 | F16: =(F9+F11)*Assum_Pricing!$C$18 -> 3054.4963 | G16: =(G9+G11)*Assum_Pricing!$C$18 -> 2874.82 | H16: =(H9+H11)*Assum_Pricing!$C$18 -> 2874.82 | I16: =(I9+I11)*Assum_Pricing!$C$18 -> 3054.4963 | ... DQ16: =(DQ9+DQ11)*Assum_Pricing!$C$18 -> 10018.194
A17: Total Discounts | B17: =B15+B16 -> 5696.8297 | C17: =C15+C16 -> 5449.1415 | D17: =D15+D16 -> 4953.765 | E17: =E15+E16 -> 4458.3885 | F17: =F15+F16 -> 4210.7002 | G17: =G15+G16 -> 3963.012 | H17: =H15+H16 -> 3963.012 | I17: =I15+I16 -> 4210.7002 | ... DQ17: =DQ15+DQ16 -> 13810.333
A19: EXCISE DUTY ($000s)
A20: Australia Excise | B20: =Calc_Volume!B17*((Assum_Volume!$C$8*(1-Assum_Volume!$C$16*Assum_Volume!$C$21)*Assum_Pricing!$C$27+Assum_Volume!$C$8*Assum_Volume!$C$16*Assum_Volume!$C$21*Assum_Pricing!$C$28)+(Assum_Volume!$C$9*(1-Assum_Volume!$C$16*Assum_Volume!$C$21)*Assum_Pricing!$C$29+Assum_Volume!$C$9*Assum_Volume!$C$16*Assum_Volume!$C$21*Assum_Pricing!$C$30))/1000 -> 14494.012 | C20: =Calc_Volume!C17*((Assum_Volume!$C$8*(1-Assum_Volume!$C$16*Assum_Volume!$C$21)*Assum_Pricing!$C$27+Assum_Volume!$C$8*Assum_Volume!$C$16*Assum_Volume!$C$21*Assum_Pricing!$C$28)+(Assum_Volume!$C$9*(1-Assum_Volume!$C$16*Assum_Volume!$C$21)*Assum_Pricing!$C$29+Assum_Volume!$C$9*Assum_Volume!$C$16*Assum_Volume!$C$21*Assum_Pricing!$C$30))/1000 -> 13863.837 | D20: =Calc_Volume!D17*((Assum_Volume!$C$8*(1-Assum_Volume!$C$16*Assum_Volume!$C$21)*Assum_Pricing!$C$27+Assum_Volume!$C$8*Assum_Volume!$C$16*Assum_Volume!$C$21*Assum_Pricing!$C$28)+(Assum_Volume!$C$9*(1-Assum_Volume!$C$16*Assum_Volume!$C$21)*Assum_Pricing!$C$29+Assum_Volume!$C$9*Assum_Volume!$C$16*Assum_Volume!$C$21*Assum_Pricing!$C$30))/1000 -> 12603.488 | E20: =Calc_Volume!E17*((Assum_Volume!$C$8*(1-Assum_Volume!$C$16*Assum_Volume!$C$21)*Assum_Pricing!$C$27+Assum_Volume!$C$8*Assum_Volume!$C$16*Assum_Volume!$C$21*Assum_Pricing!$C$28)+(Assum_Volume!$C$9*(1-Assum_Volume!$C$16*Assum_Volume!$C$21)*Assum_Pricing!$C$29+Assum_Volume!$C$9*Assum_Volume!$C$16*Assum_Volume!$C$21*Assum_Pricing!$C$30))/1000 -> 11343.139 | F20: =Calc_Volume!F17*((Assum_Volume!$C$8*(1-Assum_Volume!$C$16*Assum_Volume!$C$21)*Assum_Pricing!$C$27+Assum_Volume!$C$8*Assum_Volume!$C$16*Assum_Volume!$C$21*Assum_Pricing!$C$28)+(Assum_Volume!$C$9*(1-Assum_Volume!$C$16*Assum_Volume!$C$21)*Assum_Pricing!$C$29+Assum_Volume!$C$9*Assum_Volume!$C$16*Assum_Volume!$C$21*Assum_Pricing!$C$30))/1000 -> 10712.965 | G20: =Calc_Volume!G17*((Assum_Volume!$C$8*(1-Assum_Volume!$C$16*Assum_Volume!$C$21)*Assum_Pricing!$C$27+Assum_Volume!$C$8*Assum_Volume!$C$16*Assum_Volume!$C$21*Assum_Pricing!$C$28)+(Assum_Volume!$C$9*(1-Assum_Volume!$C$16*Assum_Volume!$C$21)*Assum_Pricing!$C$29+Assum_Volume!$C$9*Assum_Volume!$C$16*Assum_Volume!$C$21*Assum_Pricing!$C$30))/1000 -> 10082.791 | H20: =Calc_Volume!H17*((Assum_Volume!$C$8*(1-Assum_Volume!$C$16*Assum_Volume!$C$21)*Assum_Pricing!$C$27+Assum_Volume!$C$8*Assum_Volume!$C$16*Assum_Volume!$C$21*Assum_Pricing!$C$28)+(Assum_Volume!$C$9*(1-Assum_Volume!$C$16*Assum_Volume!$C$21)*Assum_Pricing!$C$29+Assum_Volume!$C$9*Assum_Volume!$C$16*Assum_Volume!$C$21*Assum_Pricing!$C$30))/1000 -> 10082.791 | I20: =Calc_Volume!I17*((Assum_Volume!$C$8*(1-Assum_Volume!$C$16*Assum_Volume!$C$21)*Assum_Pricing!$C$27+Assum_Volume!$C$8*Assum_Volume!$C$16*Assum_Volume!$C$21*Assum_Pricing!$C$28)+(Assum_Volume!$C$9*(1-Assum_Volume!$C$16*Assum_Volume!$C$21)*Assum_Pricing!$C$29+Assum_Volume!$C$9*Assum_Volume!$C$16*Assum_Volume!$C$21*Assum_Pricing!$C$30))/1000 -> 10712.965 | ... DQ20: =Calc_Volume!DQ17*((Assum_Volume!$C$8*(1-Assum_Volume!$C$16*Assum_Volume!$C$21)*Assum_Pricing!$C$27+Assum_Volume!$C$8*Assum_Volume!$C$16*Assum_Volume!$C$21*Assum_Pricing!$C$28)+(Assum_Volume!$C$9*(1-Assum_Volume!$C$16*Assum_Volume!$C$21)*Assum_Pricing!$C$29+Assum_Volume!$C$9*Assum_Volume!$C$16*Assum_Volume!$C$21*Assum_Pricing!$C$30))/1000 -> 28134.859
A21: New Zealand Excise | B21: =Calc_Volume!B18*(Assum_Volume!$C$8*Assum_Pricing!$C$31+Assum_Volume!$C$9*Assum_Pricing!$C$32)/1000 -> 3900.8 | C21: =Calc_Volume!C18*(Assum_Volume!$C$8*Assum_Pricing!$C$31+Assum_Volume!$C$9*Assum_Pricing!$C$32)/1000 -> 3731.2 | D21: =Calc_Volume!D18*(Assum_Volume!$C$8*Assum_Pricing!$C$31+Assum_Volume!$C$9*Assum_Pricing!$C$32)/1000 -> 3392 | E21: =Calc_Volume!E18*(Assum_Volume!$C$8*Assum_Pricing!$C$31+Assum_Volume!$C$9*Assum_Pricing!$C$32)/1000 -> 3052.8 | F21: =Calc_Volume!F18*(Assum_Volume!$C$8*Assum_Pricing!$C$31+Assum_Volume!$C$9*Assum_Pricing!$C$32)/1000 -> 2883.2 | G21: =Calc_Volume!G18*(Assum_Volume!$C$8*Assum_Pricing!$C$31+Assum_Volume!$C$9*Assum_Pricing!$C$32)/1000 -> 2713.6 | H21: =Calc_Volume!H18*(Assum_Volume!$C$8*Assum_Pricing!$C$31+Assum_Volume!$C$9*Assum_Pricing!$C$32)/1000 -> 2713.6 | I21: =Calc_Volume!I18*(Assum_Volume!$C$8*Assum_Pricing!$C$31+Assum_Volume!$C$9*Assum_Pricing!$C$32)/1000 -> 2883.2 | ... DQ21: =Calc_Volume!DQ18*(Assum_Volume!$C$8*Assum_Pricing!$C$31+Assum_Volume!$C$9*Assum_Pricing!$C$32)/1000 -> 7571.9863
A22: Total Excise | B22: =B20+B21 -> 18394.812 | C22: =C20+C21 -> 17595.037 | D22: =D20+D21 -> 15995.488 | E22: =E20+E21 -> 14395.94 | F22: =F20+F21 -> 13596.165 | G22: =G20+G21 -> 12796.391 | H22: =H20+H21 -> 12796.391 | I22: =I20+I21 -> 13596.165 | ... DQ22: =DQ20+DQ21 -> 35706.845
A24: NET REVENUE ($000s)
A25: Net Revenue | B25: =B12-B17-B22 -> 23012.167 | C25: =C12-C17-C22 -> 22011.638 | D25: =D12-D17-D22 -> 20010.58 | E25: =E12-E17-E22 -> 18009.522 | F25: =F12-F17-F22 -> 17008.993 | G25: =G12-G17-G22 -> 16008.464 | H25: =H12-H17-H22 -> 16008.464 | I25: =I12-I17-I22 -> 17008.993 | ... DQ25: =DQ12-DQ17-DQ22 -> 64672.525
A27: KEY METRICS
A28: Gross Revenue per HL | B28: =IF(Calc_Volume!B14>0,B12*1000/Calc_Volume!B14,0) -> 614.3975 | C28: =IF(Calc_Volume!C14>0,C12*1000/Calc_Volume!C14,0) -> 614.3975 | D28: =IF(Calc_Volume!D14>0,D12*1000/Calc_Volume!D14,0) -> 614.3975 | E28: =IF(Calc_Volume!E14>0,E12*1000/Calc_Volume!E14,0) -> 614.3975 | F28: =IF(Calc_Volume!F14>0,F12*1000/Calc_Volume!F14,0) -> 614.3975 | G28: =IF(Calc_Volume!G14>0,G12*1000/Calc_Volume!G14,0) -> 614.3975 | H28: =IF(Calc_Volume!H14>0,H12*1000/Calc_Volume!H14,0) -> 614.3975 | I28: =IF(Calc_Volume!I14>0,I12*1000/Calc_Volume!I14,0) -> 614.3975 | ... DQ28: =IF(Calc_Volume!DQ14>0,DQ12*1000/Calc_Volume!DQ14,0) -> 767.29829
A29: Net Revenue per HL | B29: =IF(Calc_Volume!B14>0,B25*1000/Calc_Volume!B14,0) -> 300.1587 | C29: =IF(Calc_Volume!C14>0,C25*1000/Calc_Volume!C14,0) -> 300.1587 | D29: =IF(Calc_Volume!D14>0,D25*1000/Calc_Volume!D14,0) -> 300.1587 | E29: =IF(Calc_Volume!E14>0,E25*1000/Calc_Volume!E14,0) -> 300.1587 | F29: =IF(Calc_Volume!F14>0,F25*1000/Calc_Volume!F14,0) -> 300.1587 | G29: =IF(Calc_Volume!G14>0,G25*1000/Calc_Volume!G14,0) -> 300.1587 | H29: =IF(Calc_Volume!H14>0,H25*1000/Calc_Volume!H14,0) -> 300.1587 | I29: =IF(Calc_Volume!I14>0,I25*1000/Calc_Volume!I14,0) -> 300.1587 | ... DQ29: =IF(Calc_Volume!DQ14>0,DQ25*1000/Calc_Volume!DQ14,0) -> 434.56736
A30: Excise per HL | B30: =IF(Calc_Volume!B14>0,B22*1000/Calc_Volume!B14,0) -> 239.93232 | C30: =IF(Calc_Volume!C14>0,C22*1000/Calc_Volume!C14,0) -> 239.93232 | D30: =IF(Calc_Volume!D14>0,D22*1000/Calc_Volume!D14,0) -> 239.93232 | E30: =IF(Calc_Volume!E14>0,E22*1000/Calc_Volume!E14,0) -> 239.93232 | F30: =IF(Calc_Volume!F14>0,F22*1000/Calc_Volume!F14,0) -> 239.93232 | G30: =IF(Calc_Volume!G14>0,G22*1000/Calc_Volume!G14,0) -> 239.93233 | H30: =IF(Calc_Volume!H14>0,H22*1000/Calc_Volume!H14,0) -> 239.93233 | I30: =IF(Calc_Volume!I14>0,I22*1000/Calc_Volume!I14,0) -> 239.93232 | ... DQ30: =IF(Calc_Volume!DQ14>0,DQ22*1000/Calc_Volume!DQ14,0) -> 239.93233

Sheet Calc_COGS
A1: COST OF GOODS SOLD
A3: Period | B3: =Calc_Volume!B3 -> 1 | C3: =Calc_Volume!C3 -> 2 | D3: =Calc_Volume!D3 -> 3 | E3: =Calc_Volume!E3 -> 4 | F3: =Calc_Volume!F3 -> 5 | G3: =Calc_Volume!G3 -> 6 | H3: =Calc_Volume!H3 -> 7 | I3: =Calc_Volume!I3 -> 8 | ... DQ3: =Calc_Volume!DQ3 -> 120
A4: Date | B4: =Calc_Volume!B4 -> 45658 | C4: =Calc_Volume!C4 -> 45689 | D4: =Calc_Volume!D4 -> 45717 | E4: =Calc_Volume!E4 -> 45748 | F4: =Calc_Volume!F4 -> 45778 | G4: =Calc_Volume!G4 -> 45809 | H4: =Calc_Volume!H4 -> 45839 | I4: =Calc_Volume!I4 -> 45870 | ... DQ4: =Calc_Volume!DQ4 -> 49279
A5: Cost Index (cumulative) | B5: 1 | C5: =B5 -> 1 | D5: =C5 -> 1 | E5: =D5 -> 1 | F5: =E5 -> 1 | G5: =F5 -> 1 | H5: =G5 -> 1 | I5: =H5 -> 1 | J5: =I5 -> 1 | ... M5: =L5 -> 1 | N5: =M5*(1+INDEX(Assum_Costs!$C$47:$C$49,Control!$D$5,1)) -> 1.025 | O5: =N5 -> 1.025 | P5: =O5 -> 1.025 | Q5: =P5 -> 1.025 | R5: =Q5 -> 1.025 | S5: =R5 -> 1.025 | T5: =S5 -> 1.025 | U5: =T5 -> 1.025 | V5: =U5 -> 1.025 | ... Y5: =X5 -> 1.025 | Z5: =Y5*(1+INDEX(Assum_Costs!$C$47:$C$49,Control!$D$5,1)) -> 1.050625 | AA5: =Z5 -> 1.050625 | AB5: =AA5 -> 1.050625 | AC5: =AB5 -> 1.050625 | AD5: =AC5 -> 1.050625 | AE5: =AD5 -> 1.050625 | AF5: =AE5 -> 1.050625 | AG5: =AF5 -> 1.050625 | AH5: =AG5 -> 1.050625 | ... AK5: =AJ5 -> 1.050625 | AL5: =AK5*(1+INDEX(Assum_Costs!$C$47:$C$49,Control!$D$5,1)) -> 1.0768906 | AM5: =AL5 -> 1.0768906 | AN5: =AM5 -> 1.0768906 | AO5: =AN5 -> 1.0768906 | AP5: =AO5 -> 1.0768906 | AQ5: =AP5 -> 1.0768906 | AR5: =AQ5 -> 1.0768906 | AS5: =AR5 -> 1.0768906 | AT5: =AS5 -> 1.0768906 | ... AW5: =AV5 -> 1.0768906 | AX5: =AW5*(1+INDEX(Assum_Costs!$C$47:$C$49,Control!$D$5,1)) -> 1.1038129 | AY5: =AX5 -> 1.1038129 | AZ5: =AY5 -> 1.1038129 | BA5: =AZ5 -> 1.1038129 | BB5: =BA5 -> 1.1038129 | BC5: =BB5 -> 1.1038129 | BD5: =BC5 -> 1.1038129 | BE5: =BD5 -> 1.1038129 | BF5: =BE5 -> 1.1038129 | ... BI5: =BH5 -> 1.1038129 | BJ5: =BI5*(1+INDEX(Assum_Costs!$C$47:$C$49,Control!$D$5,1)) -> 1.1314082 | BK5: =BJ5 -> 1.1314082 | BL5: =BK5 -> 1.1314082 | BM5: =BL5 -> 1.1314082 | BN5: =BM5 -> 1.1314082 | BO5: =BN5 -> 1.1314082 | BP5: =BO5 -> 1.1314082 | BQ5: =BP5 -> 1.1314082 | BR5: =BQ5 -> 1.1314082 | ... BU5: =BT5 -> 1.1314082 | BV5: =BU5*(1+INDEX(Assum_Costs!$C$47:$C$49,Control!$D$5,1)) -> 1.1596934 | BW5: =BV5 -> 1.1596934 | BX5: =BW5 -> 1.1596934 | BY5: =BX5 -> 1.1596934 | BZ5: =BY5 -> 1.1596934 | CA5: =BZ5 -> 1.1596934 | CB5: =CA5 -> 1.1596934 | CC5: =CB5 -> 1.1596934 | CD5: =CC5 -> 1.1596934 | ... CG5: =CF5 -> 1.1596934 | CH5: =CG5*(1+INDEX(Assum_Costs!$C$47:$C$49,Control!$D$5,1)) -> 1.1886858 | CI5: =CH5 -> 1.1886858 | CJ5: =CI5 -> 1.1886858 | CK5: =CJ5 -> 1.1886858 | CL5: =CK5 -> 1.1886858 | CM5: =CL5 -> 1.1886858 | CN5: =CM5 -> 1.1886858 | CO5: =CN5 -> 1.1886858 | CP5: =CO5 -> 1.1886858 | ... CS5: =CR5 -> 1.1886858 | CT5: =CS5*(1+INDEX(Assum_Costs!$C$47:$C$49,Control!$D$5,1)) -> 1.2184029 | CU5: =CT5 -> 1.2184029 | CV5: =CU5 -> 1.2184029 | CW5: =CV5 -> 1.2184029 | CX5: =CW5 -> 1.2184029 | CY5: =CX5 -> 1.2184029 | CZ5: =CY5 -> 1.2184029 | DA5: =CZ5 -> 1.2184029 | DB5: =DA5 -> 1.2184029 | ... DE5: =DD5 -> 1.2184029 | DF5: =DE5*(1+INDEX(Assum_Costs!$C$47:$C$49,Control!$D$5,1)) -> 1.248863 | DG5: =DF5 -> 1.248863 | DH5: =DG5 -> 1.248863 | DI5: =DH5 -> 1.248863 | DJ5: =DI5 -> 1.248863 | DK5: =DJ5 -> 1.248863 | DL5: =DK5 -> 1.248863 | DM5: =DL5 -> 1.248863 | DN5: =DM5 -> 1.248863 | ... DQ5: =DP5 -> 1.248863
A7: RAW MATERIALS ($000s)
A8: Malt & Adjuncts | B8: =Calc_Volume!B14*Assum_Costs!$C$6*B5/1000 -> 920 | C8: =Calc_Volume!C14*Assum_Costs!$C$6*C5/1000 -> 880 | D8: =Calc_Volume!D14*Assum_Costs!$C$6*D5/1000 -> 800 | E8: =Calc_Volume!E14*Assum_Costs!$C$6*E5/1000 -> 720 | F8: =Calc_Volume!F14*Assum_Costs!$C$6*F5/1000 -> 680 | G8: =Calc_Volume!G14*Assum_Costs!$C$6*G5/1000 -> 640 | H8: =Calc_Volume!H14*Assum_Costs!$C$6*H5/1000 -> 640 | I8: =Calc_Volume!I14*Assum_Costs!$C$6*I5/1000 -> 680 | ... DQ8: =Calc_Volume!DQ14*Assum_Costs!$C$6*DQ5/1000 -> 2230.2767
A9: Hops | B9: =Calc_Volume!B14*Assum_Costs!$C$7*B5/1000 -> 383.33333 | C9: =Calc_Volume!C14*Assum_Costs!$C$7*C5/1000 -> 366.66667 | D9: =Calc_Volume!D14*Assum_Costs!$C$7*D5/1000 -> 333.33333 | E9: =Calc_Volume!E14*Assum_Costs!$C$7*E5/1000 -> 300 | F9: =Calc_Volume!F14*Assum_Costs!$C$7*F5/1000 -> 283.33333 | G9: =Calc_Volume!G14*Assum_Costs!$C$7*G5/1000 -> 266.66667 | H9: =Calc_Volume!H14*Assum_Costs!$C$7*H5/1000 -> 266.66667 | I9: =Calc_Volume!I14*Assum_Costs!$C$7*I5/1000 -> 283.33333 | ... DQ9: =Calc_Volume!DQ14*Assum_Costs!$C$7*DQ5/1000 -> 929.28196
A10: Yeast | B10: =Calc_Volume!B14*Assum_Costs!$C$8*B5/1000 -> 115 | C10: =Calc_Volume!C14*Assum_Costs!$C$8*C5/1000 -> 110 | D10: =Calc_Volume!D14*Assum_Costs!$C$8*D5/1000 -> 100 | E10: =Calc_Volume!E14*Assum_Costs!$C$8*E5/1000 -> 90 | F10: =Calc_Volume!F14*Assum_Costs!$C$8*F5/1000 -> 85 | G10: =Calc_Volume!G14*Assum_Costs!$C$8*G5/1000 -> 80 | H10: =Calc_Volume!H14*Assum_Costs!$C$8*H5/1000 -> 80 | I10: =Calc_Volume!I14*Assum_Costs!$C$8*I5/1000 -> 85 | ... DQ10: =Calc_Volume!DQ14*Assum_Costs!$C$8*DQ5/1000 -> 278.78459
A11: Water & Treatment | B11: =Calc_Volume!B14*Assum_Costs!$C$9*B5/1000 -> 115 | C11: =Calc_Volume!C14*Assum_Costs!$C$9*C5/1000 -> 110 | D11: =Calc_Volume!D14*Assum_Costs!$C$9*D5/1000 -> 100 | E11: =Calc_Volume!E14*Assum_Costs!$C$9*E5/1000 -> 90 | F11: =Calc_Volume!F14*Assum_Costs!$C$9*F5/1000 -> 85 | G11: =Calc_Volume!G14*Assum_Costs!$C$9*G5/1000 -> 80 | H11: =Calc_Volume!H14*Assum_Costs!$C$9*H5/1000 -> 80 | I11: =Calc_Volume!I14*Assum_Costs!$C$9*I5/1000 -> 85 | ... DQ11: =Calc_Volume!DQ14*Assum_Costs!$C$9*DQ5/1000 -> 278.78459
A12: Total Raw Materials | B12: =SUM(B8:B11) -> 1533.3333 | C12: =SUM(C8:C11) -> 1466.6667 | D12: =SUM(D8:D11) -> 1333.3333 | E12: =SUM(E8:E11) -> 1200 | F12: =SUM(F8:F11) -> 1133.3333 | G12: =SUM(G8:G11) -> 1066.6667 | H12: =SUM(H8:H11) -> 1066.6667 | I12: =SUM(I8:I11) -> 1133.3333 | ... DQ12: =SUM(DQ8:DQ11) -> 3717.1278
A14: PACKAGING ($000s)
A15: Bottles | B15: =Calc_Volume!B25*Assum_Costs!$C$13*B5/1000 -> 972.70833 | C15: =Calc_Volume!C25*Assum_Costs!$C$13*C5/1000 -> 930.41667 | D15: =Calc_Volume!D25*Assum_Costs!$C$13*D5/1000 -> 845.83333 | E15: =Calc_Volume!E25*Assum_Costs!$C$13*E5/1000 -> 761.25 | F15: =Calc_Volume!F25*Assum_Costs!$C$13*F5/1000 -> 718.95833 | G15: =Calc_Volume!G25*Assum_Costs!$C$13*G5/1000 -> 676.66667 | H15: =Calc_Volume!H25*Assum_Costs!$C$13*H5/1000 -> 676.66667 | I15: =Calc_Volume!I25*Assum_Costs!$C$13*I5/1000 -> 718.95833 | ... DQ15: =Calc_Volume!DQ25*Assum_Costs!$C$13*DQ5/1000 -> 2358.053
A16: Cans | B16: =Calc_Volume!B26*Assum_Costs!$C$14*B5/1000 -> 902.75 | C16: =Calc_Volume!C26*Assum_Costs!$C$14*C5/1000 -> 863.5 | D16: =Calc_Volume!D26*Assum_Costs!$C$14*D5/1000 -> 785 | E16: =Calc_Volume!E26*Assum_Costs!$C$14*E5/1000 -> 706.5 | F16: =Calc_Volume!F26*Assum_Costs!$C$14*F5/1000 -> 667.25 | G16: =Calc_Volume!G26*Assum_Costs!$C$14*G5/1000 -> 628 | H16: =Calc_Volume!H26*Assum_Costs!$C$14*H5/1000 -> 628 | I16: =Calc_Volume!I26*Assum_Costs!$C$14*I5/1000 -> 667.25 | ... DQ16: =Calc_Volume!DQ26*Assum_Costs!$C$14*DQ5/1000 -> 2188.459
A17: Kegs | B17: =Calc_Volume!B27*Assum_Costs!$C$15*B5/1000 -> 150.26667 | C17: =Calc_Volume!C27*Assum_Costs!$C$15*C5/1000 -> 143.73333 | D17: =Calc_Volume!D27*Assum_Costs!$C$15*D5/1000 -> 130.66667 | E17: =Calc_Volume!E27*Assum_Costs!$C$15*E5/1000 -> 117.6 | F17: =Calc_Volume!F27*Assum_Costs!$C$15*F5/1000 -> 111.06667 | G17: =Calc_Volume!G27*Assum_Costs!$C$15*G5/1000 -> 104.53333 | H17: =Calc_Volume!H27*Assum_Costs!$C$15*H5/1000 -> 104.53333 | I17: =Calc_Volume!I27*Assum_Costs!$C$15*I5/1000 -> 111.06667 | ... DQ17: =Calc_Volume!DQ27*Assum_Costs!$C$15*DQ5/1000 -> 364.27853
A18: Total Packaging | B18: =SUM(B15:B17) -> 2025.725 | C18: =SUM(C15:C17) -> 1937.65 | D18: =SUM(D15:D17) -> 1761.5 | E18: =SUM(E15:E17) -> 1585.35 | F18: =SUM(F15:F17) -> 1497.275 | G18: =SUM(G15:G17) -> 1409.2 | H18: =SUM(H15:H17) -> 1409.2 | I18: =SUM(I15:I17) -> 1497.275 | ... DQ18: =SUM(DQ15:DQ17) -> 4910.7905
A20: DIRECT MANUFACTURING ($000s)
A21: Direct Labour | B21: =Calc_Volume!B14*Assum_Costs!$C$18*B5/1000 -> 920 | C21: =Calc_Volume!C14*Assum_Costs!$C$18*C5/1000 -> 880 | D21: =Calc_Volume!D14*Assum_Costs!$C$18*D5/1000 -> 800 | E21: =Calc_Volume!E14*Assum_Costs!$C$18*E5/1000 -> 720 | F21: =Calc_Volume!F14*Assum_Costs!$C$18*F5/1000 -> 680 | G21: =Calc_Volume!G14*Assum_Costs!$C$18*G5/1000 -> 640 | H21: =Calc_Volume!H14*Assum_Costs!$C$18*H5/1000 -> 640 | I21: =Calc_Volume!I14*Assum_Costs!$C$18*I5/1000 -> 680 | ... DQ21: =Calc_Volume!DQ14*Assum_Costs!$C$18*DQ5/1000 -> 2230.2767
A22: Utilities | B22: =Calc_Volume!B14*Assum_Costs!$C$19*B5/1000 -> 460 | C22: =Calc_Volume!C14*Assum_Costs!$C$19*C5/1000 -> 440 | D22: =Calc_Volume!D14*Assum_Costs!$C$19*D5/1000 -> 400 | E22: =Calc_Volume!E14*Assum_Costs!$C$19*E5/1000 -> 360 | F22: =Calc_Volume!F14*Assum_Costs!$C$19*F5/1000 -> 340 | G22: =Calc_Volume!G14*Assum_Costs!$C$19*G5/1000 -> 320 | H22: =Calc_Volume!H14*Assum_Costs!$C$19*H5/1000 -> 320 | I22: =Calc_Volume!I14*Assum_Costs!$C$19*I5/1000 -> 340 | ... DQ22: =Calc_Volume!DQ14*Assum_Costs!$C$19*DQ5/1000 -> 1115.1384
A23: Manufacturing Overhead | B23: =Calc_Volume!B14*Assum_Costs!$C$20*B5/1000 -> 613.33333 | C23: =Calc_Volume!C14*Assum_Costs!$C$20*C5/1000 -> 586.66667 | D23: =Calc_Volume!D14*Assum_Costs!$C$20*D5/1000 -> 533.33333 | E23: =Calc_Volume!E14*Assum_Costs!$C$20*E5/1000 -> 480 | F23: =Calc_Volume!F14*Assum_Costs!$C$20*F5/1000 -> 453.33333 | G23: =Calc_Volume!G14*Assum_Costs!$C$20*G5/1000 -> 426.66667 | H23: =Calc_Volume!H14*Assum_Costs!$C$20*H5/1000 -> 426.66667 | I23: =Calc_Volume!I14*Assum_Costs!$C$20*I5/1000 -> 453.33333 | ... DQ23: =Calc_Volume!DQ14*Assum_Costs!$C$20*DQ5/1000 -> 1486.8511
A24: Quality Control | B24: =Calc_Volume!B14*Assum_Costs!$C$21*B5/1000 -> 153.33333 | C24: =Calc_Volume!C14*Assum_Costs!$C$21*C5/1000 -> 146.66667 | D24: =Calc_Volume!D14*Assum_Costs!$C$21*D5/1000 -> 133.33333 | E24: =Calc_Volume!E14*Assum_Costs!$C$21*E5/1000 -> 120 | F24: =Calc_Volume!F14*Assum_Costs!$C$21*F5/1000 -> 113.33333 | G24: =Calc_Volume!G14*Assum_Costs!$C$21*G5/1000 -> 106.66667 | H24: =Calc_Volume!H14*Assum_Costs!$C$21*H5/1000 -> 106.66667 | I24: =Calc_Volume!I14*Assum_Costs!$C$21*I5/1000 -> 113.33333 | ... DQ24: =Calc_Volume!DQ14*Assum_Costs!$C$21*DQ5/1000 -> 371.71278
A25: Total Direct Manufacturing | B25: =SUM(B21:B24) -> 2146.6667 | C25: =SUM(C21:C24) -> 2053.3333 | D25: =SUM(D21:D24) -> 1866.6667 | E25: =SUM(E21:E24) -> 1680 | F25: =SUM(F21:F24) -> 1586.6667 | G25: =SUM(G21:G24) -> 1493.3333 | H25: =SUM(H21:H24) -> 1493.3333 | I25: =SUM(I21:I24) -> 1586.6667 | ... DQ25: =SUM(DQ21:DQ24) -> 5203.979
A27: TOTAL COGS ($000s)
A28: Total COGS | B28: =B12+B18+B25 -> 5705.725 | C28: =C12+C18+C25 -> 5457.65 | D28: =D12+D18+D25 -> 4961.5 | E28: =E12+E18+E25 -> 4465.35 | F28: =F12+F18+F25 -> 4217.275 | G28: =G12+G18+G25 -> 3969.2 | H28: =H12+H18+H25 -> 3969.2 | I28: =I12+I18+I25 -> 4217.275 | ... DQ28: =DQ12+DQ18+DQ25 -> 13831.897
A30: KEY METRICS
A31: COGS per HL | B31: =IF(Calc_Volume!B14>0,B28*1000/Calc_Volume!B14,0) -> 74.4225 | C31: =IF(Calc_Volume!C14>0,C28*1000/Calc_Volume!C14,0) -> 74.4225 | D31: =IF(Calc_Volume!D14>0,D28*1000/Calc_Volume!D14,0) -> 74.4225 | E31: =IF(Calc_Volume!E14>0,E28*1000/Calc_Volume!E14,0) -> 74.4225 | F31: =IF(Calc_Volume!F14>0,F28*1000/Calc_Volume!F14,0) -> 74.4225 | G31: =IF(Calc_Volume!G14>0,G28*1000/Calc_Volume!G14,0) -> 74.4225 | H31: =IF(Calc_Volume!H14>0,H28*1000/Calc_Volume!H14,0) -> 74.4225 | I31: =IF(Calc_Volume!I14>0,I28*1000/Calc_Volume!I14,0) -> 74.4225 | ... DQ31: =IF(Calc_Volume!DQ14>0,DQ28*1000/Calc_Volume!DQ14,0) -> 92.943504
A32: Gross Margin % | B32: =IF(Calc_Revenue!B25>0,(Calc_Revenue!B25-B28)/Calc_Revenue!B25,0) -> 0.75205616 | C32: =IF(Calc_Revenue!C25>0,(Calc_Revenue!C25-C28)/Calc_Revenue!C25,0) -> 0.75205616 | D32: =IF(Calc_Revenue!D25>0,(Calc_Revenue!D25-D28)/Calc_Revenue!D25,0) -> 0.75205616 | E32: =IF(Calc_Revenue!E25>0,(Calc_Revenue!E25-E28)/Calc_Revenue!E25,0) -> 0.75205616 | F32: =IF(Calc_Revenue!F25>0,(Calc_Revenue!F25-F28)/Calc_Revenue!F25,0) -> 0.75205616 | G32: =IF(Calc_Revenue!G25>0,(Calc_Revenue!G25-G28)/Calc_Revenue!G25,0) -> 0.75205616 | H32: =IF(Calc_Revenue!H25>0,(Calc_Revenue!H25-H28)/Calc_Revenue!H25,0) -> 0.75205616 | I32: =IF(Calc_Revenue!I25>0,(Calc_Revenue!I25-I28)/Calc_Revenue!I25,0) -> 0.75205616 | ... DQ32: =IF(Calc_Revenue!DQ25>0,(Calc_Revenue!DQ25-DQ28)/Calc_Revenue!DQ25,0) -> 0.78612405

Sheet Calc_Opex
A1: OPERATING EXPENSES
A3: Period | B3: =Calc_Volume!B3 -> 1 | C3: =Calc_Volume!C3 -> 2 | D3: =Calc_Volume!D3 -> 3 | E3: =Calc_Volume!E3 -> 4 | F3: =Calc_Volume!F3 -> 5 | G3: =Calc_Volume!G3 -> 6 | H3: =Calc_Volume!H3 -> 7 | I3: =Calc_Volume!I3 -> 8 | ... DQ3: =Calc_Volume!DQ3 -> 120
A4: Date | B4: =Calc_Volume!B4 -> 45658 | C4: =Calc_Volume!C4 -> 45689 | D4: =Calc_Volume!D4 -> 45717 | E4: =Calc_Volume!E4 -> 45748 | F4: =Calc_Volume!F4 -> 45778 | G4: =Calc_Volume!G4 -> 45809 | H4: =Calc_Volume!H4 -> 45839 | I4: =Calc_Volume!I4 -> 45870 | ... DQ4: =Calc_Volume!DQ4 -> 49279
A6: LOGISTICS & DISTRIBUTION ($000s)
