Workbook
Name COD: Inputs!$E$14
Name Days_Year: 'L&N'!$E$30
Name Million: 'L&N'!$E$35
Name Model_Start: Inputs!$E$6
Name Months_Qtr: 'L&N'!$E$33
Name Months_Yr: 'L&N'!$E$31
Name Name_Course: 'L&N'!$E$26
Name Name_Model: 'L&N'!$E$27
Name Qtrs_Yr: 'L&N'!$E$32

Sheet  
H7: =Name_Course -> Preparation and Ownership fo Financial Models
H8: =Name_Model -> Transaction Model: Funding options and testing limits
H9: IFM Investors, Melbourne, June 2014
H13: Name | I13: Kenny Chew, Senior Associate
H14: Company | I14: Corality Financial Group
H15: Email | I15: kenny.chew@corality.com
B23: www.corality.com
B24: contact@corality.com
B25: © Copyright 2012 Corality Financial Group

Sheet QCF
A1: Quarterly Cashflow
A2: =Name_Model -> Transaction Model: Funding options and testing limits
A4: =Timing!A4 -> Period Start | J4: =Timing!J4 -> 40909 | K4: =Timing!K4 -> 41000 | L4: =Timing!L4 -> 41091 | M4: =Timing!M4 -> 41183 | N4: =Timing!N4 -> 41275 | O4: =Timing!O4 -> 41365 | P4: =Timing!P4 -> 41456 | Q4: =Timing!Q4 -> 41548 | ... BI4: =Timing!BI4 -> 45566
A5: =Timing!A5 -> Period End | I5: =Timing!I5 -> 40908 | J5: =Timing!J5 -> 40999 | K5: =Timing!K5 -> 41090 | L5: =Timing!L5 -> 41182 | M5: =Timing!M5 -> 41274 | N5: =Timing!N5 -> 41364 | O5: =Timing!O5 -> 41455 | P5: =Timing!P5 -> 41547 | ... BI5: =Timing!BI5 -> 45657
A6: =Timing!A6 -> Construction | J6: =Timing!J6 -> 1 | K6: =Timing!K6 -> 1 | L6: =Timing!L6 -> 1 | M6: =Timing!M6 -> 1 | N6: =Timing!N6 -> 1 | O6: =Timing!O6 -> 1 | P6: =Timing!P6 -> 1 | Q6: =Timing!Q6 -> 1 | ... BI6: =Timing!BI6 -> 0
A7: =Timing!A7 -> Operations | J7: =Timing!J7 -> 0 | K7: =Timing!K7 -> 0 | L7: =Timing!L7 -> 0 | M7: =Timing!M7 -> 0 | N7: =Timing!N7 -> 0 | O7: =Timing!O7 -> 0 | P7: =Timing!P7 -> 0 | Q7: =Timing!Q7 -> 0 | ... BI7: =Timing!BI7 -> 0
C9: Counters
C10: Calendar Year | J10: =YEAR((J5)) -> 2012 | K10: =YEAR((K5)) -> 2012 | L10: =YEAR((L5)) -> 2012 | M10: =YEAR((M5)) -> 2012 | N10: =YEAR((N5)) -> 2013 | O10: =YEAR((O5)) -> 2013 | P10: =YEAR((P5)) -> 2013 | Q10: =YEAR((Q5)) -> 2013 | ... BI10: =YEAR((BI5)) -> 2024
C12: Cashflow Statement (AUD M)
C13: Revenue
C14: Sales | I14: =SUM(J14:BI14) -> 1.5532719e+08 | J14: =Ops!J19 -> 0 | K14: =Ops!K19 -> 0 | L14: =Ops!L19 -> 0 | M14: =Ops!M19 -> 0 | N14: =Ops!N19 -> 0 | O14: =Ops!O19 -> 0 | P14: =Ops!P19 -> 0 | Q14: =Ops!Q19 -> 0 | ... BI14: =Ops!BI19 -> 0
C16: Operational Expense
C17: Fixed Costs | I17: =SUM(J17:BI17) -> -70.846774 | J17: =-Ops!J43 -> 0 | K17: =-Ops!K43 -> 0 | L17: =-Ops!L43 -> 0 | M17: =-Ops!M43 -> 0 | N17: =-Ops!N43 -> 0 | O17: =-Ops!O43 -> 0 | P17: =-Ops!P43 -> 0 | Q17: =-Ops!Q43 -> 0 | ... BI17: =-Ops!BI43 -> 0
C18: Variable Costs | I18: =SUM(J18:BI18) -> 0 | J18: =-Ops!J44 -> 0 | K18: =-Ops!K44 -> 0 | L18: =-Ops!L44 -> 0 | M18: =-Ops!M44 -> 0 | N18: =-Ops!N44 -> 0 | O18: =-Ops!O44 -> 0 | P18: =-Ops!P44 -> 0 | Q18: =-Ops!Q44 -> 0 | ... BI18: =-Ops!BI44 -> 0
C19: Total | I19: =SUM(J19:BI19) -> -70.846774 | J19: =SUM(J17:J18) -> 0 | K19: =SUM(K17:K18) -> 0 | L19: =SUM(L17:L18) -> 0 | M19: =SUM(M17:M18) -> 0 | N19: =SUM(N17:N18) -> 0 | O19: =SUM(O17:O18) -> 0 | P19: =SUM(P17:P18) -> 0 | Q19: =SUM(Q17:Q18) -> 0 | ... BI19: =SUM(BI17:BI18) -> 0
C21: Operating Cashflow | I21: =SUM(J21:BI21) -> 1.5532712e+08 | J21: =J14+J19 -> 0 | K21: =K14+K19 -> 0 | L21: =L14+L19 -> 0 | M21: =M14+M19 -> 0 | N21: =N14+N19 -> 0 | O21: =O14+O19 -> 0 | P21: =P14+P19 -> 0 | Q21: =Q14+Q19 -> 0 | ... BI21: =BI14+BI19 -> 0
C23: Capital Expenditure
C24: =Cons!C23 -> Construction Cost | I24: =SUM(J24:BI24) -> -60 | J24: =-Cons!J23 -> -7.5 | K24: =-Cons!K23 -> -7.5 | L24: =-Cons!L23 -> -7.5 | M24: =-Cons!M23 -> -7.5 | N24: =-Cons!N23 -> -7.5 | O24: =-Cons!O23 -> -7.5 | P24: =-Cons!P23 -> -7.5 | Q24: =-Cons!Q23 -> -7.5 | ... BI24: =-Cons!BI23 -> 0
C25: =Cons!C24 -> Interest During Construction | I25: =SUM(J25:BI25) -> -3.4380986 | J25: =-Cons!J24 -> 0 | K25: =-Cons!K24 -> -0.1293621 | L25: =-Cons!L24 -> -0.26384797 | M25: =-Cons!M24 -> -0.39924532 | N25: =-Cons!N24 -> -0.48187788 | O25: =-Cons!O24 -> -0.61358319 | P25: =-Cons!P24 -> -0.7501948 | Q25: =-Cons!Q24 -> -0.79998735 | ... BI25: =-Cons!BI24 -> 0
C26: Total | I26: =SUM(J26:BI26) -> -63.438099 | J26: =SUM(J24:J25) -> -7.5 | K26: =SUM(K24:K25) -> -7.6293621 | L26: =SUM(L24:L25) -> -7.763848 | M26: =SUM(M24:M25) -> -7.8992453 | N26: =SUM(N24:N25) -> -7.9818779 | O26: =SUM(O24:O25) -> -8.1135832 | P26: =SUM(P24:P25) -> -8.2501948 | Q26: =SUM(Q24:Q25) -> -8.2999873 | ... BI26: =SUM(BI24:BI25) -> 0
C28: Funding
C29: Debt | I29: =SUM(J29:BI29) -> 50 | J29: =Cons!J28 -> 7.5 | K29: =Cons!K28 -> 7.6293621 | L29: =Cons!L28 -> 7.763848 | M29: =Cons!M28 -> 7.8992453 | N29: =Cons!N28 -> 7.9818779 | O29: =Cons!O28 -> 8.1135832 | P29: =Cons!P28 -> 3.1120835 | Q29: =Cons!Q28 -> 0 | ... BI29: =Cons!BI28 -> 0
C30: Equity | I30: =SUM(J30:BI30) -> 13.438099 | J30: =Cons!J31 -> 0 | K30: =Cons!K31 -> 0 | L30: =Cons!L31 -> 0 | M30: =Cons!M31 -> 0 | N30: =Cons!N31 -> 0 | O30: =Cons!O31 -> 0 | P30: =Cons!P31 -> 5.1381112 | Q30: =Cons!Q31 -> 8.2999873 | ... BI30: =Cons!BI31 -> 0
C31: Total | I31: =SUM(J31:BI31) -> 63.438099 | J31: =SUM(J29:J30) -> 7.5 | K31: =SUM(K29:K30) -> 7.6293621 | L31: =SUM(L29:L30) -> 7.763848 | M31: =SUM(M29:M30) -> 7.8992453 | N31: =SUM(N29:N30) -> 7.9818779 | O31: =SUM(O29:O30) -> 8.1135832 | P31: =SUM(P29:P30) -> 8.2501948 | Q31: =SUM(Q29:Q30) -> 8.2999873 | ... BI31: =SUM(BI29:BI30) -> 0
C33: Cashflow Available for Debt Service (CFADS) | I33: =SUM(J33:BI33) -> 1.5532712e+08 | J33: =J21+J26+J31 -> 0 | K33: =K21+K26+K31 -> 0 | L33: =L21+L26+L31 -> 0 | M33: =M21+M26+M31 -> 0 | N33: =N21+N26+N31 -> 0 | O33: =O21+O26+O31 -> 0 | P33: =P21+P26+P31 -> 0 | Q33: =Q21+Q26+Q31 -> 0 | ... BI33: =BI21+BI26+BI31 -> 0
C35: Debt Repayment
C36: Principal | I36: =SUM(J36:BI36) -> -50 | J36: =Debt!J21 -> 0 | K36: =Debt!K21 -> 0 | L36: =Debt!L21 -> 0 | M36: =Debt!M21 -> 0 | N36: =Debt!N21 -> 0 | O36: =Debt!O21 -> 0 | P36: =Debt!P21 -> 0 | Q36: =Debt!Q21 -> 0 | ... BI36: =Debt!BI21 -> 0
C37: Interest | I37: =SUM(J37:BI37) -> -8.546875 | J37: =-Debt!J30 -> 0 | K37: =-Debt!K30 -> 0 | L37: =-Debt!L30 -> 0 | M37: =-Debt!M30 -> 0 | N37: =-Debt!N30 -> 0 | O37: =-Debt!O30 -> 0 | P37: =-Debt!P30 -> 0 | Q37: =-Debt!Q30 -> 0 | ... BI37: =-Debt!BI30 -> 0
C38: Total | I38: =SUM(J38:BI38) -> -58.546875 | J38: =SUM(J36:J37) -> 0 | K38: =SUM(K36:K37) -> 0 | L38: =SUM(L36:L37) -> 0 | M38: =SUM(M36:M37) -> 0 | N38: =SUM(N36:N37) -> 0 | O38: =SUM(O36:O37) -> 0 | P38: =SUM(P36:P37) -> 0 | Q38: =SUM(Q36:Q37) -> 0 | ... BI38: =SUM(BI36:BI37) -> 0
C40: Cashflow Available for Equity | I40: =SUM(J40:BI40) -> 1.5532706e+08 | J40: =J33+J38 -> 0 | K40: =K33+K38 -> 0 | L40: =L33+L38 -> 0 | M40: =M33+M38 -> 0 | N40: =N33+N38 -> 0 | O40: =O33+O38 -> 0 | P40: =P33+P38 -> 0 | Q40: =Q33+Q38 -> 0 | ... BI40: =BI33+BI38 -> 0
C42: Dividends | I42: =SUM(J42:BI42) -> -1.5532706e+08 | J42: =-Ops!J50 -> 0 | K42: =-Ops!K50 -> 0 | L42: =-Ops!L50 -> 0 | M42: =-Ops!M50 -> 0 | N42: =-Ops!N50 -> 0 | O42: =-Ops!O50 -> 0 | P42: =-Ops!P50 -> 0 | Q42: =-Ops!Q50 -> 0 | ... BI42: =-Ops!BI50 -> 0
C44: Net Cashflow | I44: =SUM(J44:BI44) -> 0 | J44: =J40+J42 -> 0 | K44: =K40+K42 -> 0 | L44: =L40+L42 -> 0 | M44: =M40+M42 -> 0 | N44: =N40+N42 -> 0 | O44: =O40+O42 -> 0 | P44: =P40+P42 -> 0 | Q44: =Q40+Q42 -> 0 | ... BI44: =BI40+BI42 -> 0
C46: Cash Balance B/f | J46: =I47 -> 0 | K46: =J47 -> 0 | L46: =K47 -> 0 | M46: =L47 -> 0 | N46: =M47 -> 0 | O46: =N47 -> 0 | P46: =O47 -> 0 | Q46: =P47 -> 0 | ... BI46: =BH47 -> 0
C47: Cash Balance C/f | J47: =J44+J46 -> 0 | K47: =K44+K46 -> 0 | L47: =L44+L46 -> 0 | M47: =M44+M46 -> 0 | N47: =N44+N46 -> 0 | O47: =O44+O46 -> 0 | P47: =P44+P46 -> 0 | Q47: =Q44+Q46 -> 0 | ... BI47: =BI44+BI46 -> 0

Sheet Inputs
A1: Assumptions
A2: =Name_Model -> Transaction Model: Funding options and testing limits
C4: Timing
C5: Start
C6: Model Start Date | D6: Date | E6: 40908
C8: Construction
C9: Start | D9: Date | E9: =Model_Start+1 -> 40909
C10: Duration | D10: Qtr(s) | E10: 8
C11: End | D11: Date | E11: =EOMONTH(E9,E10*Months_Qtr-1) -> 41639
C13: Operations
C14: Start | D14: Date | E14: =E11+1 -> 41640
C15: Duration | D15: Yr(s) | E15: 10
C16: End | D16: Date | E16: =EOMONTH(E14,E15*Months_Yr-1) -> 45291
C18: Construction
C19: CapEx
C20: All construction costs | D20: AUD M | E20: 60
C22: Development Schedule | E22: Total | F22: 1 | G22: =F22+1 -> 2 | H22: =G22+1 -> 3 | I22: =H22+1 -> 4 | J22: =I22+1 -> 5 | K22: =J22+1 -> 6 | L22: =K22+1 -> 7 | M22: =L22+1 -> 8 | N22: =M22+1 -> 9 | ... Q22: =P22+1 -> 12
C23: Construction spend profile | D23: % | E23: =SUM(F23:Q23) -> 1 | F23: 0.125 | G23: 0.125 | H23: 0.125 | I23: 0.125 | J23: 0.125 | K23: 0.125 | L23: 0.125 | M23: 0.125
C25: Volume & Price
C26: Net Generation
C27: Period | E27: 1 | F27: =E27+1 -> 2 | G27: =F27+1 -> 3 | H27: =G27+1 -> 4 | I27: =H27+1 -> 5 | J27: =I27+1 -> 6 | K27: =J27+1 -> 7 | L27: =K27+1 -> 8 | M27: =L27+1 -> 9 | N27: =M27+1 -> 10
C28: Net Generation | D28: MWh p.a. | E28: 130000 | F28: =E28 -> 130000 | G28: =F28 -> 130000 | H28: =G28 -> 130000 | I28: =H28 -> 130000 | J28: =I28 -> 130000 | K28: =J28 -> 130000 | L28: =K28 -> 130000 | M28: =L28 -> 130000 | N28: =M28 -> 130000
C30: Price
C31: Period | F31: =YEAR(COD) -> 2014 | G31: =F31+1 -> 2015 | H31: =G31+1 -> 2016 | I31: =H31+1 -> 2017
C32: Price | D32: AUD/MWh | F32: 110 | G32: 112 | H32: 114.5 | I32: 115
C34: Operational Expenditure
C35: Fixed Costs
C36: Nominal | E36: 1 | F36: =E36+1 -> 2 | G36: =F36+1 -> 3 | H36: =G36+1 -> 4 | I36: =H36+1 -> 5 | J36: =I36+1 -> 6 | K36: =J36+1 -> 7 | L36: =K36+1 -> 8 | M36: =L36+1 -> 9 | N36: =M36+1 -> 10
C37: Labour | D37: AUD M | E37: 0.515 | F37: 0.53045 | G37: 0.5463635 | H37: 0.56275441 | I37: 0.57963704 | J37: 0.59702615 | K37: 0.61493693 | L37: 0.63338504 | M37: 0.65238659 | N37: 0.67195819
C38: Land & Leasing | D38: AUD M | E38: 1.03 | F38: 1.0609 | G38: 1.092727 | H38: 1.1255088 | I38: 1.1592741 | J38: 1.1940523 | K38: 1.2298739 | L38: 1.2667701 | M38: 1.3047732 | N38: 1.3439164
C39: Spare | D39: AUD M
C41: Variable Costs
C42: Nominal Cost Price | E42: 1 | F42: =E42+1 -> 2 | G42: =F42+1 -> 3 | H42: =G42+1 -> 4 | I42: =H42+1 -> 5 | J42: =I42+1 -> 6 | K42: =J42+1 -> 7 | L42: =K42+1 -> 8 | M42: =L42+1 -> 9 | N42: =M42+1 -> 10
C43: Other | D43: AUD / Mwh | E43: 1.545 | F43: 1.59135 | G43: 1.6390905 | H43: 1.6882632 | I43: 1.7389111 | J43: 1.7910784 | K43: 1.8448108 | L43: 1.9001551 | M43: 1.9571598 | N43: 2.0158746
C44: Spare | D44: AUD / Mwh
C45: Spare | D45: AUD / Mwh
C47: Funding
C48: Senior Debt
C49: Debt Limit | D49: AUD M | E49: 50
C51: Period | E51: Cons | F51: 1 | G51: 2 | H51: 3 | I51: 4
...

Sheet Cons
A1: Construction
A2: =Name_Model -> Transaction Model: Funding options and testing limits
A4: =Timing!A4 -> Period Start | J4: =Timing!J4 -> 40909 | K4: =Timing!K4 -> 41000 | L4: =Timing!L4 -> 41091 | M4: =Timing!M4 -> 41183 | N4: =Timing!N4 -> 41275 | O4: =Timing!O4 -> 41365 | P4: =Timing!P4 -> 41456 | Q4: =Timing!Q4 -> 41548 | ... BI4: =Timing!BI4 -> 45566
A5: =Timing!A5 -> Period End | I5: =Timing!I5 -> 40908 | J5: =Timing!J5 -> 40999 | K5: =Timing!K5 -> 41090 | L5: =Timing!L5 -> 41182 | M5: =Timing!M5 -> 41274 | N5: =Timing!N5 -> 41364 | O5: =Timing!O5 -> 41455 | P5: =Timing!P5 -> 41547 | ... BI5: =Timing!BI5 -> 45657
A6: =Timing!A6 -> Construction | J6: =Timing!J6 -> 1 | K6: =Timing!K6 -> 1 | L6: =Timing!L6 -> 1 | M6: =Timing!M6 -> 1 | N6: =Timing!N6 -> 1 | O6: =Timing!O6 -> 1 | P6: =Timing!P6 -> 1 | Q6: =Timing!Q6 -> 1 | ... BI6: =Timing!BI6 -> 0
A7: =Timing!A7 -> Operations | J7: =Timing!J7 -> 0 | K7: =Timing!K7 -> 0 | L7: =Timing!L7 -> 0 | M7: =Timing!M7 -> 0 | N7: =Timing!N7 -> 0 | O7: =Timing!O7 -> 0 | P7: =Timing!P7 -> 0 | Q7: =Timing!Q7 -> 0 | ... BI7: =Timing!BI7 -> 0
C9: =Timing!C9 -> Counters
C10: =Timing!C10 -> Construction Quarters | D10: Num# | J10: =Timing!J10 -> 1 | K10: =Timing!K10 -> 2 | L10: =Timing!L10 -> 3 | M10: =Timing!M10 -> 4 | N10: =Timing!N10 -> 5 | O10: =Timing!O10 -> 6 | P10: =Timing!P10 -> 7 | Q10: =Timing!Q10 -> 8 | ... BI10: =Timing!BI10 -> 0
C11: =Timing!C13 -> Calendar Year | D11: Year | J11: =Timing!J13 -> 2012 | K11: =Timing!K13 -> 2012 | L11: =Timing!L13 -> 2012 | M11: =Timing!M13 -> 2012 | N11: =Timing!N13 -> 2013 | O11: =Timing!O13 -> 2013 | P11: =Timing!P13 -> 2013 | Q11: =Timing!Q13 -> 2013 | ... BI11: =Timing!BI13 -> 2024
C12: =Timing!C14 -> Days in Period | D12: Days | J12: =Timing!J14 -> 91 | K12: =Timing!K14 -> 91 | L12: =Timing!L14 -> 92 | M12: =Timing!M14 -> 92 | N12: =Timing!N14 -> 90 | O12: =Timing!O14 -> 91 | P12: =Timing!P14 -> 92 | Q12: =Timing!Q14 -> 92 | ... BI12: =Timing!BI14 -> 92
C14: Construction Costs
C15: Spend Profile
C16: =Inputs!C20 -> All construction costs | D16: % | I16: =SUM(J16:BI16) -> 1 | J16: =IF(J$10=0,0,LOOKUP(J$10,Inputs!$F$22:$Q$22,Inputs!$F23:$Q23)) -> 0.125 | K16: =IF(K$10=0,0,LOOKUP(K$10,Inputs!$F$22:$Q$22,Inputs!$F23:$Q23)) -> 0.125 | L16: =IF(L$10=0,0,LOOKUP(L$10,Inputs!$F$22:$Q$22,Inputs!$F23:$Q23)) -> 0.125 | M16: =IF(M$10=0,0,LOOKUP(M$10,Inputs!$F$22:$Q$22,Inputs!$F23:$Q23)) -> 0.125 | N16: =IF(N$10=0,0,LOOKUP(N$10,Inputs!$F$22:$Q$22,Inputs!$F23:$Q23)) -> 0.125 | O16: =IF(O$10=0,0,LOOKUP(O$10,Inputs!$F$22:$Q$22,Inputs!$F23:$Q23)) -> 0.125 | P16: =IF(P$10=0,0,LOOKUP(P$10,Inputs!$F$22:$Q$22,Inputs!$F23:$Q23)) -> 0.125 | Q16: =IF(Q$10=0,0,LOOKUP(Q$10,Inputs!$F$22:$Q$22,Inputs!$F23:$Q23)) -> 0.125 | ... BI16: =IF(BI$10=0,0,LOOKUP(BI$10,Inputs!$F$22:$Q$22,Inputs!$F23:$Q23)) -> 0
C18: Costs
C19: =C16 -> All construction costs | D19: AUD M | E19: =Inputs!E20 -> 60 | I19: =SUM(J19:BI19) -> 60 | J19: =$E19*J16*(1+$F$19) -> 7.5 | K19: =$E19*K16*(1+$F$19) -> 7.5 | L19: =$E19*L16*(1+$F$19) -> 7.5 | M19: =$E19*M16*(1+$F$19) -> 7.5 | N19: =$E19*N16*(1+$F$19) -> 7.5 | O19: =$E19*O16*(1+$F$19) -> 7.5 | P19: =$E19*P16*(1+$F$19) -> 7.5 | Q19: =$E19*Q16*(1+$F$19) -> 7.5 | ... BI19: =$E19*BI16*(1+$F$19) -> 0
C21: Funding
C22: Uses
C23: Construction Cost | D23: AUD M | I23: =SUM(J23:BI23) -> 60 | J23: =J19 -> 7.5 | K23: =K19 -> 7.5 | L23: =L19 -> 7.5 | M23: =M19 -> 7.5 | N23: =N19 -> 7.5 | O23: =O19 -> 7.5 | P23: =P19 -> 7.5 | Q23: =Q19 -> 7.5 | ... BI23: =BI19 -> 0
C24: Interest During Construction | D24: AUD M | I24: =SUM(J24:BI24) -> 3.4380986 | J24: =J48 -> 0 | K24: =K48 -> 0.1293621 | L24: =L48 -> 0.26384797 | M24: =M48 -> 0.39924532 | N24: =N48 -> 0.48187788 | O24: =O48 -> 0.61358319 | P24: =P48 -> 0.7501948 | Q24: =Q48 -> 0.79998735 | ... BI24: =BI48 -> 0
C25: Total | D25: AUD M | I25: =SUM(J25:BI25) -> 63.438099 | J25: =SUM(J23:J24) -> 7.5 | K25: =SUM(K23:K24) -> 7.6293621 | L25: =SUM(L23:L24) -> 7.763848 | M25: =SUM(M23:M24) -> 7.8992453 | N25: =SUM(N23:N24) -> 7.9818779 | O25: =SUM(O23:O24) -> 8.1135832 | P25: =SUM(P23:P24) -> 8.2501948 | Q25: =SUM(Q23:Q24) -> 8.2999873 | ... BI25: =SUM(BI23:BI24) -> 0
C27: Sources
C28: Debt | D28: AUD M | I28: =SUM(J28:BI28) -> 50 | J28: =MIN(J25,J40) -> 7.5 | K28: =MIN(K25,K40) -> 7.6293621 | L28: =MIN(L25,L40) -> 7.763848 | M28: =MIN(M25,M40) -> 7.8992453 | N28: =MIN(N25,N40) -> 7.9818779 | O28: =MIN(O25,O40) -> 8.1135832 | P28: =MIN(P25,P40) -> 3.1120835 | Q28: =MIN(Q25,Q40) -> 0 | ... BI28: =MIN(BI25,BI40) -> 0
C29: Shortfall | D29: AUD M | I29: =SUM(J29:BI29) -> 13.438099 | J29: =J25-J28 -> 0 | K29: =K25-K28 -> 0 | L29: =L25-L28 -> 0 | M29: =M25-M28 -> 0 | N29: =N25-N28 -> 0 | O29: =O25-O28 -> 0 | P29: =P25-P28 -> 5.1381112 | Q29: =Q25-Q28 -> 8.2999873 | ... BI29: =BI25-BI28 -> 0
C31: Equity | D31: AUD M | I31: =SUM(J31:BI31) -> 13.438099 | J31: =J29 -> 0 | K31: =K29 -> 0 | L31: =L29 -> 0 | M31: =M29 -> 0 | N31: =N29 -> 0 | O31: =O29 -> 0 | P31: =P29 -> 5.1381112 | Q31: =Q29 -> 8.2999873 | ... BI31: =BI29 -> 0
C32: Check | D32: AUD M | I32: =SUM(J32:BI32) -> 0 | J32: =J29-J31 -> 0 | K32: =K29-K31 -> 0 | L32: =L29-L31 -> 0 | M32: =M29-M31 -> 0 | N32: =N29-N31 -> 0 | O32: =O29-O31 -> 0 | P32: =P29-P31 -> 0 | Q32: =Q29-Q31 -> 0 | ... BI32: =BI29-BI31 -> 0
C34: Debt
C35: Balance B/f | D35: AUD M | J35: =I38 -> 0 | K35: =J38 -> 7.5 | L35: =K38 -> 15.129362 | M35: =L38 -> 22.89321 | N35: =M38 -> 30.792455 | O35: =N38 -> 38.774333 | P35: =O38 -> 46.887916 | Q35: =P38 -> 50 | ... BI35: =BH38 -> 0
C36: Drawdowns | D36: AUD M | I36: =SUM(J36:BI36) -> 50 | J36: =J28 -> 7.5 | K36: =K28 -> 7.6293621 | L36: =L28 -> 7.763848 | M36: =M28 -> 7.8992453 | N36: =N28 -> 7.9818779 | O36: =O28 -> 8.1135832 | P36: =P28 -> 3.1120835 | Q36: =Q28 -> 0 | ... BI36: =BI28 -> 0
C37: Refinance | D37: AUD M | E37: =Inputs!E11 -> 41639 | I37: =SUM(J37:BI37) -> -50 | J37: =-IF(J5=$E37,SUM(J35:J36),0) -> 0 | K37: =-IF(K5=$E37,SUM(K35:K36),0) -> 0 | L37: =-IF(L5=$E37,SUM(L35:L36),0) -> 0 | M37: =-IF(M5=$E37,SUM(M35:M36),0) -> 0 | N37: =-IF(N5=$E37,SUM(N35:N36),0) -> 0 | O37: =-IF(O5=$E37,SUM(O35:O36),0) -> 0 | P37: =-IF(P5=$E37,SUM(P35:P36),0) -> 0 | Q37: =-IF(Q5=$E37,SUM(Q35:Q36),0) -> -50 | ... BI37: =-IF(BI5=$E37,SUM(BI35:BI36),0) -> 0
C38: Balance C/f | D38: AUD M | J38: =SUM(J35:J37) -> 7.5 | K38: =SUM(K35:K37) -> 15.129362 | L38: =SUM(L35:L37) -> 22.89321 | M38: =SUM(M35:M37) -> 30.792455 | N38: =SUM(N35:N37) -> 38.774333 | O38: =SUM(O35:O37) -> 46.887916 | P38: =SUM(P35:P37) -> 50 | Q38: =SUM(Q35:Q37) -> 0 | ... BI38: =SUM(BI35:BI37) -> 0
C40: Undrawn Amount | D40: AUD M | E40: =Inputs!E49 -> 50 | J40: =($E40-J35)*J$6 -> 50 | K40: =($E40-K35)*K$6 -> 42.5 | L40: =($E40-L35)*L$6 -> 34.870638 | M40: =($E40-M35)*M$6 -> 27.10679 | N40: =($E40-N35)*N$6 -> 19.207545 | O40: =($E40-O35)*O$6 -> 11.225667 | P40: =($E40-P35)*P$6 -> 3.1120835 | Q40: =($E40-Q35)*Q$6 -> 0 | ... BI40: =($E40-BI35)*BI$6 -> 0
C42: Interest
C43: Base Rate | D43: % p.a. | J43: =LOOKUP(J$11,Inputs!$F$62:$I$62,Inputs!$F$63:$I$63) -> 0.036 | K43: =LOOKUP(K$11,Inputs!$F$62:$I$62,Inputs!$F$63:$I$63) -> 0.036 | L43: =LOOKUP(L$11,Inputs!$F$62:$I$62,Inputs!$F$63:$I$63) -> 0.036 | M43: =LOOKUP(M$11,Inputs!$F$62:$I$62,Inputs!$F$63:$I$63) -> 0.036 | N43: =LOOKUP(N$11,Inputs!$F$62:$I$62,Inputs!$F$63:$I$63) -> 0.03 | O43: =LOOKUP(O$11,Inputs!$F$62:$I$62,Inputs!$F$63:$I$63) -> 0.03 | P43: =LOOKUP(P$11,Inputs!$F$62:$I$62,Inputs!$F$63:$I$63) -> 0.03 | Q43: =LOOKUP(Q$11,Inputs!$F$62:$I$62,Inputs!$F$63:$I$63) -> 0.03 | ... BI43: =LOOKUP(BI$11,Inputs!$F$62:$I$62,Inputs!$F$63:$I$63) -> 0.03
C44: Margin | D44: % p.a. | E44: =Inputs!E52 -> 0.035 | J44: =$E44*J$6 -> 0.035 | K44: =$E44*K$6 -> 0.035 | L44: =$E44*L$6 -> 0.035 | M44: =$E44*M$6 -> 0.035 | N44: =$E44*N$6 -> 0.035 | O44: =$E44*O$6 -> 0.035 | P44: =$E44*P$6 -> 0.035 | Q44: =$E44*Q$6 -> 0.035 | ... BI44: =$E44*BI$6 -> 0
C45: All-in-rate | D45: % p.a. | J45: =SUM(J43:J44)*J6 -> 0.071 | K45: =SUM(K43:K44)*K6 -> 0.071 | L45: =SUM(L43:L44)*L6 -> 0.071 | M45: =SUM(M43:M44)*M6 -> 0.071 | N45: =SUM(N43:N44)*N6 -> 0.065 | O45: =SUM(O43:O44)*O6 -> 0.065 | P45: =SUM(P43:P44)*P6 -> 0.065 | Q45: =SUM(Q43:Q44)*Q6 -> 0.065 | ... BI45: =SUM(BI43:BI44)*BI6 -> 0
C46: All-in-rate | D46: % p.p. | J46: =(1+J45)^(J$12/Days_Year) - 1 -> 0.017248279 | K46: =(1+K45)^(K$12/Days_Year) - 1 -> 0.017248279 | L46: =(1+L45)^(L$12/Days_Year) - 1 -> 0.017439464 | M46: =(1+M45)^(M$12/Days_Year) - 1 -> 0.017439464 | N46: =(1+N45)^(N$12/Days_Year) - 1 -> 0.015649219 | O46: =(1+O45)^(O$12/Days_Year) - 1 -> 0.015824468 | P46: =(1+P45)^(P$12/Days_Year) - 1 -> 0.015999747 | Q46: =(1+Q45)^(Q$12/Days_Year) - 1 -> 0.015999747 | ... BI46: =(1+BI45)^(BI$12/Days_Year) - 1 -> 0
C48: Interest During Construction | D48: AUD M | I48: =SUM(J48:BI48) -> 3.4380986 | J48: =J35*J46 -> 0 | K48: =K35*K46 -> 0.1293621 | L48: =L35*L46 -> 0.26384797 | M48: =M35*M46 -> 0.39924532 | N48: =N35*N46 -> 0.48187788 | O48: =O35*O46 -> 0.61358319 | P48: =P35*P46 -> 0.7501948 | Q48: =Q35*Q46 -> 0.79998735 | ... BI48: =BI35*BI46 -> 0

Sheet Ops
A1: Operations & Returns
A2: =Name_Model -> Transaction Model: Funding options and testing limits
A4: =Timing!A4 -> Period Start | J4: =Timing!J4 -> 40909 | K4: =Timing!K4 -> 41000 | L4: =Timing!L4 -> 41091 | M4: =Timing!M4 -> 41183 | N4: =Timing!N4 -> 41275 | O4: =Timing!O4 -> 41365 | P4: =Timing!P4 -> 41456 | Q4: =Timing!Q4 -> 41548 | ... BI4: =Timing!BI4 -> 45566
A5: =Timing!A5 -> Period End | I5: =Timing!I5 -> 40908 | J5: =Timing!J5 -> 40999 | K5: =Timing!K5 -> 41090 | L5: =Timing!L5 -> 41182 | M5: =Timing!M5 -> 41274 | N5: =Timing!N5 -> 41364 | O5: =Timing!O5 -> 41455 | P5: =Timing!P5 -> 41547 | ... BI5: =Timing!BI5 -> 45657
A6: =Timing!A6 -> Construction | J6: =Timing!J6 -> 1 | K6: =Timing!K6 -> 1 | L6: =Timing!L6 -> 1 | M6: =Timing!M6 -> 1 | N6: =Timing!N6 -> 1 | O6: =Timing!O6 -> 1 | P6: =Timing!P6 -> 1 | Q6: =Timing!Q6 -> 1 | ... BI6: =Timing!BI6 -> 0
A7: =Timing!A7 -> Operations | J7: =Timing!J7 -> 0 | K7: =Timing!K7 -> 0 | L7: =Timing!L7 -> 0 | M7: =Timing!M7 -> 0 | N7: =Timing!N7 -> 0 | O7: =Timing!O7 -> 0 | P7: =Timing!P7 -> 0 | Q7: =Timing!Q7 -> 0 | ... BI7: =Timing!BI7 -> 0
C9: =Timing!C9 -> Counters
C10: =Timing!C12 -> Operations Year | D10: Num# | J10: =Timing!J12 -> 0 | K10: =Timing!K12 -> 0 | L10: =Timing!L12 -> 0 | M10: =Timing!M12 -> 0 | N10: =Timing!N12 -> 0 | O10: =Timing!O12 -> 0 | P10: =Timing!P12 -> 0 | Q10: =Timing!Q12 -> 0 | ... BI10: =Timing!BI12 -> 0
C11: =Timing!C13 -> Calendar Year | D11: Year | J11: =Timing!J13 -> 2012 | K11: =Timing!K13 -> 2012 | L11: =Timing!L13 -> 2012 | M11: =Timing!M13 -> 2012 | N11: =Timing!N13 -> 2013 | O11: =Timing!O13 -> 2013 | P11: =Timing!P13 -> 2013 | Q11: =Timing!Q13 -> 2013 | ... BI11: =Timing!BI13 -> 2024
C13: Revenue
C14: Volume
C15: Net Generation | D15: MWh p.q. | I15: =SUM(J15:BI15) -> 1499042.8 | J15: =IF(J$10=0,0,LOOKUP(J$10,Inputs!$E$27:$M$27,Inputs!$E$28:$M$28))/Qtrs_Yr -> 0 | K15: =IF(K$10=0,0,LOOKUP(K$10,Inputs!$E$27:$M$27,Inputs!$E$28:$M$28))/Qtrs_Yr -> 0 | L15: =IF(L$10=0,0,LOOKUP(L$10,Inputs!$E$27:$M$27,Inputs!$E$28:$M$28))/Qtrs_Yr -> 0 | M15: =IF(M$10=0,0,LOOKUP(M$10,Inputs!$E$27:$M$27,Inputs!$E$28:$M$28))/Qtrs_Yr -> 0 | N15: =IF(N$10=0,0,LOOKUP(N$10,Inputs!$E$27:$M$27,Inputs!$E$28:$M$28))/Qtrs_Yr -> 0 | O15: =IF(O$10=0,0,LOOKUP(O$10,Inputs!$E$27:$M$27,Inputs!$E$28:$M$28))/Qtrs_Yr -> 0 | P15: =IF(P$10=0,0,LOOKUP(P$10,Inputs!$E$27:$M$27,Inputs!$E$28:$M$28))/Qtrs_Yr -> 0 | Q15: =IF(Q$10=0,0,LOOKUP(Q$10,Inputs!$E$27:$M$27,Inputs!$E$28:$M$28))/Qtrs_Yr -> 0 | ... AG15: =IF(AG$10=0,0,LOOKUP(AG$10,Inputs!$E$27:$M$27,Inputs!$E$28:$M$28))/Qtrs_Yr -> 32500 | AH15: =AG15*(1+0.5%) -> 32662.5 | AI15: =AH15*(1+0.5%) -> 32825.812 | AJ15: =AI15*(1+0.5%) -> 32989.942 | AK15: =AJ15*(1+0.5%) -> 33154.891 | AL15: =AK15*(1+0.5%) -> 33320.666 | AM15: =AL15*(1+0.5%) -> 33487.269 | AN15: =AM15*(1+0.5%) -> 33654.705 | AO15: =AN15*(1+0.5%) -> 33822.979 | ... BI15: =BH15*(1+0.5%) -> 37370.86
C17: Price
C18: Market Price | D18: AUD/MWh | J18: =LOOKUP(J11,Inputs!$F$32:$I$32)*J7 -> 0 | K18: =LOOKUP(K11,Inputs!$F$32:$I$32)*K7 -> 0 | L18: =LOOKUP(L11,Inputs!$F$32:$I$32)*L7 -> 0 | M18: =LOOKUP(M11,Inputs!$F$32:$I$32)*M7 -> 0 | N18: =LOOKUP(N11,Inputs!$F$32:$I$32)*N7 -> 0 | O18: =LOOKUP(O11,Inputs!$F$32:$I$32)*O7 -> 0 | P18: =LOOKUP(P11,Inputs!$F$32:$I$32)*P7 -> 0 | Q18: =LOOKUP(Q11,Inputs!$F$32:$I$32)*Q7 -> 0 | ... BI18: =LOOKUP(BI11,Inputs!$F$32:$I$32)*BI7 -> 0
C19: Revenue | D19: AUD M | I19: =SUM(J19:BI19) -> 1.5532719e+08 | J19: =J15*J18 -> 0 | K19: =K15*K18 -> 0 | L19: =L15*L18 -> 0 | M19: =M15*M18 -> 0 | N19: =N15*N18 -> 0 | O19: =O15*O18 -> 0 | P19: =P15*P18 -> 0 | Q19: =Q15*Q18 -> 0 | ... BI19: =BI15*BI18 -> 0
C21: Operational Expense
C22: Fixed Nominal Costs
C23: =Inputs!C37 -> Labour | D23: AUD M | I23: =SUM(J23:BI23) -> 23.615591 | J23: =IF(J$10=0,0,LOOKUP(J$10,Inputs!$E$36:$N$36,Inputs!$E37:$N37)) -> 0 | K23: =IF(K$10=0,0,LOOKUP(K$10,Inputs!$E$36:$N$36,Inputs!$E37:$N37)) -> 0 | L23: =IF(L$10=0,0,LOOKUP(L$10,Inputs!$E$36:$N$36,Inputs!$E37:$N37)) -> 0 | M23: =IF(M$10=0,0,LOOKUP(M$10,Inputs!$E$36:$N$36,Inputs!$E37:$N37)) -> 0 | N23: =IF(N$10=0,0,LOOKUP(N$10,Inputs!$E$36:$N$36,Inputs!$E37:$N37)) -> 0 | O23: =IF(O$10=0,0,LOOKUP(O$10,Inputs!$E$36:$N$36,Inputs!$E37:$N37)) -> 0 | P23: =IF(P$10=0,0,LOOKUP(P$10,Inputs!$E$36:$N$36,Inputs!$E37:$N37)) -> 0 | Q23: =IF(Q$10=0,0,LOOKUP(Q$10,Inputs!$E$36:$N$36,Inputs!$E37:$N37)) -> 0 | ... BI23: =IF(BI$10=0,0,LOOKUP(BI$10,Inputs!$E$36:$N$36,Inputs!$E37:$N37)) -> 0
C24: =Inputs!C38 -> Land & Leasing | D24: AUD M | I24: =SUM(J24:BI24) -> 47.231183 | J24: =IF(J$10=0,0,LOOKUP(J$10,Inputs!$E$36:$N$36,Inputs!$E38:$N38)) -> 0 | K24: =IF(K$10=0,0,LOOKUP(K$10,Inputs!$E$36:$N$36,Inputs!$E38:$N38)) -> 0 | L24: =IF(L$10=0,0,LOOKUP(L$10,Inputs!$E$36:$N$36,Inputs!$E38:$N38)) -> 0 | M24: =IF(M$10=0,0,LOOKUP(M$10,Inputs!$E$36:$N$36,Inputs!$E38:$N38)) -> 0 | N24: =IF(N$10=0,0,LOOKUP(N$10,Inputs!$E$36:$N$36,Inputs!$E38:$N38)) -> 0 | O24: =IF(O$10=0,0,LOOKUP(O$10,Inputs!$E$36:$N$36,Inputs!$E38:$N38)) -> 0 | P24: =IF(P$10=0,0,LOOKUP(P$10,Inputs!$E$36:$N$36,Inputs!$E38:$N38)) -> 0 | Q24: =IF(Q$10=0,0,LOOKUP(Q$10,Inputs!$E$36:$N$36,Inputs!$E38:$N38)) -> 0 | ... BI24: =IF(BI$10=0,0,LOOKUP(BI$10,Inputs!$E$36:$N$36,Inputs!$E38:$N38)) -> 0
C25: =Inputs!C39 -> Spare | D25: AUD M | I25: =SUM(J25:BI25) -> 0 | J25: =IF(J$10=0,0,LOOKUP(J$10,Inputs!$E$36:$N$36,Inputs!$E39:$N39)) -> 0 | K25: =IF(K$10=0,0,LOOKUP(K$10,Inputs!$E$36:$N$36,Inputs!$E39:$N39)) -> 0 | L25: =IF(L$10=0,0,LOOKUP(L$10,Inputs!$E$36:$N$36,Inputs!$E39:$N39)) -> 0 | M25: =IF(M$10=0,0,LOOKUP(M$10,Inputs!$E$36:$N$36,Inputs!$E39:$N39)) -> 0 | N25: =IF(N$10=0,0,LOOKUP(N$10,Inputs!$E$36:$N$36,Inputs!$E39:$N39)) -> 0 | O25: =IF(O$10=0,0,LOOKUP(O$10,Inputs!$E$36:$N$36,Inputs!$E39:$N39)) -> 0 | P25: =IF(P$10=0,0,LOOKUP(P$10,Inputs!$E$36:$N$36,Inputs!$E39:$N39)) -> 0 | Q25: =IF(Q$10=0,0,LOOKUP(Q$10,Inputs!$E$36:$N$36,Inputs!$E39:$N39)) -> 0 | ... BI25: =IF(BI$10=0,0,LOOKUP(BI$10,Inputs!$E$36:$N$36,Inputs!$E39:$N39)) -> 0
C26: Total | D26: AUD M | I26: =SUM(J26:BI26) -> 70.846774 | J26: =SUM(J23:J25) -> 0 | K26: =SUM(K23:K24) -> 0 | L26: =SUM(L23:L24) -> 0 | M26: =SUM(M23:M24) -> 0 | N26: =SUM(N23:N24) -> 0 | O26: =SUM(O23:O24) -> 0 | P26: =SUM(P23:P24) -> 0 | Q26: =SUM(Q23:Q24) -> 0 | R26: =SUM(R23:R24) -> 1.545 | ... BI26: =SUM(BI23:BI24) -> 0
C28: Variable Nominal Costs
C29: Nominal Cost Price
C30: =Inputs!C43 -> Other | D30: AUD / MWh | J30: =Inputs!E43*$J7 -> 0 | K30: =Inputs!F43*$J7 -> 0 | L30: =Inputs!G43*$J7 -> 0 | M30: =Inputs!H43*$J7 -> 0 | N30: =Inputs!I43*$J7 -> 0 | O30: =Inputs!J43*$J7 -> 0 | P30: =Inputs!K43*$J7 -> 0 | Q30: =Inputs!L43*$J7 -> 0 | ... BI30: =Inputs!BD43*$J7 -> 0
C31: =Inputs!C44 -> Spare | D31: AUD / MWh | J31: =Inputs!E44*$J8 -> 0 | K31: =Inputs!F44*$J8 -> 0 | L31: =Inputs!G44*$J8 -> 0 | M31: =Inputs!H44*$J8 -> 0 | N31: =Inputs!I44*$J8 -> 0 | O31: =Inputs!J44*$J8 -> 0 | P31: =Inputs!K44*$J8 -> 0 | Q31: =Inputs!L44*$J8 -> 0 | ... BI31: =Inputs!BD44*$J8 -> 0
C32: =Inputs!C45 -> Spare | D32: AUD / MWh | J32: =Inputs!E45*$J9 -> 0 | K32: =Inputs!F45*$J9 -> 0 | L32: =Inputs!G45*$J9 -> 0 | M32: =Inputs!H45*$J9 -> 0 | N32: =Inputs!I45*$J9 -> 0 | O32: =Inputs!J45*$J9 -> 0 | P32: =Inputs!K45*$J9 -> 0 | Q32: =Inputs!L45*$J9 -> 0 | ... BI32: =Inputs!BD45*$J9 -> 0
C34: Variable Costs
C35: Net Generation | D35: MWh | J35: =J15 -> 0 | K35: =K15 -> 0 | L35: =L15 -> 0 | M35: =M15 -> 0 | N35: =N15 -> 0 | O35: =O15 -> 0 | P35: =P15 -> 0 | Q35: =Q15 -> 0 | ... BI35: =BI15 -> 37370.86
C37: =C30 -> Other | D37: AUD M | I37: =SUM(J37:BI37) -> 0 | J37: =J30*J$35/Million -> 0 | K37: =K30*K$35/Million -> 0 | L37: =L30*L$35/Million -> 0 | M37: =M30*M$35/Million -> 0 | N37: =N30*N$35/Million -> 0 | O37: =O30*O$35/Million -> 0 | P37: =P30*P$35/Million -> 0 | Q37: =Q30*Q$35/Million -> 0 | ... BI37: =BI30*BI$35/Million -> 0
C38: =C31 -> Spare | D38: AUD M | I38: =SUM(J38:BI38) -> 0 | J38: =J31*J$35/Million -> 0 | K38: =K31*K$35/Million -> 0 | L38: =L31*L$35/Million -> 0 | M38: =M31*M$35/Million -> 0 | N38: =N31*N$35/Million -> 0 | O38: =O31*O$35/Million -> 0 | P38: =P31*P$35/Million -> 0 | Q38: =Q31*Q$35/Million -> 0 | ... BI38: =BI31*BI$35/Million -> 0
C39: =C32 -> Spare | D39: AUD M | I39: =SUM(J39:BI39) -> 0 | J39: =J32*J$35 -> 0 | K39: =K32*K$35 -> 0 | L39: =L32*L$35 -> 0 | M39: =M32*M$35 -> 0 | N39: =N32*N$35 -> 0 | O39: =O32*O$35 -> 0 | P39: =P32*P$35 -> 0 | Q39: =Q32*Q$35 -> 0 | ... BI39: =BI32*BI$35 -> 0
C40: Total | D40: AUD M | I40: =SUM(J40:BI40) -> 0 | J40: =SUM(J37:J38) -> 0 | K40: =SUM(K37:K39) -> 0 | L40: =SUM(L37:L39) -> 0 | M40: =SUM(M37:M39) -> 0 | N40: =SUM(N37:N39) -> 0 | O40: =SUM(O37:O39) -> 0 | P40: =SUM(P37:P39) -> 0 | Q40: =SUM(Q37:Q39) -> 0 | R40: =SUM(R37:R39) -> 0 | ... BI40: =SUM(BI37:BI39) -> 0
C42: Summary
C43: Fixed Costs | D43: AUD M | I43: =SUM(J43:BI43) -> 70.846774 | J43: =J26 -> 0 | K43: =K26 -> 0 | L43: =L26 -> 0 | M43: =M26 -> 0 | N43: =N26 -> 0 | O43: =O26 -> 0 | P43: =P26 -> 0 | Q43: =Q26 -> 0 | ... BI43: =BI26 -> 0
C44: Variable Costs | D44: AUD M | I44: =SUM(J44:BI44) -> 0 | J44: =J40 -> 0 | K44: =K40 -> 0 | L44: =L40 -> 0 | M44: =M40 -> 0 | N44: =N40 -> 0 | O44: =O40 -> 0 | P44: =P40 -> 0 | Q44: =Q40 -> 0 | ... BI44: =BI40 -> 0
C45: Total Costs | D45: AUD M | I45: =SUM(J45:BI45) -> 70.846774 | J45: =SUM(J43:J44) -> 0 | K45: =SUM(K43:K44) -> 0 | L45: =SUM(L43:L44) -> 0 | M45: =SUM(M43:M44) -> 0 | N45: =SUM(N43:N44) -> 0 | O45: =SUM(O43:O44) -> 0 | P45: =SUM(P43:P44) -> 0 | Q45: =SUM(Q43:Q44) -> 0 | ... BI45: =SUM(BI43:BI44) -> 0
C47: Free Cash Flow to Equity
C48: Cashflow available for Equity | D48: AUD M | I48: =SUM(J48:BI48) -> 1.5532706e+08 | J48: =QCF!J40 -> 0 | K48: =QCF!K40 -> 0 | L48: =QCF!L40 -> 0 | M48: =QCF!M40 -> 0 | N48: =QCF!N40 -> 0 | O48: =QCF!O40 -> 0 | P48: =QCF!P40 -> 0 | Q48: =QCF!Q40 -> 0 | ... BI48: =QCF!BI40 -> 0
C49: Cash Balance B/f | D49: AUD M | J49: =QCF!J46 -> 0 | K49: =QCF!K46 -> 0 | L49: =QCF!L46 -> 0 | M49: =QCF!M46 -> 0 | N49: =QCF!N46 -> 0 | O49: =QCF!O46 -> 0 | P49: =QCF!P46 -> 0 | Q49: =QCF!Q46 -> 0 | ... BI49: =QCF!BI46 -> 0
C50: Free Cash Flow to Equity | D50: AUD M | I50: =SUM(J50:BI50) -> 1.5532706e+08 | J50: =MAX(J48+J49,0) -> 0 | K50: =MAX(K48+K49,0) -> 0 | L50: =MAX(L48+L49,0) -> 0 | M50: =MAX(M48+M49,0) -> 0 | N50: =MAX(N48+N49,0) -> 0 | O50: =MAX(O48+O49,0) -> 0 | P50: =MAX(P48+P49,0) -> 0 | Q50: =MAX(Q48+Q49,0) -> 0 | ... BI50: =MAX(BI48+BI49,0) -> 0
...

Sheet Debt
A1: Debt
A2: =Name_Model -> Transaction Model: Funding options and testing limits
A4: =Timing!A4 -> Period Start | J4: =Timing!J4 -> 40909 | K4: =Timing!K4 -> 41000 | L4: =Timing!L4 -> 41091 | M4: =Timing!M4 -> 41183 | N4: =Timing!N4 -> 41275 | O4: =Timing!O4 -> 41365 | P4: =Timing!P4 -> 41456 | Q4: =Timing!Q4 -> 41548 | ... BI4: =Timing!BI4 -> 45566
A5: =Timing!A5 -> Period End | I5: =Timing!I5 -> 40908 | J5: =Timing!J5 -> 40999 | K5: =Timing!K5 -> 41090 | L5: =Timing!L5 -> 41182 | M5: =Timing!M5 -> 41274 | N5: =Timing!N5 -> 41364 | O5: =Timing!O5 -> 41455 | P5: =Timing!P5 -> 41547 | ... BI5: =Timing!BI5 -> 45657
A6: =Timing!A6 -> Construction | J6: =Timing!J6 -> 1 | K6: =Timing!K6 -> 1 | L6: =Timing!L6 -> 1 | M6: =Timing!M6 -> 1 | N6: =Timing!N6 -> 1 | O6: =Timing!O6 -> 1 | P6: =Timing!P6 -> 1 | Q6: =Timing!Q6 -> 1 | ... BI6: =Timing!BI6 -> 0
A7: =Timing!A7 -> Operations | J7: =Timing!J7 -> 0 | K7: =Timing!K7 -> 0 | L7: =Timing!L7 -> 0 | M7: =Timing!M7 -> 0 | N7: =Timing!N7 -> 0 | O7: =Timing!O7 -> 0 | P7: =Timing!P7 -> 0 | Q7: =Timing!Q7 -> 0 | ... BI7: =Timing!BI7 -> 0
C9: =Timing!C9 -> Counters
C10: =Timing!C12 -> Operations Year | D10: Num# | J10: =Timing!J12 -> 0 | K10: =Timing!K12 -> 0 | L10: =Timing!L12 -> 0 | M10: =Timing!M12 -> 0 | N10: =Timing!N12 -> 0 | O10: =Timing!O12 -> 0 | P10: =Timing!P12 -> 0 | Q10: =Timing!Q12 -> 0 | ... BI10: =Timing!BI12 -> 0
C11: =Timing!C13 -> Calendar Year | D11: Year | J11: =Timing!J13 -> 2012 | K11: =Timing!K13 -> 2012 | L11: =Timing!L13 -> 2012 | M11: =Timing!M13 -> 2012 | N11: =Timing!N13 -> 2013 | O11: =Timing!O13 -> 2013 | P11: =Timing!P13 -> 2013 | Q11: =Timing!Q13 -> 2013 | ... BI11: =Timing!BI13 -> 2024
C12: =Timing!C14 -> Days in Period | D12: Days | J12: =Timing!J14 -> 91 | K12: =Timing!K14 -> 91 | L12: =Timing!L14 -> 92 | M12: =Timing!M14 -> 92 | N12: =Timing!N14 -> 90 | O12: =Timing!O14 -> 91 | P12: =Timing!P14 -> 92 | Q12: =Timing!Q14 -> 92 | ... BI12: =Timing!BI14 -> 92
C14: Debt Repayment
E15: Start | F15: End
C16: Tenor Flag | D16: [1,0] | E16: =Inputs!G55 -> 41640 | F16: =Inputs!H55 -> 43830 | J16: =IF(AND(J$4>=$E16,J$5<=$F16),1,0) -> 0 | K16: =IF(AND(K$4>=$E16,K$5<=$F16),1,0) -> 0 | L16: =IF(AND(L$4>=$E16,L$5<=$F16),1,0) -> 0 | M16: =IF(AND(M$4>=$E16,M$5<=$F16),1,0) -> 0 | N16: =IF(AND(N$4>=$E16,N$5<=$F16),1,0) -> 0 | O16: =IF(AND(O$4>=$E16,O$5<=$F16),1,0) -> 0 | P16: =IF(AND(P$4>=$E16,P$5<=$F16),1,0) -> 0 | Q16: =IF(AND(Q$4>=$E16,Q$5<=$F16),1,0) -> 0 | ... BI16: =IF(AND(BI$4>=$E16,BI$5<=$F16),1,0) -> 0
C18: Account
C19: Balance B/f | D19: AUD M | J19: =I22 -> 0 | K19: =J22 -> 0 | L19: =K22 -> 0 | M19: =L22 -> 0 | N19: =M22 -> 0 | O19: =N22 -> 0 | P19: =O22 -> 0 | Q19: =P22 -> 0 | ... BI19: =BH22 -> -3.5527137e-15
C20: Refinance from Construction | D20: AUD M | I20: =SUM(J20:BI20) -> 50 | J20: =-Cons!J37 -> 0 | K20: =-Cons!K37 -> 0 | L20: =-Cons!L37 -> 0 | M20: =-Cons!M37 -> 0 | N20: =-Cons!N37 -> 0 | O20: =-Cons!O37 -> 0 | P20: =-Cons!P37 -> 0 | Q20: =-Cons!Q37 -> 50 | ... BI20: =-Cons!BI37 -> 0
C21: Principal Repayment | D21: AUD M | I21: =SUM(J21:BI21) -> -50 | J21: =-J35 -> 0 | K21: =-K35 -> 0 | L21: =-L35 -> 0 | M21: =-M35 -> 0 | N21: =-N35 -> 0 | O21: =-O35 -> 0 | P21: =-P35 -> 0 | Q21: =-Q35 -> 0 | ... BI21: =-BI35 -> 0
C22: Balance C/f | D22: AUD M | J22: =SUM(J19:J21) -> 0 | K22: =SUM(K19:K21) -> 0 | L22: =SUM(L19:L21) -> 0 | M22: =SUM(M19:M21) -> 0 | N22: =SUM(N19:N21) -> 0 | O22: =SUM(O19:O21) -> 0 | P22: =SUM(P19:P21) -> 0 | Q22: =SUM(Q19:Q21) -> 50 | ... BI22: =SUM(BI19:BI21) -> -3.5527137e-15
C24: Interest
C25: Base Rate | D25: % p.a. | J25: =Cons!J43 -> 0.036 | K25: =Cons!K43 -> 0.036 | L25: =Cons!L43 -> 0.036 | M25: =Cons!M43 -> 0.036 | N25: =Cons!N43 -> 0.03 | O25: =Cons!O43 -> 0.03 | P25: =Cons!P43 -> 0.03 | Q25: =Cons!Q43 -> 0.03 | ... BI25: =Cons!BI43 -> 0.03
C26: Margin | D26: % p.a. | J26: =IF(J10=0,0,LOOKUP(J10,Inputs!$F$51:$I$51,Inputs!$F$52:$I$52)) -> 0 | K26: =IF(K10=0,0,LOOKUP(K10,Inputs!$F$51:$I$51,Inputs!$F$52:$I$52)) -> 0 | L26: =IF(L10=0,0,LOOKUP(L10,Inputs!$F$51:$I$51,Inputs!$F$52:$I$52)) -> 0 | M26: =IF(M10=0,0,LOOKUP(M10,Inputs!$F$51:$I$51,Inputs!$F$52:$I$52)) -> 0 | N26: =IF(N10=0,0,LOOKUP(N10,Inputs!$F$51:$I$51,Inputs!$F$52:$I$52)) -> 0 | O26: =IF(O10=0,0,LOOKUP(O10,Inputs!$F$51:$I$51,Inputs!$F$52:$I$52)) -> 0 | P26: =IF(P10=0,0,LOOKUP(P10,Inputs!$F$51:$I$51,Inputs!$F$52:$I$52)) -> 0 | Q26: =IF(Q10=0,0,LOOKUP(Q10,Inputs!$F$51:$I$51,Inputs!$F$52:$I$52)) -> 0 | ... BI26: =IF(BI10=0,0,LOOKUP(BI10,Inputs!$F$51:$I$51,Inputs!$F$52:$I$52)) -> 0
C27: All-in-Rate | D27: % p.a. | J27: =SUM(J25:J26) -> 0.036 | K27: =SUM(K25:K26) -> 0.036 | L27: =SUM(L25:L26) -> 0.036 | M27: =SUM(M25:M26) -> 0.036 | N27: =SUM(N25:N26) -> 0.03 | O27: =SUM(O25:O26) -> 0.03 | P27: =SUM(P25:P26) -> 0.03 | Q27: =SUM(Q25:Q26) -> 0.03 | ... BI27: =SUM(BI25:BI26) -> 0.03
C28: All-in-Rate | D28: % p.p. | J28: =J27/Qtrs_Yr -> 0.009 | K28: =K27/Qtrs_Yr -> 0.009 | L28: =L27/Qtrs_Yr -> 0.009 | M28: =M27/Qtrs_Yr -> 0.009 | N28: =N27/Qtrs_Yr -> 0.0075 | O28: =O27/Qtrs_Yr -> 0.0075 | P28: =P27/Qtrs_Yr -> 0.0075 | Q28: =Q27/Qtrs_Yr -> 0.0075 | ... BI28: =BI27/Qtrs_Yr -> 0.0075
C30: Interest During Operations | D30: AUD M | I30: =SUM(J30:BI30) -> 8.546875 | J30: =J19*J28*J16 -> 0 | K30: =K19*K28*K16 -> 0 | L30: =L19*L28*L16 -> 0 | M30: =M19*M28*M16 -> 0 | N30: =N19*N28*N16 -> 0 | O30: =O19*O28*O16 -> 0 | P30: =P19*P28*P16 -> 0 | Q30: =Q19*Q28*Q16 -> 0 | ... BI30: =BI19*BI28*BI16 -> 0
C32: Repayment
C33: Linear
C34: Principal repayment (annualised) | D34: % p.a. | E34: =Inputs!E58 -> 0.16666667 | I34: =SUM(J34:BI34) -> 200 | J34: =$I$20*$E34*J16 -> 0 | K34: =$I$20*$E34*K16 -> 0 | L34: =$I$20*$E34*L16 -> 0 | M34: =$I$20*$E34*M16 -> 0 | N34: =$I$20*$E34*N16 -> 0 | O34: =$I$20*$E34*O16 -> 0 | P34: =$I$20*$E34*P16 -> 0 | Q34: =$I$20*$E34*Q16 -> 0 | ... BI34: =$I$20*$E34*BI16 -> 0
C35: Principal repayment | D35: % p.q. | I35: =SUM(J35:BI35) -> 50 | J35: =J34/Qtrs_Yr -> 0 | K35: =K34/Qtrs_Yr -> 0 | L35: =L34/Qtrs_Yr -> 0 | M35: =M34/Qtrs_Yr -> 0 | N35: =N34/Qtrs_Yr -> 0 | O35: =O34/Qtrs_Yr -> 0 | P35: =P34/Qtrs_Yr -> 0 | Q35: =Q34/Qtrs_Yr -> 0 | ... BI35: =BI34/Qtrs_Yr -> 0
C37: Debt Ratios
C38: Debt Service Cover Ratio (DSCR)
C39: CFADS | D39: AUD M | I39: =SUM(J39:BI39) -> 90380618 | J39: =QCF!J33*J16 -> 0 | K39: =QCF!K33*K16 -> 0 | L39: =QCF!L33*L16 -> 0 | M39: =QCF!M33*M16 -> 0 | N39: =QCF!N33*N16 -> 0 | O39: =QCF!O33*O16 -> 0 | P39: =QCF!P33*P16 -> 0 | Q39: =QCF!Q33*Q16 -> 0 | ... BI39: =QCF!BI33*BI16 -> 0
C41: Interest | D41: AUD M | I41: =SUM(J41:BI41) -> 8.546875 | J41: =J30 -> 0 | K41: =K30 -> 0 | L41: =L30 -> 0 | M41: =M30 -> 0 | N41: =N30 -> 0 | O41: =O30 -> 0 | P41: =P30 -> 0 | Q41: =Q30 -> 0 | ... BI41: =BI30 -> 0
C42: Principal | D42: AUD M | I42: =SUM(J42:BI42) -> 50 | J42: =J35 -> 0 | K42: =K35 -> 0 | L42: =L35 -> 0 | M42: =M35 -> 0 | N42: =N35 -> 0 | O42: =O35 -> 0 | P42: =P35 -> 0 | Q42: =Q35 -> 0 | ... BI42: =BI35 -> 0
C43: Total Debt Service | D43: AUD M | I43: =SUM(J43:BI43) -> 58.546875 | J43: =SUM(J41:J42) -> 0 | K43: =SUM(K41:K42) -> 0 | L43: =SUM(L41:L42) -> 0 | M43: =SUM(M41:M42) -> 0 | N43: =SUM(N41:N42) -> 0 | O43: =SUM(O41:O42) -> 0 | P43: =SUM(P41:P42) -> 0 | Q43: =SUM(Q41:Q42) -> 0 | ... BI43: =SUM(BI41:BI42) -> 0
E44: Min | F44: Average
C45: DSCR | D45: x | E45: {=MIN(IF(J16:BI16=1,J45:BI45))} -> 1354984.3 | F45: =IF(I43=0,0,I39/I43) -> 1543730.9 | J45: =IF(J19>0,J39/J43,0) -> 0 | K45: =IF(K19>0,K39/K43,0) -> 0 | L45: =IF(L19>0,L39/L43,0) -> 0 | M45: =IF(M19>0,M39/M43,0) -> 0 | N45: =IF(N19>0,N39/N43,0) -> 0 | O45: =IF(O19>0,O39/O43,0) -> 0 | P45: =IF(P19>0,P39/P43,0) -> 0 | Q45: =IF(Q19>0,Q39/Q43,0) -> 0 | ... BI45: =IF(BI19>0,BI39/BI43,0) -> 0

Sheet Timing
A1: Timing
A2: =Name_Model -> Transaction Model: Funding options and testing limits
A4: Period Start | J4: =I5+1 -> 40909 | K4: =J5+1 -> 41000 | L4: =K5+1 -> 41091 | M4: =L5+1 -> 41183 | N4: =M5+1 -> 41275 | O4: =N5+1 -> 41365 | P4: =O5+1 -> 41456 | Q4: =P5+1 -> 41548 | ... BI4: =BH5+1 -> 45566
A5: Period End | I5: =Model_Start -> 40908 | J5: =EOMONTH(J4,Months_Qtr-1) -> 40999 | K5: =EOMONTH(K4,Months_Qtr-1) -> 41090 | L5: =EOMONTH(L4,Months_Qtr-1) -> 41182 | M5: =EOMONTH(M4,Months_Qtr-1) -> 41274 | N5: =EOMONTH(N4,Months_Qtr-1) -> 41364 | O5: =EOMONTH(O4,Months_Qtr-1) -> 41455 | P5: =EOMONTH(P4,Months_Qtr-1) -> 41547 | Q5: =EOMONTH(Q4,Months_Qtr-1) -> 41639 | ... BI5: =EOMONTH(BI4,Months_Qtr-1) -> 45657
A6: Construction | E6: =Inputs!E9 -> 40909 | F6: =Inputs!E11 -> 41639 | J6: =IF(AND(J$4>=$E6,J$5<=$F6),1,0) -> 1 | K6: =IF(AND(K$4>=$E6,K$5<=$F6),1,0) -> 1 | L6: =IF(AND(L$4>=$E6,L$5<=$F6),1,0) -> 1 | M6: =IF(AND(M$4>=$E6,M$5<=$F6),1,0) -> 1 | N6: =IF(AND(N$4>=$E6,N$5<=$F6),1,0) -> 1 | O6: =IF(AND(O$4>=$E6,O$5<=$F6),1,0) -> 1 | P6: =IF(AND(P$4>=$E6,P$5<=$F6),1,0) -> 1 | Q6: =IF(AND(Q$4>=$E6,Q$5<=$F6),1,0) -> 1 | ... BI6: =IF(AND(BI$4>=$E6,BI$5<=$F6),1,0) -> 0
A7: Operations | E7: =Inputs!E14 -> 41640 | F7: =Inputs!E16 -> 45291 | J7: =IF(AND(J$4>=$E7,J$5<=$F7),1,0) -> 0 | K7: =IF(AND(K$4>=$E7,K$5<=$F7),1,0) -> 0 | L7: =IF(AND(L$4>=$E7,L$5<=$F7),1,0) -> 0 | M7: =IF(AND(M$4>=$E7,M$5<=$F7),1,0) -> 0 | N7: =IF(AND(N$4>=$E7,N$5<=$F7),1,0) -> 0 | O7: =IF(AND(O$4>=$E7,O$5<=$F7),1,0) -> 0 | P7: =IF(AND(P$4>=$E7,P$5<=$F7),1,0) -> 0 | Q7: =IF(AND(Q$4>=$E7,Q$5<=$F7),1,0) -> 0 | ... BI7: =IF(AND(BI$4>=$E7,BI$5<=$F7),1,0) -> 0
C9: Counters
C10: Construction Quarters | D10: Num# | J10: =SUM($J6:J6)*J6 -> 1 | K10: =SUM($J6:K6)*K6 -> 2 | L10: =SUM($J6:L6)*L6 -> 3 | M10: =SUM($J6:M6)*M6 -> 4 | N10: =SUM($J6:N6)*N6 -> 5 | O10: =SUM($J6:O6)*O6 -> 6 | P10: =SUM($J6:P6)*P6 -> 7 | Q10: =SUM($J6:Q6)*Q6 -> 8 | ... BI10: =SUM($J6:BI6)*BI6 -> 0
C11: Operations Quarters | D11: Num# | J11: =SUM($J7:J7)*J7 -> 0 | K11: =SUM($J7:K7)*K7 -> 0 | L11: =SUM($J7:L7)*L7 -> 0 | M11: =SUM($J7:M7)*M7 -> 0 | N11: =SUM($J7:N7)*N7 -> 0 | O11: =SUM($J7:O7)*O7 -> 0 | P11: =SUM($J7:P7)*P7 -> 0 | Q11: =SUM($J7:Q7)*Q7 -> 0 | ... BI11: =SUM($J7:BI7)*BI7 -> 0
C12: Operations Year | D12: Num# | J12: =ROUNDUP(J11/Qtrs_Yr, 0) -> 0 | K12: =ROUNDUP(K11/Qtrs_Yr, 0) -> 0 | L12: =ROUNDUP(L11/Qtrs_Yr, 0) -> 0 | M12: =ROUNDUP(M11/Qtrs_Yr, 0) -> 0 | N12: =ROUNDUP(N11/Qtrs_Yr, 0) -> 0 | O12: =ROUNDUP(O11/Qtrs_Yr, 0) -> 0 | P12: =ROUNDUP(P11/Qtrs_Yr, 0) -> 0 | Q12: =ROUNDUP(Q11/Qtrs_Yr, 0) -> 0 | ... BI12: =ROUNDUP(BI11/Qtrs_Yr, 0) -> 0
C13: Calendar Year | D13: Year | J13: =YEAR(J5) -> 2012 | K13: =YEAR(K5) -> 2012 | L13: =YEAR(L5) -> 2012 | M13: =YEAR(M5) -> 2012 | N13: =YEAR(N5) -> 2013 | O13: =YEAR(O5) -> 2013 | P13: =YEAR(P5) -> 2013 | Q13: =YEAR(Q5) -> 2013 | ... BI13: =YEAR(BI5) -> 2024
C14: Days in Period | D14: Days | J14: =J5-J4+1 -> 91 | K14: =K5-K4+1 -> 91 | L14: =L5-L4+1 -> 92 | M14: =M5-M4+1 -> 92 | N14: =N5-N4+1 -> 90 | O14: =O5-O4+1 -> 91 | P14: =P5-P4+1 -> 92 | Q14: =Q5-Q4+1 -> 92 | ... BI14: =BI5-BI4+1 -> 92

Sheet L&N
A1: Formatting Legend, Names & Constants
A2: =Name_Model -> Transaction Model: Funding options and testing limits
C4: Formatting Styles
C5: Formatting of Headers / Dividers | G5: Infrastructure
C6: Header0 | E6: Header 0 | G6: Line_Summary | I6: 100
C7: Header1 | E7: Header 1
C8: Header2 | E8: Header 2 | G8: Unit | I8: USD
C9: Header3 | E9: Header 3
G10: Line_Operation | I10: 100
C11: Table_Heading | E11: Table Heading
G12: Line_Total | I12: 100
C13: Individual Cell Assumptions
C14: Assumptions | E14: 100 | G14: Line_ClosingBal | I14: 100
C16: Offsheet | E16: 100 | G16: Line_Key | I16: 100
C18: Assumption_Flex | E18: 100
C20: Input | E20: 1000
C22: Empty_Cell
C24: Technical Inputs
C25: Entity Names
C26: Name Course | E26: Preparation and Ownership fo Financial Models
C27: Model Name | E27: Transaction Model: Funding options and testing limits
C29: Constants
C30: Days in Year | E30: 365
C31: Months per Year | E31: 12
C32: Quarters per Year | E32: 4
C33: Months per Quarter | E33: 3
C35: Million | E35: 1000000
