Workbook

Sheet Inputs
A1: FINANCIAL MODEL INPUTS
A3: MODEL ASSUMPTIONS & DRIVERS
A5: Timeline
A6: Number of Periods (Months) | B6: 12
A9: REVENUE ASSUMPTIONS
A10: Month 1 Revenue | B10: 100000
A11: Monthly Revenue Growth % | B11: 0.05
A13: COST OF GOODS SOLD
A14: COGS % of Revenue | B14: 0.4
A16: OPERATING EXPENSES
A17: Sales & Marketing (Monthly) | B17: 15000
A18: General & Admin (Monthly) | B18: 20000
A20: WORKING CAPITAL ASSUMPTIONS
A21: AR Collection Period (Days) | B21: 45
A22: Inventory Days on Hand | B22: 60
A23: AP Payment Period (Days) | B23: 30
A24: Prepayments (% of Monthly OpEx) | B24: 0.1
A25: Accrued Expenses (% of Monthly OpEx) | B25: 0.15
A26: Deferred Revenue (% of Monthly Revenue) | B26: 0.2
A28: FIXED ASSETS
A29: Opening PP&E (Gross) | B29: 500000
A30: Opening Accumulated Depreciation | B30: 100000
A31: Monthly Capex | B31: 10000
A32: Depreciation Rate (Annual %) | B32: 0.2
A34: DEBT
A35: Opening Debt Balance | B35: 200000
A36: Interest Rate (Annual %) | B36: 0.06
A37: Monthly Principal Repayment | B37: 5000
A39: EQUITY
A40: Opening Share Capital | B40: 300000
A41: Opening Retained Earnings | B41: 150000
A43: CASH
A44: Opening Cash Balance | B44: 200000
A46: TAX
A47: Corporate Tax Rate % | B47: 0.25

Sheet Workings
A1: CONTROL ACCOUNTS - WORKINGS
A3: Period | B3: Jan-25 | C3: Feb-25 | D3: Mar-25 | E3: Apr-25 | F3: May-25 | G3: Jun-25 | H3: Jul-25 | I3: Aug-25 | J3: Sep-25 | K3: Oct-25 | L3: Nov-25 | M3: Dec-25
A5: REVENUE & COGS DRIVERS
A6: Revenue (Credit Sales) | B6: =Inputs!$B$10 | C6: =B6*(1+Inputs!$B$11) | D6: =C6*(1+Inputs!$B$11) | E6: =D6*(1+Inputs!$B$11) | F6: =E6*(1+Inputs!$B$11) | G6: =F6*(1+Inputs!$B$11) | H6: =G6*(1+Inputs!$B$11) | I6: =H6*(1+Inputs!$B$11) | J6: =I6*(1+Inputs!$B$11) | ... M6: =L6*(1+Inputs!$B$11)
A7: Cost of Goods Sold | B7: =B6*Inputs!$B$15 | C7: =C6*Inputs!$B$15 | D7: =D6*Inputs!$B$15 | E7: =E6*Inputs!$B$15 | F7: =F6*Inputs!$B$15 | G7: =G6*Inputs!$B$15 | H7: =H6*Inputs!$B$15 | I7: =I6*Inputs!$B$15 | ... M7: =M6*Inputs!$B$15
A8: Inventory Purchases | B8: =B7*1.1 | C8: =C7*1.1 | D8: =D7*1.1 | E8: =E7*1.1 | F8: =F7*1.1 | G8: =G7*1.1 | H8: =H7*1.1 | I8: =I7*1.1 | ... M8: =M7*1.1
A10: ACCOUNTS RECEIVABLE CONTROL
A11: Opening Balance | B11: =Inputs!$B$10*Inputs!$B$21/30 | C11: =B14 | D11: =C14 | E11: =D14 | F11: =E14 | G11: =F14 | H11: =G14 | I11: =H14 | J11: =I14 | ... M11: =L14
A12: + Credit Sales | B12: =B6 | C12: =C6 | D12: =D6 | E12: =E6 | F12: =F6 | G12: =G6 | H12: =H6 | I12: =I6 | ... M12: =M6
A13: - Cash Collections | B13: =B11*30/Inputs!$B$21 | C13: =C11*30/Inputs!$B$21 | D13: =D11*30/Inputs!$B$21 | E13: =E11*30/Inputs!$B$21 | F13: =F11*30/Inputs!$B$21 | G13: =G11*30/Inputs!$B$21 | H13: =H11*30/Inputs!$B$21 | I13: =I11*30/Inputs!$B$21 | ... M13: =M11*30/Inputs!$B$21
A14: Closing Balance | B14: =B11+B12-B13 | C14: =C11+C12-C13 | D14: =D11+D12-D13 | E14: =E11+E12-E13 | F14: =F11+F12-F13 | G14: =G11+G12-G13 | H14: =H11+H12-H13 | I14: =I11+I12-I13 | ... M14: =M11+M12-M13
A16: INVENTORY CONTROL
A17: Opening Balance | B17: =Inputs!$B$15*Inputs!$B$10*Inputs!$B$22/30 | C17: =B20 | D17: =C20 | E17: =D20 | F17: =E20 | G17: =F20 | H17: =G20 | I17: =H20 | J17: =I20 | ... M17: =L20
A18: + Purchases | B18: =B8 | C18: =C8 | D18: =D8 | E18: =E8 | F18: =F8 | G18: =G8 | H18: =H8 | I18: =I8 | ... M18: =M8
A19: - COGS Withdrawal | B19: =B7 | C19: =C7 | D19: =D7 | E19: =E7 | F19: =F7 | G19: =G7 | H19: =H7 | I19: =I7 | ... M19: =M7
A20: Closing Balance | B20: =B17+B18-B19 | C20: =C17+C18-C19 | D20: =D17+D18-D19 | E20: =E17+E18-E19 | F20: =F17+F18-F19 | G20: =G17+G18-G19 | H20: =H17+H18-H19 | I20: =I17+I18-I19 | ... M20: =M17+M18-M19
A22: PREPAYMENTS CONTROL
A23: Opening Balance | B23: =(Inputs!$B$17+Inputs!$B$18)*Inputs!$B$24 | C23: =B26 | D23: =C26 | E23: =D26 | F23: =E26 | G23: =F26 | H23: =G26 | I23: =H26 | J23: =I26 | ... M23: =L26
A24: + Cash Prepayments | B24: =(Inputs!$B$17+Inputs!$B$18)*Inputs!$B$24 | C24: =(Inputs!$B$17+Inputs!$B$18)*Inputs!$B$24 | D24: =(Inputs!$B$17+Inputs!$B$18)*Inputs!$B$24 | E24: =(Inputs!$B$17+Inputs!$B$18)*Inputs!$B$24 | F24: =(Inputs!$B$17+Inputs!$B$18)*Inputs!$B$24 | G24: =(Inputs!$B$17+Inputs!$B$18)*Inputs!$B$24 | H24: =(Inputs!$B$17+Inputs!$B$18)*Inputs!$B$24 | I24: =(Inputs!$B$17+Inputs!$B$18)*Inputs!$B$24 | ... M24: =(Inputs!$B$17+Inputs!$B$18)*Inputs!$B$24
A25: - Expensed to P&L | B25: =(Inputs!$B$17+Inputs!$B$18)*Inputs!$B$24 | C25: =(Inputs!$B$17+Inputs!$B$18)*Inputs!$B$24 | D25: =(Inputs!$B$17+Inputs!$B$18)*Inputs!$B$24 | E25: =(Inputs!$B$17+Inputs!$B$18)*Inputs!$B$24 | F25: =(Inputs!$B$17+Inputs!$B$18)*Inputs!$B$24 | G25: =(Inputs!$B$17+Inputs!$B$18)*Inputs!$B$24 | H25: =(Inputs!$B$17+Inputs!$B$18)*Inputs!$B$24 | I25: =(Inputs!$B$17+Inputs!$B$18)*Inputs!$B$24 | ... M25: =(Inputs!$B$17+Inputs!$B$18)*Inputs!$B$24
A26: Closing Balance | B26: =B23+B24-B25 | C26: =C23+C24-C25 | D26: =D23+D24-D25 | E26: =E23+E24-E25 | F26: =F23+F24-F25 | G26: =G23+G24-G25 | H26: =H23+H24-H25 | I26: =I23+I24-I25 | ... M26: =M23+M24-M25
A28: ACCOUNTS PAYABLE CONTROL
A29: Opening Balance | B29: =B8*Inputs!$B$23/30 | C29: =B32 | D29: =C32 | E29: =D32 | F29: =E32 | G29: =F32 | H29: =G32 | I29: =H32 | J29: =I32 | ... M29: =L32
A30: + Credit Purchases | B30: =B8 | C30: =C8 | D30: =D8 | E30: =E8 | F30: =F8 | G30: =G8 | H30: =H8 | I30: =I8 | ... M30: =M8
A31: - Cash Payments | B31: =B29*30/Inputs!$B$23 | C31: =C29*30/Inputs!$B$23 | D31: =D29*30/Inputs!$B$23 | E31: =E29*30/Inputs!$B$23 | F31: =F29*30/Inputs!$B$23 | G31: =G29*30/Inputs!$B$23 | H31: =H29*30/Inputs!$B$23 | I31: =I29*30/Inputs!$B$23 | ... M31: =M29*30/Inputs!$B$23
A32: Closing Balance | B32: =B29+B30-B31 | C32: =C29+C30-C31 | D32: =D29+D30-D31 | E32: =E29+E30-E31 | F32: =F29+F30-F31 | G32: =G29+G30-G31 | H32: =H29+H30-H31 | I32: =I29+I30-I31 | ... M32: =M29+M30-M31
A34: ACCRUED EXPENSES CONTROL
A35: Opening Balance | B35: =(Inputs!$B$17+Inputs!$B$18)*Inputs!$B$25 | C35: =B38 | D35: =C38 | E35: =D38 | F35: =E38 | G35: =F38 | H35: =G38 | I35: =H38 | J35: =I38 | ... M35: =L38
A36: + Expenses Accrued | B36: =(Inputs!$B$17+Inputs!$B$18)*Inputs!$B$25 | C36: =(Inputs!$B$17+Inputs!$B$18)*Inputs!$B$25 | D36: =(Inputs!$B$17+Inputs!$B$18)*Inputs!$B$25 | E36: =(Inputs!$B$17+Inputs!$B$18)*Inputs!$B$25 | F36: =(Inputs!$B$17+Inputs!$B$18)*Inputs!$B$25 | G36: =(Inputs!$B$17+Inputs!$B$18)*Inputs!$B$25 | H36: =(Inputs!$B$17+Inputs!$B$18)*Inputs!$B$25 | I36: =(Inputs!$B$17+Inputs!$B$18)*Inputs!$B$25 | ... M36: =(Inputs!$B$17+Inputs!$B$18)*Inputs!$B$25
A37: - Cash Payments | B37: =(Inputs!$B$17+Inputs!$B$18)*Inputs!$B$25 | C37: =(Inputs!$B$17+Inputs!$B$18)*Inputs!$B$25 | D37: =(Inputs!$B$17+Inputs!$B$18)*Inputs!$B$25 | E37: =(Inputs!$B$17+Inputs!$B$18)*Inputs!$B$25 | F37: =(Inputs!$B$17+Inputs!$B$18)*Inputs!$B$25 | G37: =(Inputs!$B$17+Inputs!$B$18)*Inputs!$B$25 | H37: =(Inputs!$B$17+Inputs!$B$18)*Inputs!$B$25 | I37: =(Inputs!$B$17+Inputs!$B$18)*Inputs!$B$25 | ... M37: =(Inputs!$B$17+Inputs!$B$18)*Inputs!$B$25
A38: Closing Balance | B38: =B35+B36-B37 | C38: =C35+C36-C37 | D38: =D35+D36-D37 | E38: =E35+E36-E37 | F38: =F35+F36-F37 | G38: =G35+G36-G37 | H38: =H35+H36-H37 | I38: =I35+I36-I37 | ... M38: =M35+M36-M37
A40: DEFERRED REVENUE CONTROL
A41: Opening Balance | B41: =Inputs!$B$10*Inputs!$B$26 | C41: =B44 | D41: =C44 | E41: =D44 | F41: =E44 | G41: =F44 | H41: =G44 | I41: =H44 | J41: =I44 | ... M41: =L44
A42: + Cash Received in Advance | B42: =B6*Inputs!$B$26 | C42: =C6*Inputs!$B$26 | D42: =D6*Inputs!$B$26 | E42: =E6*Inputs!$B$26 | F42: =F6*Inputs!$B$26 | G42: =G6*Inputs!$B$26 | H42: =H6*Inputs!$B$26 | I42: =I6*Inputs!$B$26 | ... M42: =M6*Inputs!$B$26
A43: - Revenue Recognized | B43: =B6*Inputs!$B$26 | C43: =C6*Inputs!$B$26 | D43: =D6*Inputs!$B$26 | E43: =E6*Inputs!$B$26 | F43: =F6*Inputs!$B$26 | G43: =G6*Inputs!$B$26 | H43: =H6*Inputs!$B$26 | I43: =I6*Inputs!$B$26 | ... M43: =M6*Inputs!$B$26
A44: Closing Balance | B44: =B41+B42-B43 | C44: =C41+C42-C43 | D44: =D41+D42-D43 | E44: =E41+E42-E43 | F44: =F41+F42-F43 | G44: =G41+G42-G43 | H44: =H41+H42-H43 | I44: =I41+I42-I43 | ... M44: =M41+M42-M43
A46: PP&E GROSS CONTROL
A47: Opening Balance | B47: =Inputs!$B$30 | C47: =B50 | D47: =C50 | E47: =D50 | F47: =E50 | G47: =F50 | H47: =G50 | I47: =H50 | J47: =I50 | ... M47: =L50
A48: + Capital Expenditure | B48: =Inputs!$B$32 | C48: =Inputs!$B$32 | D48: =Inputs!$B$32 | E48: =Inputs!$B$32 | F48: =Inputs!$B$32 | G48: =Inputs!$B$32 | H48: =Inputs!$B$32 | I48: =Inputs!$B$32 | ... M48: =Inputs!$B$32
A49: - Disposals | B49: 0 | C49: 0 | D49: 0 | E49: 0 | F49: 0 | G49: 0 | H49: 0 | I49: 0 | J49: 0 | K49: 0 | L49: 0 | M49: 0
...

Sheet Income Statement
A1: INCOME STATEMENT
A3: Period | B3: Jan-25 | C3: Feb-25 | D3: Mar-25 | E3: Apr-25 | F3: May-25 | G3: Jun-25 | H3: Jul-25 | I3: Aug-25 | J3: Sep-25 | K3: Oct-25 | L3: Nov-25 | M3: Dec-25
A5: Revenue | B5: =Workings!B6 | C5: =Workings!C6 | D5: =Workings!D6 | E5: =Workings!E6 | F5: =Workings!F6 | G5: =Workings!G6 | H5: =Workings!H6 | I5: =Workings!I6 | ... M5: =Workings!M6
A6: Cost of Goods Sold | B6: =-Workings!B7 | C6: =-Workings!C7 | D6: =-Workings!D7 | E6: =-Workings!E7 | F6: =-Workings!F7 | G6: =-Workings!G7 | H6: =-Workings!H7 | I6: =-Workings!I7 | ... M6: =-Workings!M7
A7: Gross Profit | B7: =B5+B6 | C7: =C5+C6 | D7: =D5+D6 | E7: =E5+E6 | F7: =F5+F6 | G7: =G5+G6 | H7: =H5+H6 | I7: =I5+I6 | ... M7: =M5+M6
A9: Operating Expenses:
A10: Sales & Marketing | B10: =-Inputs!$B$17 | C10: =-Inputs!$B$17 | D10: =-Inputs!$B$17 | E10: =-Inputs!$B$17 | F10: =-Inputs!$B$17 | G10: =-Inputs!$B$17 | H10: =-Inputs!$B$17 | I10: =-Inputs!$B$17 | ... M10: =-Inputs!$B$17
A11: General & Administrative | B11: =-Inputs!$B$18 | C11: =-Inputs!$B$18 | D11: =-Inputs!$B$18 | E11: =-Inputs!$B$18 | F11: =-Inputs!$B$18 | G11: =-Inputs!$B$18 | H11: =-Inputs!$B$18 | I11: =-Inputs!$B$18 | ... M11: =-Inputs!$B$18
A12: Depreciation | B12: =-Workings!B54 | C12: =-Workings!C54 | D12: =-Workings!D54 | E12: =-Workings!E54 | F12: =-Workings!F54 | G12: =-Workings!G54 | H12: =-Workings!H54 | I12: =-Workings!I54 | ... M12: =-Workings!M54
A13: EBIT | B13: =B7+B10+B11+B12 | C13: =C7+C10+C11+C12 | D13: =D7+D10+D11+D12 | E13: =E7+E10+E11+E12 | F13: =F7+F10+F11+F12 | G13: =G7+G10+G11+G12 | H13: =H7+H10+H11+H12 | I13: =I7+I10+I11+I12 | ... M13: =M7+M10+M11+M12
A15: Interest Expense | B15: =-Workings!B64 | C15: =-Workings!C64 | D15: =-Workings!D64 | E15: =-Workings!E64 | F15: =-Workings!F64 | G15: =-Workings!G64 | H15: =-Workings!H64 | I15: =-Workings!I64 | ... M15: =-Workings!M64
A16: Earnings Before Tax | B16: =B14+B15 | C16: =C14+C15 | D16: =D14+D15 | E16: =E14+E15 | F16: =F14+F15 | G16: =G14+G15 | H16: =H14+H15 | I16: =I14+I15 | ... M16: =M14+M15
A18: Income Tax | B18: =-MAX(B17,0)*Inputs!$B$50 | C18: =-MAX(C17,0)*Inputs!$B$50 | D18: =-MAX(D17,0)*Inputs!$B$50 | E18: =-MAX(E17,0)*Inputs!$B$50 | F18: =-MAX(F17,0)*Inputs!$B$50 | G18: =-MAX(G17,0)*Inputs!$B$50 | H18: =-MAX(H17,0)*Inputs!$B$50 | I18: =-MAX(I17,0)*Inputs!$B$50 | ... M18: =-MAX(M17,0)*Inputs!$B$50
A19: Net Income | B19: =B17+B18 | C19: =C17+C18 | D19: =D17+D18 | E19: =E17+E18 | F19: =F17+F18 | G19: =G17+G18 | H19: =H17+H18 | I19: =I17+I18 | ... M19: =M17+M18

Sheet Balance Sheet
A1: BALANCE SHEET
A3: Period | B3: Jan-25 | C3: Feb-25 | D3: Mar-25 | E3: Apr-25 | F3: May-25 | G3: Jun-25 | H3: Jul-25 | I3: Aug-25 | J3: Sep-25 | K3: Oct-25 | L3: Nov-25 | M3: Dec-25
A5: ASSETS
A6: Current Assets:
A7: Cash | B7: =Workings!B80 | C7: =Workings!C80 | D7: =Workings!D80 | E7: =Workings!E80 | F7: =Workings!F80 | G7: =Workings!G80 | H7: =Workings!H80 | I7: =Workings!I80 | ... M7: =Workings!M80
A8: Accounts Receivable | B8: =Workings!B14 | C8: =Workings!C14 | D8: =Workings!D14 | E8: =Workings!E14 | F8: =Workings!F14 | G8: =Workings!G14 | H8: =Workings!H14 | I8: =Workings!I14 | ... M8: =Workings!M14
A9: Inventory | B9: =Workings!B20 | C9: =Workings!C20 | D9: =Workings!D20 | E9: =Workings!E20 | F9: =Workings!F20 | G9: =Workings!G20 | H9: =Workings!H20 | I9: =Workings!I20 | ... M9: =Workings!M20
A10: Prepayments | B10: =Workings!B26 | C10: =Workings!C26 | D10: =Workings!D26 | E10: =Workings!E26 | F10: =Workings!F26 | G10: =Workings!G26 | H10: =Workings!H26 | I10: =Workings!I26 | ... M10: =Workings!M26
A11: Total Current Assets | B11: =SUM(B7:B10) | C11: =SUM(C7:C10) | D11: =SUM(D7:D10) | E11: =SUM(E7:E10) | F11: =SUM(F7:F10) | G11: =SUM(G7:G10) | H11: =SUM(H7:H10) | I11: =SUM(I7:I10) | ... M11: =SUM(M7:M10)
A13: Fixed Assets:
A14: PP&E (Gross) | B14: =Workings!B50 | C14: =Workings!C50 | D14: =Workings!D50 | E14: =Workings!E50 | F14: =Workings!F50 | G14: =Workings!G50 | H14: =Workings!H50 | I14: =Workings!I50 | ... M14: =Workings!M50
A15: Less: Accumulated Depreciation | B15: =-Workings!B56 | C15: =-Workings!C56 | D15: =-Workings!D56 | E15: =-Workings!E56 | F15: =-Workings!F56 | G15: =-Workings!G56 | H15: =-Workings!H56 | I15: =-Workings!I56 | ... M15: =-Workings!M56
A16: Net PP&E | B16: =B14+B15 | C16: =C14+C15 | D16: =D14+D15 | E16: =E14+E15 | F16: =F14+F15 | G16: =G14+G15 | H16: =H14+H15 | I16: =I14+I15 | ... M16: =M14+M15
A18: TOTAL ASSETS | B18: =B11+B16 | C18: =C11+C16 | D18: =D11+D16 | E18: =E11+E16 | F18: =F11+F16 | G18: =G11+G16 | H18: =H11+H16 | I18: =I11+I16 | ... M18: =M11+M16
A20: LIABILITIES
A21: Current Liabilities:
A22: Accounts Payable | B22: =Workings!B32 | C22: =Workings!C32 | D22: =Workings!D32 | E22: =Workings!E32 | F22: =Workings!F32 | G22: =Workings!G32 | H22: =Workings!H32 | I22: =Workings!I32 | ... M22: =Workings!M32
A23: Accrued Expenses | B23: =Workings!B38 | C23: =Workings!C38 | D23: =Workings!D38 | E23: =Workings!E38 | F23: =Workings!F38 | G23: =Workings!G38 | H23: =Workings!H38 | I23: =Workings!I38 | ... M23: =Workings!M38
A24: Deferred Revenue | B24: =Workings!B44 | C24: =Workings!C44 | D24: =Workings!D44 | E24: =Workings!E44 | F24: =Workings!F44 | G24: =Workings!G44 | H24: =Workings!H44 | I24: =Workings!I44 | ... M24: =Workings!M44
A25: Total Current Liabilities | B25: =SUM(B22:B24) | C25: =SUM(C22:C24) | D25: =SUM(D22:D24) | E25: =SUM(E22:E24) | F25: =SUM(F22:F24) | G25: =SUM(G22:G24) | H25: =SUM(H22:H24) | I25: =SUM(I22:I24) | ... M25: =SUM(M22:M24)
A27: Long-term Liabilities:
A28: Long-term Debt | B28: =Workings!B62 | C28: =Workings!C62 | D28: =Workings!D62 | E28: =Workings!E62 | F28: =Workings!F62 | G28: =Workings!G62 | H28: =Workings!H62 | I28: =Workings!I62 | ... M28: =Workings!M62
A29: Total Long-term Liabilities | B29: =B28 | C29: =C28 | D29: =D28 | E29: =E28 | F29: =F28 | G29: =G28 | H29: =H28 | I29: =I28 | ... M29: =M28
A31: TOTAL LIABILITIES | B31: =B25+B29 | C31: =C25+C29 | D31: =D25+D29 | E31: =E25+E29 | F31: =F25+F29 | G31: =G25+G29 | H31: =H25+H29 | I31: =I25+I29 | ... M31: =M25+M29
A33: EQUITY
A34: Share Capital | B34: =Workings!B70 | C34: =Workings!C70 | D34: =Workings!D70 | E34: =Workings!E70 | F34: =Workings!F70 | G34: =Workings!G70 | H34: =Workings!H70 | I34: =Workings!I70 | ... M34: =Workings!M70
A35: Retained Earnings | B35: =Workings!B76 | C35: =Workings!C76 | D35: =Workings!D76 | E35: =Workings!E76 | F35: =Workings!F76 | G35: =Workings!G76 | H35: =Workings!H76 | I35: =Workings!I76 | ... M35: =Workings!M76
A36: TOTAL EQUITY | B36: =SUM(B34:B35) | C36: =SUM(C34:C35) | D36: =SUM(D34:D35) | E36: =SUM(E34:E35) | F36: =SUM(F34:F35) | G36: =SUM(G34:G35) | H36: =SUM(H34:H35) | I36: =SUM(I34:I35) | ... M36: =SUM(M34:M35)
A38: TOTAL LIABILITIES & EQUITY | B38: =B31+B36 | C38: =C31+C36 | D38: =D31+D36 | E38: =E31+E36 | F38: =F31+F36 | G38: =G31+G36 | H38: =H31+H36 | I38: =I31+I36 | ... M38: =M31+M36
A40: BALANCE CHECK (Should be 0) | B40: =B18-B38 | C40: =C18-C38 | D40: =D18-D38 | E40: =E18-E38 | F40: =F18-F38 | G40: =G18-G38 | H40: =H18-H38 | I40: =I18-I38 | ... M40: =M18-M38

Sheet Cash Flow Statement
A1: CASH FLOW STATEMENT (Indirect Method)
A3: Period | B3: Jan-25 | C3: Feb-25 | D3: Mar-25 | E3: Apr-25 | F3: May-25 | G3: Jun-25 | H3: Jul-25 | I3: Aug-25 | J3: Sep-25 | K3: Oct-25 | L3: Nov-25 | M3: Dec-25
A5: OPERATING ACTIVITIES
A6: Net Income | B6: ='Income Statement'!B19 | C6: ='Income Statement'!C19 | D6: ='Income Statement'!D19 | E6: ='Income Statement'!E19 | F6: ='Income Statement'!F19 | G6: ='Income Statement'!G19 | H6: ='Income Statement'!H19 | I6: ='Income Statement'!I19 | ... M6: ='Income Statement'!M19
A7: Adjustments:
A8: + Depreciation | B8: =Workings!B54 | C8: =Workings!C54 | D8: =Workings!D54 | E8: =Workings!E54 | F8: =Workings!F54 | G8: =Workings!G54 | H8: =Workings!H54 | I8: =Workings!I54 | ... M8: =Workings!M54
A9: Changes in Working Capital:
A10: - Increase in AR | B10: =-(Workings!B14-Workings!B11) | C10: =-(Workings!C14-Workings!B14) | D10: =-(Workings!D14-Workings!C14) | E10: =-(Workings!E14-Workings!D14) | F10: =-(Workings!F14-Workings!E14) | G10: =-(Workings!G14-Workings!F14) | H10: =-(Workings!H14-Workings!G14) | I10: =-(Workings!I14-Workings!H14) | J10: =-(Workings!J14-Workings!I14) | ... M10: =-(Workings!M14-Workings!L14)
A11: - Increase in Inventory | B11: =-(Workings!B20-Workings!B17) | C11: =-(Workings!C20-Workings!B20) | D11: =-(Workings!D20-Workings!C20) | E11: =-(Workings!E20-Workings!D20) | F11: =-(Workings!F20-Workings!E20) | G11: =-(Workings!G20-Workings!F20) | H11: =-(Workings!H20-Workings!G20) | I11: =-(Workings!I20-Workings!H20) | J11: =-(Workings!J20-Workings!I20) | ... M11: =-(Workings!M20-Workings!L20)
A12: - Increase in Prepayments | B12: =-(Workings!B26-Workings!B23) | C12: =-(Workings!C26-Workings!B26) | D12: =-(Workings!D26-Workings!C26) | E12: =-(Workings!E26-Workings!D26) | F12: =-(Workings!F26-Workings!E26) | G12: =-(Workings!G26-Workings!F26) | H12: =-(Workings!H26-Workings!G26) | I12: =-(Workings!I26-Workings!H26) | J12: =-(Workings!J26-Workings!I26) | ... M12: =-(Workings!M26-Workings!L26)
A13: + Increase in AP | B13: =Workings!B32-Workings!B29 | C13: =Workings!C32-Workings!B32 | D13: =Workings!D32-Workings!C32 | E13: =Workings!E32-Workings!D32 | F13: =Workings!F32-Workings!E32 | G13: =Workings!G32-Workings!F32 | H13: =Workings!H32-Workings!G32 | I13: =Workings!I32-Workings!H32 | J13: =Workings!J32-Workings!I32 | ... M13: =Workings!M32-Workings!L32
A14: + Increase in Accrued Expenses | B14: =Workings!B38-Workings!B35 | C14: =Workings!C38-Workings!B38 | D14: =Workings!D38-Workings!C38 | E14: =Workings!E38-Workings!D38 | F14: =Workings!F38-Workings!E38 | G14: =Workings!G38-Workings!F38 | H14: =Workings!H38-Workings!G38 | I14: =Workings!I38-Workings!H38 | J14: =Workings!J38-Workings!I38 | ... M14: =Workings!M38-Workings!L38
A15: + Increase in Deferred Revenue | B15: =Workings!B44-Workings!B41 | C15: =Workings!C44-Workings!B44 | D15: =Workings!D44-Workings!C44 | E15: =Workings!E44-Workings!D44 | F15: =Workings!F44-Workings!E44 | G15: =Workings!G44-Workings!F44 | H15: =Workings!H44-Workings!G44 | I15: =Workings!I44-Workings!H44 | J15: =Workings!J44-Workings!I44 | ... M15: =Workings!M44-Workings!L44
A16: Cash from Operating Activities | B16: =B6+B8+SUM(B10:B15) | C16: =C6+C8+SUM(C10:C15) | D16: =D6+D8+SUM(D10:D15) | E16: =E6+E8+SUM(E10:E15) | F16: =F6+F8+SUM(F10:F15) | G16: =G6+G8+SUM(G10:G15) | H16: =H6+H8+SUM(H10:H15) | I16: =I6+I8+SUM(I10:I15) | ... M16: =M6+M8+SUM(M10:M15)
A18: INVESTING ACTIVITIES
A19: Capital Expenditure | B19: =-Workings!B48 | C19: =-Workings!C48 | D19: =-Workings!D48 | E19: =-Workings!E48 | F19: =-Workings!F48 | G19: =-Workings!G48 | H19: =-Workings!H48 | I19: =-Workings!I48 | ... M19: =-Workings!M48
A20: Cash from Investing Activities | B20: =B19 | C20: =C19 | D20: =D19 | E20: =E19 | F20: =F19 | G20: =G19 | H20: =H19 | I20: =I19 | ... M20: =M19
A22: FINANCING ACTIVITIES
A23: Debt Repayments | B23: =-Workings!B61 | C23: =-Workings!C61 | D23: =-Workings!D61 | E23: =-Workings!E61 | F23: =-Workings!F61 | G23: =-Workings!G61 | H23: =-Workings!H61 | I23: =-Workings!I61 | ... M23: =-Workings!M61
A24: Dividends Paid | B24: 0 | C24: 0 | D24: 0 | E24: 0 | F24: 0 | G24: 0 | H24: 0 | I24: 0 | J24: 0 | K24: 0 | L24: 0 | M24: 0
A25: Cash from Financing Activities | B25: =SUM(B23:B24) | C25: =SUM(C23:C24) | D25: =SUM(D23:D24) | E25: =SUM(E23:E24) | F25: =SUM(F23:F24) | G25: =SUM(G23:G24) | H25: =SUM(H23:H24) | I25: =SUM(I23:I24) | ... M25: =SUM(M23:M24)
A27: Net Change in Cash | B27: =B16+B20+B25 | C27: =C16+C20+C25 | D27: =D16+D20+D25 | E27: =E16+E20+E25 | F27: =F16+F20+F25 | G27: =G16+G20+G25 | H27: =H16+H20+H25 | I27: =I16+I20+I25 | ... M27: =M16+M20+M25
A29: Opening Cash | B29: =Workings!B79 | C29: =Workings!C79 | D29: =Workings!D79 | E29: =Workings!E79 | F29: =Workings!F79 | G29: =Workings!G79 | H29: =Workings!H79 | I29: =Workings!I79 | ... M29: =Workings!M79
A30: Closing Cash | B30: =B29+B27 | C30: =C29+C27 | D30: =D29+D27 | E30: =E29+E27 | F30: =F29+F27 | G30: =G29+G27 | H30: =H29+H27 | I30: =I29+I27 | ... M30: =M29+M27
A32: Check vs Balance Sheet (Should be 0) | B32: =B30-'Balance Sheet'!B7 | C32: =C30-'Balance Sheet'!C7 | D32: =D30-'Balance Sheet'!D7 | E32: =E30-'Balance Sheet'!E7 | F32: =F30-'Balance Sheet'!F7 | G32: =G30-'Balance Sheet'!G7 | H32: =H30-'Balance Sheet'!H7 | I32: =I30-'Balance Sheet'!I7 | ... M32: =M30-'Balance Sheet'!M7
