Workbook

Sheet 01_Control
A1: MODEL CONTROL PANEL
A3: Model Scenario Selector (1=Base, 2=High Cost, 3=Aggressive) | B3: 1
A5: Global Rates & Statutory Assumptions
A6: GST Rate | B6: 0.1
A7: Corporate Tax Rate | B7: 0.3
A8: Payroll Tax Rate | B8: 0.0485
A9: Superannuation Rate | B9: 0.115
A11: Australian Excise Rates (ATO)
A12: Packaged Beer (>1.15% ABV) / LAL | B12: 60.22
A13: Draught Beer (>1.15% ABV) / LAL | B13: 40.5

Sheet 02_Inputs_Sales
A1: SALES & PRICING INPUTS
A3: Monthly Seasonality Indices
B4: Month 1 | C4: Month 2 | D4: Month 3 | E4: Month 4 | F4: Month 5 | G4: Month 6 | H4: Month 7 | I4: Month 8 | J4: Month 9 | K4: Month 10 | L4: Month 11 | M4: Month 12
B5: 1.2 | C5: 1.15 | D5: 0.9 | E5: 0.8 | F5: 0.75 | G5: 0.85 | H5: 0.95 | I5: 1.05 | J5: 1.1 | K5: 1.25 | L5: 1.35 | M5: 1.45
A6: SKU Performance Assumptions
A8: SKU Name | B8: ABV | C8: On-Trade Price/HL | D8: Off-Trade Price/HL | E8: On-Trade % | F8: Base Vol HL/m
A9: Lager - Premium | B9: 0.042 | C9: 520 | D9: 440 | E9: 0.35 | F9: 1200
A10: Lager - Mid Strength | B10: 0.035 | C10: 480 | D10: 410 | E10: 0.25 | F10: 1000
A11: Pale Ale - Pacific | B11: 0.048 | C11: 560 | D11: 480 | E11: 0.4 | F11: 800
A12: Pale Ale - West Coast | B12: 0.056 | C12: 590 | D12: 510 | E12: 0.45 | F12: 600
A13: IPA - Hazy | B13: 0.062 | C13: 650 | D13: 570 | E13: 0.55 | F13: 400
A14: IPA - Double | B14: 0.075 | C14: 850 | D14: 750 | E14: 0.6 | F14: 150
A15: Stout - Oatmeal | B15: 0.052 | C15: 610 | D15: 530 | E15: 0.3 | F15: 250
A16: Summer Ale | B16: 0.04 | C16: 530 | D16: 460 | E16: 0.5 | F16: 500
A17: Winter Porter | B17: 0.06 | C17: 620 | D17: 540 | E17: 0.4 | F17: 300

Sheet 03_Inputs_Ops
A1: OPERATIONAL & COGS INPUTS
A3: Bill of Materials (per HL)
B4: Malt (kg) | C4: Hops (g) | D4: Packaging Units | E4: Water/Utils ($)
A5: Lager - Premium | B5: 16 | C5: 150 | D5: 303 | E5: 12
A6: Lager - Mid Strength | B6: 14 | C6: 120 | D6: 303 | E6: 11
A7: Pale Ale - Pacific | B7: 19 | C7: 450 | D7: 303 | E7: 14
A8: Pale Ale - West Coast | B8: 21 | C8: 600 | D8: 303 | E8: 15
A9: IPA - Hazy | B9: 24 | C9: 900 | D9: 303 | E9: 18
A10: IPA - Double | B10: 28 | C10: 1200 | D10: 303 | E10: 20
A11: Stout - Oatmeal | B11: 25 | C11: 300 | D11: 303 | E11: 16
A12: Summer Ale | B12: 17 | C12: 400 | D12: 303 | E12: 13
A13: Winter Porter | B13: 26 | C13: 350 | D13: 303 | E13: 17
A15: Unit Cost Inputs
A16: Malt ($/kg) | B16: 1.35
A17: Hops ($/kg) | B17: 52
A18: Packaging ($/unit) | B18: 0.58
A21: Labor & Salaries
A23: Department | B23: Headcount | C23: Avg Salary ($k)
A24: Brewing | B24: 5 | C24: 95
A25: Packaging | B25: 6 | C25: 70
A26: Quality/Lab | B26: 2 | C26: 105
A27: Sales/Marketing | B27: 8 | C27: 110
A28: Admin/Finance | B28: 4 | C28: 125

Sheet 04_Calcs_Volume
B3: M1 | C3: M2 | D3: M3 | E3: M4 | F3: M5 | G3: M6 | H3: M7 | I3: M8 | J3: M9 | K3: M10 | L3: M11 | M3: M12 | N3: M13 | O3: M14 | P3: M15 | Q3: M16 | R3: M17 | S3: M18 | T3: M19 | U3: M20 | V3: M21 | W3: M22 | X3: M23 | Y3: M24 | Z3: M25 | AA3: M26 | AB3: M27 | AC3: M28 | AD3: M29 | AE3: M30 | AF3: M31 | AG3: M32 | AH3: M33 | AI3: M34 | AJ3: M35 | AK3: M36 | AL3: M37 | AM3: M38 | AN3: M39 | AO3: M40 | AP3: M41 | AQ3: M42 | AR3: M43 | AS3: M44 | AT3: M45 | AU3: M46 | AV3: M47 | AW3: M48 | AX3: M49 | AY3: M50 | AZ3: M51 | BA3: M52 | BB3: M53 | BC3: M54 | BD3: M55 | BE3: M56 | BF3: M57 | BG3: M58 | BH3: M59 | BI3: M60
A6: Lager - Premium | B6: ='02_Inputs_Sales'!F9 * '02_Inputs_Sales'!B5 * (1.005^0) -> 0 | C6: ='02_Inputs_Sales'!F9 * '02_Inputs_Sales'!C5 * (1.005^1) -> 0 | D6: ='02_Inputs_Sales'!F9 * '02_Inputs_Sales'!D5 * (1.005^2) -> 0 | E6: ='02_Inputs_Sales'!F9 * '02_Inputs_Sales'!E5 * (1.005^3) -> 0 | F6: ='02_Inputs_Sales'!F9 * '02_Inputs_Sales'!F5 * (1.005^4) -> 0 | G6: ='02_Inputs_Sales'!F9 * '02_Inputs_Sales'!G5 * (1.005^5) -> 0 | H6: ='02_Inputs_Sales'!F9 * '02_Inputs_Sales'!H5 * (1.005^6) -> 0 | I6: ='02_Inputs_Sales'!F9 * '02_Inputs_Sales'!I5 * (1.005^7) -> 0 | J6: ='02_Inputs_Sales'!F9 * '02_Inputs_Sales'!J5 * (1.005^8) -> 0 | K6: ='02_Inputs_Sales'!F9 * '02_Inputs_Sales'!K5 * (1.005^9) -> 0 | L6: ='02_Inputs_Sales'!F9 * '02_Inputs_Sales'!L5 * (1.005^10) -> 0 | M6: ='02_Inputs_Sales'!F9 * '02_Inputs_Sales'!M5 * (1.005^11) -> 0 | N6: ='02_Inputs_Sales'!F9 * '02_Inputs_Sales'!B5 * (1.005^12) -> 0 | O6: ='02_Inputs_Sales'!F9 * '02_Inputs_Sales'!C5 * (1.005^13) -> 0 | P6: ='02_Inputs_Sales'!F9 * '02_Inputs_Sales'!D5 * (1.005^14) -> 0 | Q6: ='02_Inputs_Sales'!F9 * '02_Inputs_Sales'!E5 * (1.005^15) -> 0 | R6: ='02_Inputs_Sales'!F9 * '02_Inputs_Sales'!F5 * (1.005^16) -> 0 | S6: ='02_Inputs_Sales'!F9 * '02_Inputs_Sales'!G5 * (1.005^17) -> 0 | T6: ='02_Inputs_Sales'!F9 * '02_Inputs_Sales'!H5 * (1.005^18) -> 0 | U6: ='02_Inputs_Sales'!F9 * '02_Inputs_Sales'!I5 * (1.005^19) -> 0 | V6: ='02_Inputs_Sales'!F9 * '02_Inputs_Sales'!J5 * (1.005^20) -> 0 | W6: ='02_Inputs_Sales'!F9 * '02_Inputs_Sales'!K5 * (1.005^21) -> 0 | X6: ='02_Inputs_Sales'!F9 * '02_Inputs_Sales'!L5 * (1.005^22) -> 0 | Y6: ='02_Inputs_Sales'!F9 * '02_Inputs_Sales'!M5 * (1.005^23) -> 0 | Z6: ='02_Inputs_Sales'!F9 * '02_Inputs_Sales'!B5 * (1.005^24) -> 0 | AA6: ='02_Inputs_Sales'!F9 * '02_Inputs_Sales'!C5 * (1.005^25) -> 0 | AB6: ='02_Inputs_Sales'!F9 * '02_Inputs_Sales'!D5 * (1.005^26) -> 0 | AC6: ='02_Inputs_Sales'!F9 * '02_Inputs_Sales'!E5 * (1.005^27) -> 0 | AD6: ='02_Inputs_Sales'!F9 * '02_Inputs_Sales'!F5 * (1.005^28) -> 0 | AE6: ='02_Inputs_Sales'!F9 * '02_Inputs_Sales'!G5 * (1.005^29) -> 0 | AF6: ='02_Inputs_Sales'!F9 * '02_Inputs_Sales'!H5 * (1.005^30) -> 0 | AG6: ='02_Inputs_Sales'!F9 * '02_Inputs_Sales'!I5 * (1.005^31) -> 0 | AH6: ='02_Inputs_Sales'!F9 * '02_Inputs_Sales'!J5 * (1.005^32) -> 0 | AI6: ='02_Inputs_Sales'!F9 * '02_Inputs_Sales'!K5 * (1.005^33) -> 0 | AJ6: ='02_Inputs_Sales'!F9 * '02_Inputs_Sales'!L5 * (1.005^34) -> 0 | AK6: ='02_Inputs_Sales'!F9 * '02_Inputs_Sales'!M5 * (1.005^35) -> 0 | AL6: ='02_Inputs_Sales'!F9 * '02_Inputs_Sales'!B5 * (1.005^36) -> 0 | AM6: ='02_Inputs_Sales'!F9 * '02_Inputs_Sales'!C5 * (1.005^37) -> 0 | AN6: ='02_Inputs_Sales'!F9 * '02_Inputs_Sales'!D5 * (1.005^38) -> 0 | AO6: ='02_Inputs_Sales'!F9 * '02_Inputs_Sales'!E5 * (1.005^39) -> 0 | AP6: ='02_Inputs_Sales'!F9 * '02_Inputs_Sales'!F5 * (1.005^40) -> 0 | AQ6: ='02_Inputs_Sales'!F9 * '02_Inputs_Sales'!G5 * (1.005^41) -> 0 | AR6: ='02_Inputs_Sales'!F9 * '02_Inputs_Sales'!H5 * (1.005^42) -> 0 | AS6: ='02_Inputs_Sales'!F9 * '02_Inputs_Sales'!I5 * (1.005^43) -> 0 | AT6: ='02_Inputs_Sales'!F9 * '02_Inputs_Sales'!J5 * (1.005^44) -> 0 | AU6: ='02_Inputs_Sales'!F9 * '02_Inputs_Sales'!K5 * (1.005^45) -> 0 | AV6: ='02_Inputs_Sales'!F9 * '02_Inputs_Sales'!L5 * (1.005^46) -> 0 | AW6: ='02_Inputs_Sales'!F9 * '02_Inputs_Sales'!M5 * (1.005^47) -> 0 | AX6: ='02_Inputs_Sales'!F9 * '02_Inputs_Sales'!B5 * (1.005^48) -> 0 | AY6: ='02_Inputs_Sales'!F9 * '02_Inputs_Sales'!C5 * (1.005^49) -> 0 | AZ6: ='02_Inputs_Sales'!F9 * '02_Inputs_Sales'!D5 * (1.005^50) -> 0 | BA6: ='02_Inputs_Sales'!F9 * '02_Inputs_Sales'!E5 * (1.005^51) -> 0 | BB6: ='02_Inputs_Sales'!F9 * '02_Inputs_Sales'!F5 * (1.005^52) -> 0 | BC6: ='02_Inputs_Sales'!F9 * '02_Inputs_Sales'!G5 * (1.005^53) -> 0 | BD6: ='02_Inputs_Sales'!F9 * '02_Inputs_Sales'!H5 * (1.005^54) -> 0 | BE6: ='02_Inputs_Sales'!F9 * '02_Inputs_Sales'!I5 * (1.005^55) -> 0 | BF6: ='02_Inputs_Sales'!F9 * '02_Inputs_Sales'!J5 * (1.005^56) -> 0 | BG6: ='02_Inputs_Sales'!F9 * '02_Inputs_Sales'!K5 * (1.005^57) -> 0 | BH6: ='02_Inputs_Sales'!F9 * '02_Inputs_Sales'!L5 * (1.005^58) -> 0 | BI6: ='02_Inputs_Sales'!F9 * '02_Inputs_Sales'!M5 * (1.005^59) -> 0
A7: Lager - Mid Strength | B7: ='02_Inputs_Sales'!F10 * '02_Inputs_Sales'!B5 * (1.005^0) -> 0 | C7: ='02_Inputs_Sales'!F10 * '02_Inputs_Sales'!C5 * (1.005^1) -> 0 | D7: ='02_Inputs_Sales'!F10 * '02_Inputs_Sales'!D5 * (1.005^2) -> 0 | E7: ='02_Inputs_Sales'!F10 * '02_Inputs_Sales'!E5 * (1.005^3) -> 0 | F7: ='02_Inputs_Sales'!F10 * '02_Inputs_Sales'!F5 * (1.005^4) -> 0 | G7: ='02_Inputs_Sales'!F10 * '02_Inputs_Sales'!G5 * (1.005^5) -> 0 | H7: ='02_Inputs_Sales'!F10 * '02_Inputs_Sales'!H5 * (1.005^6) -> 0 | I7: ='02_Inputs_Sales'!F10 * '02_Inputs_Sales'!I5 * (1.005^7) -> 0 | J7: ='02_Inputs_Sales'!F10 * '02_Inputs_Sales'!J5 * (1.005^8) -> 0 | K7: ='02_Inputs_Sales'!F10 * '02_Inputs_Sales'!K5 * (1.005^9) -> 0 | L7: ='02_Inputs_Sales'!F10 * '02_Inputs_Sales'!L5 * (1.005^10) -> 0 | M7: ='02_Inputs_Sales'!F10 * '02_Inputs_Sales'!M5 * (1.005^11) -> 0 | N7: ='02_Inputs_Sales'!F10 * '02_Inputs_Sales'!B5 * (1.005^12) -> 0 | O7: ='02_Inputs_Sales'!F10 * '02_Inputs_Sales'!C5 * (1.005^13) -> 0 | P7: ='02_Inputs_Sales'!F10 * '02_Inputs_Sales'!D5 * (1.005^14) -> 0 | Q7: ='02_Inputs_Sales'!F10 * '02_Inputs_Sales'!E5 * (1.005^15) -> 0 | R7: ='02_Inputs_Sales'!F10 * '02_Inputs_Sales'!F5 * (1.005^16) -> 0 | S7: ='02_Inputs_Sales'!F10 * '02_Inputs_Sales'!G5 * (1.005^17) -> 0 | T7: ='02_Inputs_Sales'!F10 * '02_Inputs_Sales'!H5 * (1.005^18) -> 0 | U7: ='02_Inputs_Sales'!F10 * '02_Inputs_Sales'!I5 * (1.005^19) -> 0 | V7: ='02_Inputs_Sales'!F10 * '02_Inputs_Sales'!J5 * (1.005^20) -> 0 | W7: ='02_Inputs_Sales'!F10 * '02_Inputs_Sales'!K5 * (1.005^21) -> 0 | X7: ='02_Inputs_Sales'!F10 * '02_Inputs_Sales'!L5 * (1.005^22) -> 0 | Y7: ='02_Inputs_Sales'!F10 * '02_Inputs_Sales'!M5 * (1.005^23) -> 0 | Z7: ='02_Inputs_Sales'!F10 * '02_Inputs_Sales'!B5 * (1.005^24) -> 0 | AA7: ='02_Inputs_Sales'!F10 * '02_Inputs_Sales'!C5 * (1.005^25) -> 0 | AB7: ='02_Inputs_Sales'!F10 * '02_Inputs_Sales'!D5 * (1.005^26) -> 0 | AC7: ='02_Inputs_Sales'!F10 * '02_Inputs_Sales'!E5 * (1.005^27) -> 0 | AD7: ='02_Inputs_Sales'!F10 * '02_Inputs_Sales'!F5 * (1.005^28) -> 0 | AE7: ='02_Inputs_Sales'!F10 * '02_Inputs_Sales'!G5 * (1.005^29) -> 0 | AF7: ='02_Inputs_Sales'!F10 * '02_Inputs_Sales'!H5 * (1.005^30) -> 0 | AG7: ='02_Inputs_Sales'!F10 * '02_Inputs_Sales'!I5 * (1.005^31) -> 0 | AH7: ='02_Inputs_Sales'!F10 * '02_Inputs_Sales'!J5 * (1.005^32) -> 0 | AI7: ='02_Inputs_Sales'!F10 * '02_Inputs_Sales'!K5 * (1.005^33) -> 0 | AJ7: ='02_Inputs_Sales'!F10 * '02_Inputs_Sales'!L5 * (1.005^34) -> 0 | AK7: ='02_Inputs_Sales'!F10 * '02_Inputs_Sales'!M5 * (1.005^35) -> 0 | AL7: ='02_Inputs_Sales'!F10 * '02_Inputs_Sales'!B5 * (1.005^36) -> 0 | AM7: ='02_Inputs_Sales'!F10 * '02_Inputs_Sales'!C5 * (1.005^37) -> 0 | AN7: ='02_Inputs_Sales'!F10 * '02_Inputs_Sales'!D5 * (1.005^38) -> 0 | AO7: ='02_Inputs_Sales'!F10 * '02_Inputs_Sales'!E5 * (1.005^39) -> 0 | AP7: ='02_Inputs_Sales'!F10 * '02_Inputs_Sales'!F5 * (1.005^40) -> 0 | AQ7: ='02_Inputs_Sales'!F10 * '02_Inputs_Sales'!G5 * (1.005^41) -> 0 | AR7: ='02_Inputs_Sales'!F10 * '02_Inputs_Sales'!H5 * (1.005^42) -> 0 | AS7: ='02_Inputs_Sales'!F10 * '02_Inputs_Sales'!I5 * (1.005^43) -> 0 | AT7: ='02_Inputs_Sales'!F10 * '02_Inputs_Sales'!J5 * (1.005^44) -> 0 | AU7: ='02_Inputs_Sales'!F10 * '02_Inputs_Sales'!K5 * (1.005^45) -> 0 | AV7: ='02_Inputs_Sales'!F10 * '02_Inputs_Sales'!L5 * (1.005^46) -> 0 | AW7: ='02_Inputs_Sales'!F10 * '02_Inputs_Sales'!M5 * (1.005^47) -> 0 | AX7: ='02_Inputs_Sales'!F10 * '02_Inputs_Sales'!B5 * (1.005^48) -> 0 | AY7: ='02_Inputs_Sales'!F10 * '02_Inputs_Sales'!C5 * (1.005^49) -> 0 | AZ7: ='02_Inputs_Sales'!F10 * '02_Inputs_Sales'!D5 * (1.005^50) -> 0 | BA7: ='02_Inputs_Sales'!F10 * '02_Inputs_Sales'!E5 * (1.005^51) -> 0 | BB7: ='02_Inputs_Sales'!F10 * '02_Inputs_Sales'!F5 * (1.005^52) -> 0 | BC7: ='02_Inputs_Sales'!F10 * '02_Inputs_Sales'!G5 * (1.005^53) -> 0 | BD7: ='02_Inputs_Sales'!F10 * '02_Inputs_Sales'!H5 * (1.005^54) -> 0 | BE7: ='02_Inputs_Sales'!F10 * '02_Inputs_Sales'!I5 * (1.005^55) -> 0 | BF7: ='02_Inputs_Sales'!F10 * '02_Inputs_Sales'!J5 * (1.005^56) -> 0 | BG7: ='02_Inputs_Sales'!F10 * '02_Inputs_Sales'!K5 * (1.005^57) -> 0 | BH7: ='02_Inputs_Sales'!F10 * '02_Inputs_Sales'!L5 * (1.005^58) -> 0 | BI7: ='02_Inputs_Sales'!F10 * '02_Inputs_Sales'!M5 * (1.005^59) -> 0
A8: Pale Ale - Pacific | B8: ='02_Inputs_Sales'!F11 * '02_Inputs_Sales'!B5 * (1.005^0) -> 0 | C8: ='02_Inputs_Sales'!F11 * '02_Inputs_Sales'!C5 * (1.005^1) -> 0 | D8: ='02_Inputs_Sales'!F11 * '02_Inputs_Sales'!D5 * (1.005^2) -> 0 | E8: ='02_Inputs_Sales'!F11 * '02_Inputs_Sales'!E5 * (1.005^3) -> 0 | F8: ='02_Inputs_Sales'!F11 * '02_Inputs_Sales'!F5 * (1.005^4) -> 0 | G8: ='02_Inputs_Sales'!F11 * '02_Inputs_Sales'!G5 * (1.005^5) -> 0 | H8: ='02_Inputs_Sales'!F11 * '02_Inputs_Sales'!H5 * (1.005^6) -> 0 | I8: ='02_Inputs_Sales'!F11 * '02_Inputs_Sales'!I5 * (1.005^7) -> 0 | J8: ='02_Inputs_Sales'!F11 * '02_Inputs_Sales'!J5 * (1.005^8) -> 0 | K8: ='02_Inputs_Sales'!F11 * '02_Inputs_Sales'!K5 * (1.005^9) -> 0 | L8: ='02_Inputs_Sales'!F11 * '02_Inputs_Sales'!L5 * (1.005^10) -> 0 | M8: ='02_Inputs_Sales'!F11 * '02_Inputs_Sales'!M5 * (1.005^11) -> 0 | N8: ='02_Inputs_Sales'!F11 * '02_Inputs_Sales'!B5 * (1.005^12) -> 0 | O8: ='02_Inputs_Sales'!F11 * '02_Inputs_Sales'!C5 * (1.005^13) -> 0 | P8: ='02_Inputs_Sales'!F11 * '02_Inputs_Sales'!D5 * (1.005^14) -> 0 | Q8: ='02_Inputs_Sales'!F11 * '02_Inputs_Sales'!E5 * (1.005^15) -> 0 | R8: ='02_Inputs_Sales'!F11 * '02_Inputs_Sales'!F5 * (1.005^16) -> 0 | S8: ='02_Inputs_Sales'!F11 * '02_Inputs_Sales'!G5 * (1.005^17) -> 0 | T8: ='02_Inputs_Sales'!F11 * '02_Inputs_Sales'!H5 * (1.005^18) -> 0 | U8: ='02_Inputs_Sales'!F11 * '02_Inputs_Sales'!I5 * (1.005^19) -> 0 | V8: ='02_Inputs_Sales'!F11 * '02_Inputs_Sales'!J5 * (1.005^20) -> 0 | W8: ='02_Inputs_Sales'!F11 * '02_Inputs_Sales'!K5 * (1.005^21) -> 0 | X8: ='02_Inputs_Sales'!F11 * '02_Inputs_Sales'!L5 * (1.005^22) -> 0 | Y8: ='02_Inputs_Sales'!F11 * '02_Inputs_Sales'!M5 * (1.005^23) -> 0 | Z8: ='02_Inputs_Sales'!F11 * '02_Inputs_Sales'!B5 * (1.005^24) -> 0 | AA8: ='02_Inputs_Sales'!F11 * '02_Inputs_Sales'!C5 * (1.005^25) -> 0 | AB8: ='02_Inputs_Sales'!F11 * '02_Inputs_Sales'!D5 * (1.005^26) -> 0 | AC8: ='02_Inputs_Sales'!F11 * '02_Inputs_Sales'!E5 * (1.005^27) -> 0 | AD8: ='02_Inputs_Sales'!F11 * '02_Inputs_Sales'!F5 * (1.005^28) -> 0 | AE8: ='02_Inputs_Sales'!F11 * '02_Inputs_Sales'!G5 * (1.005^29) -> 0 | AF8: ='02_Inputs_Sales'!F11 * '02_Inputs_Sales'!H5 * (1.005^30) -> 0 | AG8: ='02_Inputs_Sales'!F11 * '02_Inputs_Sales'!I5 * (1.005^31) -> 0 | AH8: ='02_Inputs_Sales'!F11 * '02_Inputs_Sales'!J5 * (1.005^32) -> 0 | AI8: ='02_Inputs_Sales'!F11 * '02_Inputs_Sales'!K5 * (1.005^33) -> 0 | AJ8: ='02_Inputs_Sales'!F11 * '02_Inputs_Sales'!L5 * (1.005^34) -> 0 | AK8: ='02_Inputs_Sales'!F11 * '02_Inputs_Sales'!M5 * (1.005^35) -> 0 | AL8: ='02_Inputs_Sales'!F11 * '02_Inputs_Sales'!B5 * (1.005^36) -> 0 | AM8: ='02_Inputs_Sales'!F11 * '02_Inputs_Sales'!C5 * (1.005^37) -> 0 | AN8: ='02_Inputs_Sales'!F11 * '02_Inputs_Sales'!D5 * (1.005^38) -> 0 | AO8: ='02_Inputs_Sales'!F11 * '02_Inputs_Sales'!E5 * (1.005^39) -> 0 | AP8: ='02_Inputs_Sales'!F11 * '02_Inputs_Sales'!F5 * (1.005^40) -> 0 | AQ8: ='02_Inputs_Sales'!F11 * '02_Inputs_Sales'!G5 * (1.005^41) -> 0 | AR8: ='02_Inputs_Sales'!F11 * '02_Inputs_Sales'!H5 * (1.005^42) -> 0 | AS8: ='02_Inputs_Sales'!F11 * '02_Inputs_Sales'!I5 * (1.005^43) -> 0 | AT8: ='02_Inputs_Sales'!F11 * '02_Inputs_Sales'!J5 * (1.005^44) -> 0 | AU8: ='02_Inputs_Sales'!F11 * '02_Inputs_Sales'!K5 * (1.005^45) -> 0 | AV8: ='02_Inputs_Sales'!F11 * '02_Inputs_Sales'!L5 * (1.005^46) -> 0 | AW8: ='02_Inputs_Sales'!F11 * '02_Inputs_Sales'!M5 * (1.005^47) -> 0 | AX8: ='02_Inputs_Sales'!F11 * '02_Inputs_Sales'!B5 * (1.005^48) -> 0 | AY8: ='02_Inputs_Sales'!F11 * '02_Inputs_Sales'!C5 * (1.005^49) -> 0 | AZ8: ='02_Inputs_Sales'!F11 * '02_Inputs_Sales'!D5 * (1.005^50) -> 0 | BA8: ='02_Inputs_Sales'!F11 * '02_Inputs_Sales'!E5 * (1.005^51) -> 0 | BB8: ='02_Inputs_Sales'!F11 * '02_Inputs_Sales'!F5 * (1.005^52) -> 0 | BC8: ='02_Inputs_Sales'!F11 * '02_Inputs_Sales'!G5 * (1.005^53) -> 0 | BD8: ='02_Inputs_Sales'!F11 * '02_Inputs_Sales'!H5 * (1.005^54) -> 0 | BE8: ='02_Inputs_Sales'!F11 * '02_Inputs_Sales'!I5 * (1.005^55) -> 0 | BF8: ='02_Inputs_Sales'!F11 * '02_Inputs_Sales'!J5 * (1.005^56) -> 0 | BG8: ='02_Inputs_Sales'!F11 * '02_Inputs_Sales'!K5 * (1.005^57) -> 0 | BH8: ='02_Inputs_Sales'!F11 * '02_Inputs_Sales'!L5 * (1.005^58) -> 0 | BI8: ='02_Inputs_Sales'!F11 * '02_Inputs_Sales'!M5 * (1.005^59) -> 0
A9: Pale Ale - West Coast | B9: ='02_Inputs_Sales'!F12 * '02_Inputs_Sales'!B5 * (1.005^0) -> 0 | C9: ='02_Inputs_Sales'!F12 * '02_Inputs_Sales'!C5 * (1.005^1) -> 0 | D9: ='02_Inputs_Sales'!F12 * '02_Inputs_Sales'!D5 * (1.005^2) -> 0 | E9: ='02_Inputs_Sales'!F12 * '02_Inputs_Sales'!E5 * (1.005^3) -> 0 | F9: ='02_Inputs_Sales'!F12 * '02_Inputs_Sales'!F5 * (1.005^4) -> 0 | G9: ='02_Inputs_Sales'!F12 * '02_Inputs_Sales'!G5 * (1.005^5) -> 0 | H9: ='02_Inputs_Sales'!F12 * '02_Inputs_Sales'!H5 * (1.005^6) -> 0 | I9: ='02_Inputs_Sales'!F12 * '02_Inputs_Sales'!I5 * (1.005^7) -> 0 | J9: ='02_Inputs_Sales'!F12 * '02_Inputs_Sales'!J5 * (1.005^8) -> 0 | K9: ='02_Inputs_Sales'!F12 * '02_Inputs_Sales'!K5 * (1.005^9) -> 0 | L9: ='02_Inputs_Sales'!F12 * '02_Inputs_Sales'!L5 * (1.005^10) -> 0 | M9: ='02_Inputs_Sales'!F12 * '02_Inputs_Sales'!M5 * (1.005^11) -> 0 | N9: ='02_Inputs_Sales'!F12 * '02_Inputs_Sales'!B5 * (1.005^12) -> 0 | O9: ='02_Inputs_Sales'!F12 * '02_Inputs_Sales'!C5 * (1.005^13) -> 0 | P9: ='02_Inputs_Sales'!F12 * '02_Inputs_Sales'!D5 * (1.005^14) -> 0 | Q9: ='02_Inputs_Sales'!F12 * '02_Inputs_Sales'!E5 * (1.005^15) -> 0 | R9: ='02_Inputs_Sales'!F12 * '02_Inputs_Sales'!F5 * (1.005^16) -> 0 | S9: ='02_Inputs_Sales'!F12 * '02_Inputs_Sales'!G5 * (1.005^17) -> 0 | T9: ='02_Inputs_Sales'!F12 * '02_Inputs_Sales'!H5 * (1.005^18) -> 0 | U9: ='02_Inputs_Sales'!F12 * '02_Inputs_Sales'!I5 * (1.005^19) -> 0 | V9: ='02_Inputs_Sales'!F12 * '02_Inputs_Sales'!J5 * (1.005^20) -> 0 | W9: ='02_Inputs_Sales'!F12 * '02_Inputs_Sales'!K5 * (1.005^21) -> 0 | X9: ='02_Inputs_Sales'!F12 * '02_Inputs_Sales'!L5 * (1.005^22) -> 0 | Y9: ='02_Inputs_Sales'!F12 * '02_Inputs_Sales'!M5 * (1.005^23) -> 0 | Z9: ='02_Inputs_Sales'!F12 * '02_Inputs_Sales'!B5 * (1.005^24) -> 0 | AA9: ='02_Inputs_Sales'!F12 * '02_Inputs_Sales'!C5 * (1.005^25) -> 0 | AB9: ='02_Inputs_Sales'!F12 * '02_Inputs_Sales'!D5 * (1.005^26) -> 0 | AC9: ='02_Inputs_Sales'!F12 * '02_Inputs_Sales'!E5 * (1.005^27) -> 0 | AD9: ='02_Inputs_Sales'!F12 * '02_Inputs_Sales'!F5 * (1.005^28) -> 0 | AE9: ='02_Inputs_Sales'!F12 * '02_Inputs_Sales'!G5 * (1.005^29) -> 0 | AF9: ='02_Inputs_Sales'!F12 * '02_Inputs_Sales'!H5 * (1.005^30) -> 0 | AG9: ='02_Inputs_Sales'!F12 * '02_Inputs_Sales'!I5 * (1.005^31) -> 0 | AH9: ='02_Inputs_Sales'!F12 * '02_Inputs_Sales'!J5 * (1.005^32) -> 0 | AI9: ='02_Inputs_Sales'!F12 * '02_Inputs_Sales'!K5 * (1.005^33) -> 0 | AJ9: ='02_Inputs_Sales'!F12 * '02_Inputs_Sales'!L5 * (1.005^34) -> 0 | AK9: ='02_Inputs_Sales'!F12 * '02_Inputs_Sales'!M5 * (1.005^35) -> 0 | AL9: ='02_Inputs_Sales'!F12 * '02_Inputs_Sales'!B5 * (1.005^36) -> 0 | AM9: ='02_Inputs_Sales'!F12 * '02_Inputs_Sales'!C5 * (1.005^37) -> 0 | AN9: ='02_Inputs_Sales'!F12 * '02_Inputs_Sales'!D5 * (1.005^38) -> 0 | AO9: ='02_Inputs_Sales'!F12 * '02_Inputs_Sales'!E5 * (1.005^39) -> 0 | AP9: ='02_Inputs_Sales'!F12 * '02_Inputs_Sales'!F5 * (1.005^40) -> 0 | AQ9: ='02_Inputs_Sales'!F12 * '02_Inputs_Sales'!G5 * (1.005^41) -> 0 | AR9: ='02_Inputs_Sales'!F12 * '02_Inputs_Sales'!H5 * (1.005^42) -> 0 | AS9: ='02_Inputs_Sales'!F12 * '02_Inputs_Sales'!I5 * (1.005^43) -> 0 | AT9: ='02_Inputs_Sales'!F12 * '02_Inputs_Sales'!J5 * (1.005^44) -> 0 | AU9: ='02_Inputs_Sales'!F12 * '02_Inputs_Sales'!K5 * (1.005^45) -> 0 | AV9: ='02_Inputs_Sales'!F12 * '02_Inputs_Sales'!L5 * (1.005^46) -> 0 | AW9: ='02_Inputs_Sales'!F12 * '02_Inputs_Sales'!M5 * (1.005^47) -> 0 | AX9: ='02_Inputs_Sales'!F12 * '02_Inputs_Sales'!B5 * (1.005^48) -> 0 | AY9: ='02_Inputs_Sales'!F12 * '02_Inputs_Sales'!C5 * (1.005^49) -> 0 | AZ9: ='02_Inputs_Sales'!F12 * '02_Inputs_Sales'!D5 * (1.005^50) -> 0 | BA9: ='02_Inputs_Sales'!F12 * '02_Inputs_Sales'!E5 * (1.005^51) -> 0 | BB9: ='02_Inputs_Sales'!F12 * '02_Inputs_Sales'!F5 * (1.005^52) -> 0 | BC9: ='02_Inputs_Sales'!F12 * '02_Inputs_Sales'!G5 * (1.005^53) -> 0 | BD9: ='02_Inputs_Sales'!F12 * '02_Inputs_Sales'!H5 * (1.005^54) -> 0 | BE9: ='02_Inputs_Sales'!F12 * '02_Inputs_Sales'!I5 * (1.005^55) -> 0 | BF9: ='02_Inputs_Sales'!F12 * '02_Inputs_Sales'!J5 * (1.005^56) -> 0 | BG9: ='02_Inputs_Sales'!F12 * '02_Inputs_Sales'!K5 * (1.005^57) -> 0 | BH9: ='02_Inputs_Sales'!F12 * '02_Inputs_Sales'!L5 * (1.005^58) -> 0 | BI9: ='02_Inputs_Sales'!F12 * '02_Inputs_Sales'!M5 * (1.005^59) -> 0
A10: IPA - Hazy | B10: ='02_Inputs_Sales'!F13 * '02_Inputs_Sales'!B5 * (1.005^0) -> 0 | C10: ='02_Inputs_Sales'!F13 * '02_Inputs_Sales'!C5 * (1.005^1) -> 0 | D10: ='02_Inputs_Sales'!F13 * '02_Inputs_Sales'!D5 * (1.005^2) -> 0 | E10: ='02_Inputs_Sales'!F13 * '02_Inputs_Sales'!E5 * (1.005^3) -> 0 | F10: ='02_Inputs_Sales'!F13 * '02_Inputs_Sales'!F5 * (1.005^4) -> 0 | G10: ='02_Inputs_Sales'!F13 * '02_Inputs_Sales'!G5 * (1.005^5) -> 0 | H10: ='02_Inputs_Sales'!F13 * '02_Inputs_Sales'!H5 * (1.005^6) -> 0 | I10: ='02_Inputs_Sales'!F13 * '02_Inputs_Sales'!I5 * (1.005^7) -> 0 | J10: ='02_Inputs_Sales'!F13 * '02_Inputs_Sales'!J5 * (1.005^8) -> 0 | K10: ='02_Inputs_Sales'!F13 * '02_Inputs_Sales'!K5 * (1.005^9) -> 0 | L10: ='02_Inputs_Sales'!F13 * '02_Inputs_Sales'!L5 * (1.005^10) -> 0 | M10: ='02_Inputs_Sales'!F13 * '02_Inputs_Sales'!M5 * (1.005^11) -> 0 | N10: ='02_Inputs_Sales'!F13 * '02_Inputs_Sales'!B5 * (1.005^12) -> 0 | O10: ='02_Inputs_Sales'!F13 * '02_Inputs_Sales'!C5 * (1.005^13) -> 0 | P10: ='02_Inputs_Sales'!F13 * '02_Inputs_Sales'!D5 * (1.005^14) -> 0 | Q10: ='02_Inputs_Sales'!F13 * '02_Inputs_Sales'!E5 * (1.005^15) -> 0 | R10: ='02_Inputs_Sales'!F13 * '02_Inputs_Sales'!F5 * (1.005^16) -> 0 | S10: ='02_Inputs_Sales'!F13 * '02_Inputs_Sales'!G5 * (1.005^17) -> 0 | T10: ='02_Inputs_Sales'!F13 * '02_Inputs_Sales'!H5 * (1.005^18) -> 0 | U10: ='02_Inputs_Sales'!F13 * '02_Inputs_Sales'!I5 * (1.005^19) -> 0 | V10: ='02_Inputs_Sales'!F13 * '02_Inputs_Sales'!J5 * (1.005^20) -> 0 | W10: ='02_Inputs_Sales'!F13 * '02_Inputs_Sales'!K5 * (1.005^21) -> 0 | X10: ='02_Inputs_Sales'!F13 * '02_Inputs_Sales'!L5 * (1.005^22) -> 0 | Y10: ='02_Inputs_Sales'!F13 * '02_Inputs_Sales'!M5 * (1.005^23) -> 0 | Z10: ='02_Inputs_Sales'!F13 * '02_Inputs_Sales'!B5 * (1.005^24) -> 0 | AA10: ='02_Inputs_Sales'!F13 * '02_Inputs_Sales'!C5 * (1.005^25) -> 0 | AB10: ='02_Inputs_Sales'!F13 * '02_Inputs_Sales'!D5 * (1.005^26) -> 0 | AC10: ='02_Inputs_Sales'!F13 * '02_Inputs_Sales'!E5 * (1.005^27) -> 0 | AD10: ='02_Inputs_Sales'!F13 * '02_Inputs_Sales'!F5 * (1.005^28) -> 0 | AE10: ='02_Inputs_Sales'!F13 * '02_Inputs_Sales'!G5 * (1.005^29) -> 0 | AF10: ='02_Inputs_Sales'!F13 * '02_Inputs_Sales'!H5 * (1.005^30) -> 0 | AG10: ='02_Inputs_Sales'!F13 * '02_Inputs_Sales'!I5 * (1.005^31) -> 0 | AH10: ='02_Inputs_Sales'!F13 * '02_Inputs_Sales'!J5 * (1.005^32) -> 0 | AI10: ='02_Inputs_Sales'!F13 * '02_Inputs_Sales'!K5 * (1.005^33) -> 0 | AJ10: ='02_Inputs_Sales'!F13 * '02_Inputs_Sales'!L5 * (1.005^34) -> 0 | AK10: ='02_Inputs_Sales'!F13 * '02_Inputs_Sales'!M5 * (1.005^35) -> 0 | AL10: ='02_Inputs_Sales'!F13 * '02_Inputs_Sales'!B5 * (1.005^36) -> 0 | AM10: ='02_Inputs_Sales'!F13 * '02_Inputs_Sales'!C5 * (1.005^37) -> 0 | AN10: ='02_Inputs_Sales'!F13 * '02_Inputs_Sales'!D5 * (1.005^38) -> 0 | AO10: ='02_Inputs_Sales'!F13 * '02_Inputs_Sales'!E5 * (1.005^39) -> 0 | AP10: ='02_Inputs_Sales'!F13 * '02_Inputs_Sales'!F5 * (1.005^40) -> 0 | AQ10: ='02_Inputs_Sales'!F13 * '02_Inputs_Sales'!G5 * (1.005^41) -> 0 | AR10: ='02_Inputs_Sales'!F13 * '02_Inputs_Sales'!H5 * (1.005^42) -> 0 | AS10: ='02_Inputs_Sales'!F13 * '02_Inputs_Sales'!I5 * (1.005^43) -> 0 | AT10: ='02_Inputs_Sales'!F13 * '02_Inputs_Sales'!J5 * (1.005^44) -> 0 | AU10: ='02_Inputs_Sales'!F13 * '02_Inputs_Sales'!K5 * (1.005^45) -> 0 | AV10: ='02_Inputs_Sales'!F13 * '02_Inputs_Sales'!L5 * (1.005^46) -> 0 | AW10: ='02_Inputs_Sales'!F13 * '02_Inputs_Sales'!M5 * (1.005^47) -> 0 | AX10: ='02_Inputs_Sales'!F13 * '02_Inputs_Sales'!B5 * (1.005^48) -> 0 | AY10: ='02_Inputs_Sales'!F13 * '02_Inputs_Sales'!C5 * (1.005^49) -> 0 | AZ10: ='02_Inputs_Sales'!F13 * '02_Inputs_Sales'!D5 * (1.005^50) -> 0 | BA10: ='02_Inputs_Sales'!F13 * '02_Inputs_Sales'!E5 * (1.005^51) -> 0 | BB10: ='02_Inputs_Sales'!F13 * '02_Inputs_Sales'!F5 * (1.005^52) -> 0 | BC10: ='02_Inputs_Sales'!F13 * '02_Inputs_Sales'!G5 * (1.005^53) -> 0 | BD10: ='02_Inputs_Sales'!F13 * '02_Inputs_Sales'!H5 * (1.005^54) -> 0 | BE10: ='02_Inputs_Sales'!F13 * '02_Inputs_Sales'!I5 * (1.005^55) -> 0 | BF10: ='02_Inputs_Sales'!F13 * '02_Inputs_Sales'!J5 * (1.005^56) -> 0 | BG10: ='02_Inputs_Sales'!F13 * '02_Inputs_Sales'!K5 * (1.005^57) -> 0 | BH10: ='02_Inputs_Sales'!F13 * '02_Inputs_Sales'!L5 * (1.005^58) -> 0 | BI10: ='02_Inputs_Sales'!F13 * '02_Inputs_Sales'!M5 * (1.005^59) -> 0
A11: IPA - Double | B11: ='02_Inputs_Sales'!F14 * '02_Inputs_Sales'!B5 * (1.005^0) -> 0 | C11: ='02_Inputs_Sales'!F14 * '02_Inputs_Sales'!C5 * (1.005^1) -> 0 | D11: ='02_Inputs_Sales'!F14 * '02_Inputs_Sales'!D5 * (1.005^2) -> 0 | E11: ='02_Inputs_Sales'!F14 * '02_Inputs_Sales'!E5 * (1.005^3) -> 0 | F11: ='02_Inputs_Sales'!F14 * '02_Inputs_Sales'!F5 * (1.005^4) -> 0 | G11: ='02_Inputs_Sales'!F14 * '02_Inputs_Sales'!G5 * (1.005^5) -> 0 | H11: ='02_Inputs_Sales'!F14 * '02_Inputs_Sales'!H5 * (1.005^6) -> 0 | I11: ='02_Inputs_Sales'!F14 * '02_Inputs_Sales'!I5 * (1.005^7) -> 0 | J11: ='02_Inputs_Sales'!F14 * '02_Inputs_Sales'!J5 * (1.005^8) -> 0 | K11: ='02_Inputs_Sales'!F14 * '02_Inputs_Sales'!K5 * (1.005^9) -> 0 | L11: ='02_Inputs_Sales'!F14 * '02_Inputs_Sales'!L5 * (1.005^10) -> 0 | M11: ='02_Inputs_Sales'!F14 * '02_Inputs_Sales'!M5 * (1.005^11) -> 0 | N11: ='02_Inputs_Sales'!F14 * '02_Inputs_Sales'!B5 * (1.005^12) -> 0 | O11: ='02_Inputs_Sales'!F14 * '02_Inputs_Sales'!C5 * (1.005^13) -> 0 | P11: ='02_Inputs_Sales'!F14 * '02_Inputs_Sales'!D5 * (1.005^14) -> 0 | Q11: ='02_Inputs_Sales'!F14 * '02_Inputs_Sales'!E5 * (1.005^15) -> 0 | R11: ='02_Inputs_Sales'!F14 * '02_Inputs_Sales'!F5 * (1.005^16) -> 0 | S11: ='02_Inputs_Sales'!F14 * '02_Inputs_Sales'!G5 * (1.005^17) -> 0 | T11: ='02_Inputs_Sales'!F14 * '02_Inputs_Sales'!H5 * (1.005^18) -> 0 | U11: ='02_Inputs_Sales'!F14 * '02_Inputs_Sales'!I5 * (1.005^19) -> 0 | V11: ='02_Inputs_Sales'!F14 * '02_Inputs_Sales'!J5 * (1.005^20) -> 0 | W11: ='02_Inputs_Sales'!F14 * '02_Inputs_Sales'!K5 * (1.005^21) -> 0 | X11: ='02_Inputs_Sales'!F14 * '02_Inputs_Sales'!L5 * (1.005^22) -> 0 | Y11: ='02_Inputs_Sales'!F14 * '02_Inputs_Sales'!M5 * (1.005^23) -> 0 | Z11: ='02_Inputs_Sales'!F14 * '02_Inputs_Sales'!B5 * (1.005^24) -> 0 | AA11: ='02_Inputs_Sales'!F14 * '02_Inputs_Sales'!C5 * (1.005^25) -> 0 | AB11: ='02_Inputs_Sales'!F14 * '02_Inputs_Sales'!D5 * (1.005^26) -> 0 | AC11: ='02_Inputs_Sales'!F14 * '02_Inputs_Sales'!E5 * (1.005^27) -> 0 | AD11: ='02_Inputs_Sales'!F14 * '02_Inputs_Sales'!F5 * (1.005^28) -> 0 | AE11: ='02_Inputs_Sales'!F14 * '02_Inputs_Sales'!G5 * (1.005^29) -> 0 | AF11: ='02_Inputs_Sales'!F14 * '02_Inputs_Sales'!H5 * (1.005^30) -> 0 | AG11: ='02_Inputs_Sales'!F14 * '02_Inputs_Sales'!I5 * (1.005^31) -> 0 | AH11: ='02_Inputs_Sales'!F14 * '02_Inputs_Sales'!J5 * (1.005^32) -> 0 | AI11: ='02_Inputs_Sales'!F14 * '02_Inputs_Sales'!K5 * (1.005^33) -> 0 | AJ11: ='02_Inputs_Sales'!F14 * '02_Inputs_Sales'!L5 * (1.005^34) -> 0 | AK11: ='02_Inputs_Sales'!F14 * '02_Inputs_Sales'!M5 * (1.005^35) -> 0 | AL11: ='02_Inputs_Sales'!F14 * '02_Inputs_Sales'!B5 * (1.005^36) -> 0 | AM11: ='02_Inputs_Sales'!F14 * '02_Inputs_Sales'!C5 * (1.005^37) -> 0 | AN11: ='02_Inputs_Sales'!F14 * '02_Inputs_Sales'!D5 * (1.005^38) -> 0 | AO11: ='02_Inputs_Sales'!F14 * '02_Inputs_Sales'!E5 * (1.005^39) -> 0 | AP11: ='02_Inputs_Sales'!F14 * '02_Inputs_Sales'!F5 * (1.005^40) -> 0 | AQ11: ='02_Inputs_Sales'!F14 * '02_Inputs_Sales'!G5 * (1.005^41) -> 0 | AR11: ='02_Inputs_Sales'!F14 * '02_Inputs_Sales'!H5 * (1.005^42) -> 0 | AS11: ='02_Inputs_Sales'!F14 * '02_Inputs_Sales'!I5 * (1.005^43) -> 0 | AT11: ='02_Inputs_Sales'!F14 * '02_Inputs_Sales'!J5 * (1.005^44) -> 0 | AU11: ='02_Inputs_Sales'!F14 * '02_Inputs_Sales'!K5 * (1.005^45) -> 0 | AV11: ='02_Inputs_Sales'!F14 * '02_Inputs_Sales'!L5 * (1.005^46) -> 0 | AW11: ='02_Inputs_Sales'!F14 * '02_Inputs_Sales'!M5 * (1.005^47) -> 0 | AX11: ='02_Inputs_Sales'!F14 * '02_Inputs_Sales'!B5 * (1.005^48) -> 0 | AY11: ='02_Inputs_Sales'!F14 * '02_Inputs_Sales'!C5 * (1.005^49) -> 0 | AZ11: ='02_Inputs_Sales'!F14 * '02_Inputs_Sales'!D5 * (1.005^50) -> 0 | BA11: ='02_Inputs_Sales'!F14 * '02_Inputs_Sales'!E5 * (1.005^51) -> 0 | BB11: ='02_Inputs_Sales'!F14 * '02_Inputs_Sales'!F5 * (1.005^52) -> 0 | BC11: ='02_Inputs_Sales'!F14 * '02_Inputs_Sales'!G5 * (1.005^53) -> 0 | BD11: ='02_Inputs_Sales'!F14 * '02_Inputs_Sales'!H5 * (1.005^54) -> 0 | BE11: ='02_Inputs_Sales'!F14 * '02_Inputs_Sales'!I5 * (1.005^55) -> 0 | BF11: ='02_Inputs_Sales'!F14 * '02_Inputs_Sales'!J5 * (1.005^56) -> 0 | BG11: ='02_Inputs_Sales'!F14 * '02_Inputs_Sales'!K5 * (1.005^57) -> 0 | BH11: ='02_Inputs_Sales'!F14 * '02_Inputs_Sales'!L5 * (1.005^58) -> 0 | BI11: ='02_Inputs_Sales'!F14 * '02_Inputs_Sales'!M5 * (1.005^59) -> 0
A12: Stout - Oatmeal | B12: ='02_Inputs_Sales'!F15 * '02_Inputs_Sales'!B5 * (1.005^0) -> 0 | C12: ='02_Inputs_Sales'!F15 * '02_Inputs_Sales'!C5 * (1.005^1) -> 0 | D12: ='02_Inputs_Sales'!F15 * '02_Inputs_Sales'!D5 * (1.005^2) -> 0 | E12: ='02_Inputs_Sales'!F15 * '02_Inputs_Sales'!E5 * (1.005^3) -> 0 | F12: ='02_Inputs_Sales'!F15 * '02_Inputs_Sales'!F5 * (1.005^4) -> 0 | G12: ='02_Inputs_Sales'!F15 * '02_Inputs_Sales'!G5 * (1.005^5) -> 0 | H12: ='02_Inputs_Sales'!F15 * '02_Inputs_Sales'!H5 * (1.005^6) -> 0 | I12: ='02_Inputs_Sales'!F15 * '02_Inputs_Sales'!I5 * (1.005^7) -> 0 | J12: ='02_Inputs_Sales'!F15 * '02_Inputs_Sales'!J5 * (1.005^8) -> 0 | K12: ='02_Inputs_Sales'!F15 * '02_Inputs_Sales'!K5 * (1.005^9) -> 0 | L12: ='02_Inputs_Sales'!F15 * '02_Inputs_Sales'!L5 * (1.005^10) -> 0 | M12: ='02_Inputs_Sales'!F15 * '02_Inputs_Sales'!M5 * (1.005^11) -> 0 | N12: ='02_Inputs_Sales'!F15 * '02_Inputs_Sales'!B5 * (1.005^12) -> 0 | O12: ='02_Inputs_Sales'!F15 * '02_Inputs_Sales'!C5 * (1.005^13) -> 0 | P12: ='02_Inputs_Sales'!F15 * '02_Inputs_Sales'!D5 * (1.005^14) -> 0 | Q12: ='02_Inputs_Sales'!F15 * '02_Inputs_Sales'!E5 * (1.005^15) -> 0 | R12: ='02_Inputs_Sales'!F15 * '02_Inputs_Sales'!F5 * (1.005^16) -> 0 | S12: ='02_Inputs_Sales'!F15 * '02_Inputs_Sales'!G5 * (1.005^17) -> 0 | T12: ='02_Inputs_Sales'!F15 * '02_Inputs_Sales'!H5 * (1.005^18) -> 0 | U12: ='02_Inputs_Sales'!F15 * '02_Inputs_Sales'!I5 * (1.005^19) -> 0 | V12: ='02_Inputs_Sales'!F15 * '02_Inputs_Sales'!J5 * (1.005^20) -> 0 | W12: ='02_Inputs_Sales'!F15 * '02_Inputs_Sales'!K5 * (1.005^21) -> 0 | X12: ='02_Inputs_Sales'!F15 * '02_Inputs_Sales'!L5 * (1.005^22) -> 0 | Y12: ='02_Inputs_Sales'!F15 * '02_Inputs_Sales'!M5 * (1.005^23) -> 0 | Z12: ='02_Inputs_Sales'!F15 * '02_Inputs_Sales'!B5 * (1.005^24) -> 0 | AA12: ='02_Inputs_Sales'!F15 * '02_Inputs_Sales'!C5 * (1.005^25) -> 0 | AB12: ='02_Inputs_Sales'!F15 * '02_Inputs_Sales'!D5 * (1.005^26) -> 0 | AC12: ='02_Inputs_Sales'!F15 * '02_Inputs_Sales'!E5 * (1.005^27) -> 0 | AD12: ='02_Inputs_Sales'!F15 * '02_Inputs_Sales'!F5 * (1.005^28) -> 0 | AE12: ='02_Inputs_Sales'!F15 * '02_Inputs_Sales'!G5 * (1.005^29) -> 0 | AF12: ='02_Inputs_Sales'!F15 * '02_Inputs_Sales'!H5 * (1.005^30) -> 0 | AG12: ='02_Inputs_Sales'!F15 * '02_Inputs_Sales'!I5 * (1.005^31) -> 0 | AH12: ='02_Inputs_Sales'!F15 * '02_Inputs_Sales'!J5 * (1.005^32) -> 0 | AI12: ='02_Inputs_Sales'!F15 * '02_Inputs_Sales'!K5 * (1.005^33) -> 0 | AJ12: ='02_Inputs_Sales'!F15 * '02_Inputs_Sales'!L5 * (1.005^34) -> 0 | AK12: ='02_Inputs_Sales'!F15 * '02_Inputs_Sales'!M5 * (1.005^35) -> 0 | AL12: ='02_Inputs_Sales'!F15 * '02_Inputs_Sales'!B5 * (1.005^36) -> 0 | AM12: ='02_Inputs_Sales'!F15 * '02_Inputs_Sales'!C5 * (1.005^37) -> 0 | AN12: ='02_Inputs_Sales'!F15 * '02_Inputs_Sales'!D5 * (1.005^38) -> 0 | AO12: ='02_Inputs_Sales'!F15 * '02_Inputs_Sales'!E5 * (1.005^39) -> 0 | AP12: ='02_Inputs_Sales'!F15 * '02_Inputs_Sales'!F5 * (1.005^40) -> 0 | AQ12: ='02_Inputs_Sales'!F15 * '02_Inputs_Sales'!G5 * (1.005^41) -> 0 | AR12: ='02_Inputs_Sales'!F15 * '02_Inputs_Sales'!H5 * (1.005^42) -> 0 | AS12: ='02_Inputs_Sales'!F15 * '02_Inputs_Sales'!I5 * (1.005^43) -> 0 | AT12: ='02_Inputs_Sales'!F15 * '02_Inputs_Sales'!J5 * (1.005^44) -> 0 | AU12: ='02_Inputs_Sales'!F15 * '02_Inputs_Sales'!K5 * (1.005^45) -> 0 | AV12: ='02_Inputs_Sales'!F15 * '02_Inputs_Sales'!L5 * (1.005^46) -> 0 | AW12: ='02_Inputs_Sales'!F15 * '02_Inputs_Sales'!M5 * (1.005^47) -> 0 | AX12: ='02_Inputs_Sales'!F15 * '02_Inputs_Sales'!B5 * (1.005^48) -> 0 | AY12: ='02_Inputs_Sales'!F15 * '02_Inputs_Sales'!C5 * (1.005^49) -> 0 | AZ12: ='02_Inputs_Sales'!F15 * '02_Inputs_Sales'!D5 * (1.005^50) -> 0 | BA12: ='02_Inputs_Sales'!F15 * '02_Inputs_Sales'!E5 * (1.005^51) -> 0 | BB12: ='02_Inputs_Sales'!F15 * '02_Inputs_Sales'!F5 * (1.005^52) -> 0 | BC12: ='02_Inputs_Sales'!F15 * '02_Inputs_Sales'!G5 * (1.005^53) -> 0 | BD12: ='02_Inputs_Sales'!F15 * '02_Inputs_Sales'!H5 * (1.005^54) -> 0 | BE12: ='02_Inputs_Sales'!F15 * '02_Inputs_Sales'!I5 * (1.005^55) -> 0 | BF12: ='02_Inputs_Sales'!F15 * '02_Inputs_Sales'!J5 * (1.005^56) -> 0 | BG12: ='02_Inputs_Sales'!F15 * '02_Inputs_Sales'!K5 * (1.005^57) -> 0 | BH12: ='02_Inputs_Sales'!F15 * '02_Inputs_Sales'!L5 * (1.005^58) -> 0 | BI12: ='02_Inputs_Sales'!F15 * '02_Inputs_Sales'!M5 * (1.005^59) -> 0
A13: Summer Ale | B13: ='02_Inputs_Sales'!F16 * '02_Inputs_Sales'!B5 * (1.005^0) -> 0 | C13: ='02_Inputs_Sales'!F16 * '02_Inputs_Sales'!C5 * (1.005^1) -> 0 | D13: ='02_Inputs_Sales'!F16 * '02_Inputs_Sales'!D5 * (1.005^2) -> 0 | E13: ='02_Inputs_Sales'!F16 * '02_Inputs_Sales'!E5 * (1.005^3) -> 0 | F13: ='02_Inputs_Sales'!F16 * '02_Inputs_Sales'!F5 * (1.005^4) -> 0 | G13: ='02_Inputs_Sales'!F16 * '02_Inputs_Sales'!G5 * (1.005^5) -> 0 | H13: ='02_Inputs_Sales'!F16 * '02_Inputs_Sales'!H5 * (1.005^6) -> 0 | I13: ='02_Inputs_Sales'!F16 * '02_Inputs_Sales'!I5 * (1.005^7) -> 0 | J13: ='02_Inputs_Sales'!F16 * '02_Inputs_Sales'!J5 * (1.005^8) -> 0 | K13: ='02_Inputs_Sales'!F16 * '02_Inputs_Sales'!K5 * (1.005^9) -> 0 | L13: ='02_Inputs_Sales'!F16 * '02_Inputs_Sales'!L5 * (1.005^10) -> 0 | M13: ='02_Inputs_Sales'!F16 * '02_Inputs_Sales'!M5 * (1.005^11) -> 0 | N13: ='02_Inputs_Sales'!F16 * '02_Inputs_Sales'!B5 * (1.005^12) -> 0 | O13: ='02_Inputs_Sales'!F16 * '02_Inputs_Sales'!C5 * (1.005^13) -> 0 | P13: ='02_Inputs_Sales'!F16 * '02_Inputs_Sales'!D5 * (1.005^14) -> 0 | Q13: ='02_Inputs_Sales'!F16 * '02_Inputs_Sales'!E5 * (1.005^15) -> 0 | R13: ='02_Inputs_Sales'!F16 * '02_Inputs_Sales'!F5 * (1.005^16) -> 0 | S13: ='02_Inputs_Sales'!F16 * '02_Inputs_Sales'!G5 * (1.005^17) -> 0 | T13: ='02_Inputs_Sales'!F16 * '02_Inputs_Sales'!H5 * (1.005^18) -> 0 | U13: ='02_Inputs_Sales'!F16 * '02_Inputs_Sales'!I5 * (1.005^19) -> 0 | V13: ='02_Inputs_Sales'!F16 * '02_Inputs_Sales'!J5 * (1.005^20) -> 0 | W13: ='02_Inputs_Sales'!F16 * '02_Inputs_Sales'!K5 * (1.005^21) -> 0 | X13: ='02_Inputs_Sales'!F16 * '02_Inputs_Sales'!L5 * (1.005^22) -> 0 | Y13: ='02_Inputs_Sales'!F16 * '02_Inputs_Sales'!M5 * (1.005^23) -> 0 | Z13: ='02_Inputs_Sales'!F16 * '02_Inputs_Sales'!B5 * (1.005^24) -> 0 | AA13: ='02_Inputs_Sales'!F16 * '02_Inputs_Sales'!C5 * (1.005^25) -> 0 | AB13: ='02_Inputs_Sales'!F16 * '02_Inputs_Sales'!D5 * (1.005^26) -> 0 | AC13: ='02_Inputs_Sales'!F16 * '02_Inputs_Sales'!E5 * (1.005^27) -> 0 | AD13: ='02_Inputs_Sales'!F16 * '02_Inputs_Sales'!F5 * (1.005^28) -> 0 | AE13: ='02_Inputs_Sales'!F16 * '02_Inputs_Sales'!G5 * (1.005^29) -> 0 | AF13: ='02_Inputs_Sales'!F16 * '02_Inputs_Sales'!H5 * (1.005^30) -> 0 | AG13: ='02_Inputs_Sales'!F16 * '02_Inputs_Sales'!I5 * (1.005^31) -> 0 | AH13: ='02_Inputs_Sales'!F16 * '02_Inputs_Sales'!J5 * (1.005^32) -> 0 | AI13: ='02_Inputs_Sales'!F16 * '02_Inputs_Sales'!K5 * (1.005^33) -> 0 | AJ13: ='02_Inputs_Sales'!F16 * '02_Inputs_Sales'!L5 * (1.005^34) -> 0 | AK13: ='02_Inputs_Sales'!F16 * '02_Inputs_Sales'!M5 * (1.005^35) -> 0 | AL13: ='02_Inputs_Sales'!F16 * '02_Inputs_Sales'!B5 * (1.005^36) -> 0 | AM13: ='02_Inputs_Sales'!F16 * '02_Inputs_Sales'!C5 * (1.005^37) -> 0 | AN13: ='02_Inputs_Sales'!F16 * '02_Inputs_Sales'!D5 * (1.005^38) -> 0 | AO13: ='02_Inputs_Sales'!F16 * '02_Inputs_Sales'!E5 * (1.005^39) -> 0 | AP13: ='02_Inputs_Sales'!F16 * '02_Inputs_Sales'!F5 * (1.005^40) -> 0 | AQ13: ='02_Inputs_Sales'!F16 * '02_Inputs_Sales'!G5 * (1.005^41) -> 0 | AR13: ='02_Inputs_Sales'!F16 * '02_Inputs_Sales'!H5 * (1.005^42) -> 0 | AS13: ='02_Inputs_Sales'!F16 * '02_Inputs_Sales'!I5 * (1.005^43) -> 0 | AT13: ='02_Inputs_Sales'!F16 * '02_Inputs_Sales'!J5 * (1.005^44) -> 0 | AU13: ='02_Inputs_Sales'!F16 * '02_Inputs_Sales'!K5 * (1.005^45) -> 0 | AV13: ='02_Inputs_Sales'!F16 * '02_Inputs_Sales'!L5 * (1.005^46) -> 0 | AW13: ='02_Inputs_Sales'!F16 * '02_Inputs_Sales'!M5 * (1.005^47) -> 0 | AX13: ='02_Inputs_Sales'!F16 * '02_Inputs_Sales'!B5 * (1.005^48) -> 0 | AY13: ='02_Inputs_Sales'!F16 * '02_Inputs_Sales'!C5 * (1.005^49) -> 0 | AZ13: ='02_Inputs_Sales'!F16 * '02_Inputs_Sales'!D5 * (1.005^50) -> 0 | BA13: ='02_Inputs_Sales'!F16 * '02_Inputs_Sales'!E5 * (1.005^51) -> 0 | BB13: ='02_Inputs_Sales'!F16 * '02_Inputs_Sales'!F5 * (1.005^52) -> 0 | BC13: ='02_Inputs_Sales'!F16 * '02_Inputs_Sales'!G5 * (1.005^53) -> 0 | BD13: ='02_Inputs_Sales'!F16 * '02_Inputs_Sales'!H5 * (1.005^54) -> 0 | BE13: ='02_Inputs_Sales'!F16 * '02_Inputs_Sales'!I5 * (1.005^55) -> 0 | BF13: ='02_Inputs_Sales'!F16 * '02_Inputs_Sales'!J5 * (1.005^56) -> 0 | BG13: ='02_Inputs_Sales'!F16 * '02_Inputs_Sales'!K5 * (1.005^57) -> 0 | BH13: ='02_Inputs_Sales'!F16 * '02_Inputs_Sales'!L5 * (1.005^58) -> 0 | BI13: ='02_Inputs_Sales'!F16 * '02_Inputs_Sales'!M5 * (1.005^59) -> 0
A14: Winter Porter | B14: ='02_Inputs_Sales'!F17 * '02_Inputs_Sales'!B5 * (1.005^0) -> 0 | C14: ='02_Inputs_Sales'!F17 * '02_Inputs_Sales'!C5 * (1.005^1) -> 0 | D14: ='02_Inputs_Sales'!F17 * '02_Inputs_Sales'!D5 * (1.005^2) -> 0 | E14: ='02_Inputs_Sales'!F17 * '02_Inputs_Sales'!E5 * (1.005^3) -> 0 | F14: ='02_Inputs_Sales'!F17 * '02_Inputs_Sales'!F5 * (1.005^4) -> 0 | G14: ='02_Inputs_Sales'!F17 * '02_Inputs_Sales'!G5 * (1.005^5) -> 0 | H14: ='02_Inputs_Sales'!F17 * '02_Inputs_Sales'!H5 * (1.005^6) -> 0 | I14: ='02_Inputs_Sales'!F17 * '02_Inputs_Sales'!I5 * (1.005^7) -> 0 | J14: ='02_Inputs_Sales'!F17 * '02_Inputs_Sales'!J5 * (1.005^8) -> 0 | K14: ='02_Inputs_Sales'!F17 * '02_Inputs_Sales'!K5 * (1.005^9) -> 0 | L14: ='02_Inputs_Sales'!F17 * '02_Inputs_Sales'!L5 * (1.005^10) -> 0 | M14: ='02_Inputs_Sales'!F17 * '02_Inputs_Sales'!M5 * (1.005^11) -> 0 | N14: ='02_Inputs_Sales'!F17 * '02_Inputs_Sales'!B5 * (1.005^12) -> 0 | O14: ='02_Inputs_Sales'!F17 * '02_Inputs_Sales'!C5 * (1.005^13) -> 0 | P14: ='02_Inputs_Sales'!F17 * '02_Inputs_Sales'!D5 * (1.005^14) -> 0 | Q14: ='02_Inputs_Sales'!F17 * '02_Inputs_Sales'!E5 * (1.005^15) -> 0 | R14: ='02_Inputs_Sales'!F17 * '02_Inputs_Sales'!F5 * (1.005^16) -> 0 | S14: ='02_Inputs_Sales'!F17 * '02_Inputs_Sales'!G5 * (1.005^17) -> 0 | T14: ='02_Inputs_Sales'!F17 * '02_Inputs_Sales'!H5 * (1.005^18) -> 0 | U14: ='02_Inputs_Sales'!F17 * '02_Inputs_Sales'!I5 * (1.005^19) -> 0 | V14: ='02_Inputs_Sales'!F17 * '02_Inputs_Sales'!J5 * (1.005^20) -> 0 | W14: ='02_Inputs_Sales'!F17 * '02_Inputs_Sales'!K5 * (1.005^21) -> 0 | X14: ='02_Inputs_Sales'!F17 * '02_Inputs_Sales'!L5 * (1.005^22) -> 0 | Y14: ='02_Inputs_Sales'!F17 * '02_Inputs_Sales'!M5 * (1.005^23) -> 0 | Z14: ='02_Inputs_Sales'!F17 * '02_Inputs_Sales'!B5 * (1.005^24) -> 0 | AA14: ='02_Inputs_Sales'!F17 * '02_Inputs_Sales'!C5 * (1.005^25) -> 0 | AB14: ='02_Inputs_Sales'!F17 * '02_Inputs_Sales'!D5 * (1.005^26) -> 0 | AC14: ='02_Inputs_Sales'!F17 * '02_Inputs_Sales'!E5 * (1.005^27) -> 0 | AD14: ='02_Inputs_Sales'!F17 * '02_Inputs_Sales'!F5 * (1.005^28) -> 0 | AE14: ='02_Inputs_Sales'!F17 * '02_Inputs_Sales'!G5 * (1.005^29) -> 0 | AF14: ='02_Inputs_Sales'!F17 * '02_Inputs_Sales'!H5 * (1.005^30) -> 0 | AG14: ='02_Inputs_Sales'!F17 * '02_Inputs_Sales'!I5 * (1.005^31) -> 0 | AH14: ='02_Inputs_Sales'!F17 * '02_Inputs_Sales'!J5 * (1.005^32) -> 0 | AI14: ='02_Inputs_Sales'!F17 * '02_Inputs_Sales'!K5 * (1.005^33) -> 0 | AJ14: ='02_Inputs_Sales'!F17 * '02_Inputs_Sales'!L5 * (1.005^34) -> 0 | AK14: ='02_Inputs_Sales'!F17 * '02_Inputs_Sales'!M5 * (1.005^35) -> 0 | AL14: ='02_Inputs_Sales'!F17 * '02_Inputs_Sales'!B5 * (1.005^36) -> 0 | AM14: ='02_Inputs_Sales'!F17 * '02_Inputs_Sales'!C5 * (1.005^37) -> 0 | AN14: ='02_Inputs_Sales'!F17 * '02_Inputs_Sales'!D5 * (1.005^38) -> 0 | AO14: ='02_Inputs_Sales'!F17 * '02_Inputs_Sales'!E5 * (1.005^39) -> 0 | AP14: ='02_Inputs_Sales'!F17 * '02_Inputs_Sales'!F5 * (1.005^40) -> 0 | AQ14: ='02_Inputs_Sales'!F17 * '02_Inputs_Sales'!G5 * (1.005^41) -> 0 | AR14: ='02_Inputs_Sales'!F17 * '02_Inputs_Sales'!H5 * (1.005^42) -> 0 | AS14: ='02_Inputs_Sales'!F17 * '02_Inputs_Sales'!I5 * (1.005^43) -> 0 | AT14: ='02_Inputs_Sales'!F17 * '02_Inputs_Sales'!J5 * (1.005^44) -> 0 | AU14: ='02_Inputs_Sales'!F17 * '02_Inputs_Sales'!K5 * (1.005^45) -> 0 | AV14: ='02_Inputs_Sales'!F17 * '02_Inputs_Sales'!L5 * (1.005^46) -> 0 | AW14: ='02_Inputs_Sales'!F17 * '02_Inputs_Sales'!M5 * (1.005^47) -> 0 | AX14: ='02_Inputs_Sales'!F17 * '02_Inputs_Sales'!B5 * (1.005^48) -> 0 | AY14: ='02_Inputs_Sales'!F17 * '02_Inputs_Sales'!C5 * (1.005^49) -> 0 | AZ14: ='02_Inputs_Sales'!F17 * '02_Inputs_Sales'!D5 * (1.005^50) -> 0 | BA14: ='02_Inputs_Sales'!F17 * '02_Inputs_Sales'!E5 * (1.005^51) -> 0 | BB14: ='02_Inputs_Sales'!F17 * '02_Inputs_Sales'!F5 * (1.005^52) -> 0 | BC14: ='02_Inputs_Sales'!F17 * '02_Inputs_Sales'!G5 * (1.005^53) -> 0 | BD14: ='02_Inputs_Sales'!F17 * '02_Inputs_Sales'!H5 * (1.005^54) -> 0 | BE14: ='02_Inputs_Sales'!F17 * '02_Inputs_Sales'!I5 * (1.005^55) -> 0 | BF14: ='02_Inputs_Sales'!F17 * '02_Inputs_Sales'!J5 * (1.005^56) -> 0 | BG14: ='02_Inputs_Sales'!F17 * '02_Inputs_Sales'!K5 * (1.005^57) -> 0 | BH14: ='02_Inputs_Sales'!F17 * '02_Inputs_Sales'!L5 * (1.005^58) -> 0 | BI14: ='02_Inputs_Sales'!F17 * '02_Inputs_Sales'!M5 * (1.005^59) -> 0
B15: =SUM(B6:B14) -> 0 | C15: =SUM(C6:C14) -> 0 | D15: =SUM(D6:D14) -> 0 | E15: =SUM(E6:E14) -> 0 | F15: =SUM(F6:F14) -> 0 | G15: =SUM(G6:G14) -> 0 | H15: =SUM(H6:H14) -> 0 | I15: =SUM(I6:I14) -> 0 | ... BI15: =SUM(BI6:BI14) -> 0

Sheet 05_Calcs_Revenue
B3: M1 | C3: M2 | D3: M3 | E3: M4 | F3: M5 | G3: M6 | H3: M7 | I3: M8 | J3: M9 | K3: M10 | L3: M11 | M3: M12 | N3: M13 | O3: M14 | P3: M15 | Q3: M16 | R3: M17 | S3: M18 | T3: M19 | U3: M20 | V3: M21 | W3: M22 | X3: M23 | Y3: M24 | Z3: M25 | AA3: M26 | AB3: M27 | AC3: M28 | AD3: M29 | AE3: M30 | AF3: M31 | AG3: M32 | AH3: M33 | AI3: M34 | AJ3: M35 | AK3: M36 | AL3: M37 | AM3: M38 | AN3: M39 | AO3: M40 | AP3: M41 | AQ3: M42 | AR3: M43 | AS3: M44 | AT3: M45 | AU3: M46 | AV3: M47 | AW3: M48 | AX3: M49 | AY3: M50 | AZ3: M51 | BA3: M52 | BB3: M53 | BC3: M54 | BD3: M55 | BE3: M56 | BF3: M57 | BG3: M58 | BH3: M59 | BI3: M60
